Workbook
Name niv_2: #REF!
Name nivo1: #REF!

Sheet Paramètres
A1: Tableau N°1: Paramètres de base pour la campagne de vaccination
A2: Désignation | B2: Valeur
A3: CIBLES | B3: 0.1
A4: Nombre de cible à vacciner/équipe fixe/jour | B4: 30
A5: Nombre de cible à vacciner/équipe mo/jour | B5: 30
A6: Nombre de cible à vacciner/équipes stratégie avancée/jour | B6: 30
A7: Nombre d'agents de santé par équipe fixe | B7: 2
A8: Nombre d'agents de santé par équipe de vaccination (équipe mobile) | B8: 2
A9: Nombre d'agents santé par équipe stratégie avancée | B9: 2
A10: Nombre de volontaires par équipe fixe/avancée/mobile | B10: 1
A11: Nombre d'agents/véhicule de vaccination | B11: 4
A12: Nombre d'agents/motos: stratégie avancée | B12: 2
A13: Nombre de chauffeurs/équipe mobile | B13: 0
A14: Nombre d'équipes par superviseur | B14: 5
... A18: Nbre d'accus 0,6 litres par glacière | B18: 24
A19: Facteur de perte | B19: =100/(100-5) -> 1.0526316
A20: Nbre portes vaccins par équipe | B20: 2
A21: Volume par accumulateur (litres) | B21: 0.6
A22: Consommation (qté litres de gaz oil au 100 km) | B22: 0.2
A23: Consommation motos (qté litres d'essence sur 100km (moto) | B23: 0.07
A24: Consommation pinasse (litre d’essence mélange au Km)
A25: Prix d'un litre de gasoil (CFA)
A26: Prix d'un litre d'essence (CFA)
A27: Frais Incinération par boite de sécurité (CFA)
A28: Forfait par radio pour la mobilisation sociale
A29: Forfait pour journée d'informations
A30: Perdiem formation vaccinateurs/relais (Perdiem 2000 F CFA+ Frais de transport 1000 F CFA)
A31: Perdiem formateurs (CPM et superviseurs)
A32: Nombre jours formation
A33: Nombre de kilomètres par superviseur de proximité / jour
A34: Nombre de kilomètres par superviseur de district /de région/national / jour
A35: Nombre de kilomètres parcouru par pinasse par jour
... A45: Perdiem non résidents atelier de restitution
A46: forfait par radio pour un passage | B46: 0
A47: Coût couverture médiatique pour la restitution F CFA | B47: 500000
A48: Forfait mobilisateurs de proximité | B48: 0
A49: Forfait pour journées d'information par district sanitaire | B49: 0
A50: Forfait frais de lancement par région | B50: 0
A51: Réhabilitation des incinérateurs | B51: 0
A52: Frais d'incinération déchets (opérateurs) par jour (CFA) | B52: 0
...

Sheet Canevas
G1: % à Couvrir par stratégies | K1: Population Cibles à vacciner par stratégies | O1: Seringues | R1: nombre équipes | V1: Nombres d'agents | Z1: Nombres de volontaires | AD1: Intrants | AQ1: Coûts
A2: N° | B2: Aires de santé | C2: Nombre villages | D2: Distance à parcourir SA | E2: Distance à parcourir EM | F2: POP TOTAL 2022 | G2: CF | H2: SA | I2: EM | J2: Cible Totale | K2: CF | L2: SA | M2: EMS | N2: Nombre doses de Vaccin | O2: Seringues Autobloquantes (SAB) | P2: Seringues de dilution (S D) | Q2: Boites de sécurité (BS) | R2: CF | S2: SA | T2: EMS | U2: Total | V2: CF | W2: SA | X2: EMS plus chauffeurs | Y2: Total agents vaccinateurs | Z2: CF | AA2: SA | AB2: EMS | AC2: Total volontaires | AD2: Besoins en coton (2 rouleaux de 500g par équipe) | AE2: Fiches de pointage | AF2: Fiche synthèse journalière Aire de santé | AG2: Fiche synthèse journalière utilisation du matériel d'injection | AH2: Fiche de réception/déstruction déchets | AI2: Fiches synthèse élimimation déchets au niveau district sanitaire | AJ2: Fiches monitorage et d'évaluation rapide | AK2: Fiches de synthèse | AL2: Besoins en sachets poubelles | AM2: Cartes de vaccination | AN2: Saisie des données | AO2: collecte journaliere | AP2: Nombre boites de Gants | AQ2: Perdiem vaccinateurs/volontaires centre fixe et avancée | AR2: Coûts de déplacement stratégie avancée | AS2: Coût coordination au niveau aire de santé | AT2: Coûts Totaux
A3: 1 | J3: =F3*Paramètres!$B$3 -> 0 | K3: =J3*G3 -> 0 | L3: =J3*H3 -> 0 | M3: =J3*I3 -> 0 | N3: =ROUNDUP(J3*Paramètres!$B$19,-1) -> 0 | O3: =N3 -> 0 | P3: =O3/10 -> 0 | Q3: =ROUNDUP((O3+P3)/100,-1) -> 0 | R3: =ROUNDUP(+K3/Paramètres!$B$4/Paramètres!$B$53,0) -> 0 | S3: =ROUNDUP(+L3/Paramètres!$B$6/Paramètres!$B$53,0) -> 0 | U3: =R3+S3+T3 -> 0 | V3: =R3*Paramètres!$B$7 -> 0 | W3: =S3*Paramètres!$B$9 -> 0 | Y3: =V3+W3+X3 -> 0 | Z3: =R3*Paramètres!$B$10 -> 0 | AA3: =S3*Paramètres!$B$10 -> 0 | AC3: =Z3+AA3+AB3 -> 0 | AD3: =U3 -> 0 | AE3: =ROUNDUP((U3/200)*2,0)*10 -> 0 | AF3: =IF(B3="",0,Paramètres!$B$53*1.5) -> 0 | AG3: =IF(C3="",0,Paramètres!$B$53*1.5) -> 0 | AL3: =(U3*Paramètres!$B$53)*3 -> 0 | AM3: =N3 -> 0 | AO3: =U3*Paramètres!$B$72*Paramètres!$B$73 -> 0 | AQ3: =(Y3+AC3)*Paramètres!$B$42*Paramètres!$B$53 -> 0 | AR3: =ROUNDUP(D3*Paramètres!$B$23*Paramètres!$B$26,-1) -> 0 | AS3: =Paramètres!$B$53*Paramètres!$B$69 -> 50000
A4: 2 | J4: =F4*Paramètres!$B$3 -> 0 | K4: =J4*G4 -> 0 | L4: =J4*H4 -> 0 | M4: =J4*I4 -> 0 | N4: =ROUNDUP(J4*Paramètres!$B$19,-1) -> 0 | O4: =N4 -> 0 | P4: =O4/10 -> 0 | Q4: =ROUNDUP((O4+P4)/100,-1) -> 0 | R4: =ROUNDUP(+K4/Paramètres!$B$4/Paramètres!$B$53,0) -> 0 | S4: =ROUNDUP(+L4/Paramètres!$B$6/Paramètres!$B$53,0) -> 0 | U4: =R4+S4+T4 -> 0 | V4: =R4*Paramètres!$B$7 -> 0 | W4: =S4*Paramètres!$B$9 -> 0 | Y4: =V4+W4+X4 -> 0 | Z4: =R4*Paramètres!$B$10 -> 0 | AA4: =S4*Paramètres!$B$10 -> 0 | AC4: =Z4+AA4+AB4 -> 0 | AD4: =U4 -> 0 | AE4: =ROUNDUP((U4/200)*2,0)*10 -> 0 | AF4: =IF(B4="",0,Paramètres!$B$53*1.5) -> 0 | AG4: =IF(C4="",0,Paramètres!$B$53*1.5) -> 0 | AL4: =(U4*Paramètres!$B$53)*3 -> 0 | AM4: =N4 -> 0 | AO4: =U4*Paramètres!$B$72*Paramètres!$B$73 -> 0 | AQ4: =(Y4+AC4)*Paramètres!$B$42*Paramètres!$B$53 -> 0 | AR4: =ROUNDUP(D4*Paramètres!$B$23*Paramètres!$B$26,-1) -> 0 | AS4: =Paramètres!$B$53*Paramètres!$B$69 -> 50000 | AT4: =+AQ4+AR4+AS4 -> 50000
A5: 3 | J5: =F5*Paramètres!$B$3 -> 0 | K5: =J5*G5 -> 0 | L5: =J5*H5 -> 0 | M5: =J5*I5 -> 0 | N5: =ROUNDUP(J5*Paramètres!$B$19,-1) -> 0 | O5: =N5 -> 0 | P5: =O5/10 -> 0 | Q5: =ROUNDUP((O5+P5)/100,-1) -> 0 | R5: =ROUNDUP(+K5/Paramètres!$B$4/Paramètres!$B$53,0) -> 0 | S5: =ROUNDUP(+L5/Paramètres!$B$6/Paramètres!$B$53,0) -> 0 | U5: =R5+S5+T5 -> 0 | V5: =R5*Paramètres!$B$7 -> 0 | W5: =S5*Paramètres!$B$9 -> 0 | Y5: =V5+W5+X5 -> 0 | Z5: =R5*Paramètres!$B$10 -> 0 | AA5: =S5*Paramètres!$B$10 -> 0 | AC5: =Z5+AA5+AB5 -> 0 | AD5: =U5 -> 0 | AE5: =ROUNDUP((U5/200)*2,0)*10 -> 0 | AF5: =IF(B5="",0,Paramètres!$B$53*1.5) -> 0 | AG5: =IF(C5="",0,Paramètres!$B$53*1.5) -> 0 | AL5: =(U5*Paramètres!$B$53)*3 -> 0 | AM5: =N5 -> 0 | AO5: =U5*Paramètres!$B$72*Paramètres!$B$73 -> 0 | AQ5: =(Y5+AC5)*Paramètres!$B$42*Paramètres!$B$53 -> 0 | AR5: =ROUNDUP(D5*Paramètres!$B$23*Paramètres!$B$26,-1) -> 0 | AS5: =Paramètres!$B$53*Paramètres!$B$69 -> 50000 | AT5: =+AQ5+AR5+AS5 -> 50000
A6: 4 | J6: =F6*Paramètres!$B$3 -> 0 | K6: =J6*G6 -> 0 | L6: =J6*H6 -> 0 | M6: =J6*I6 -> 0 | N6: =ROUNDUP(J6*Paramètres!$B$19,-1) -> 0 | O6: =N6 -> 0 | P6: =O6/10 -> 0 | Q6: =ROUNDUP((O6+P6)/100,-1) -> 0 | R6: =ROUNDUP(+K6/Paramètres!$B$4/Paramètres!$B$53,0) -> 0 | S6: =ROUNDUP(+L6/Paramètres!$B$6/Paramètres!$B$53,0) -> 0 | U6: =R6+S6+T6 -> 0 | V6: =R6*Paramètres!$B$7 -> 0 | W6: =S6*Paramètres!$B$9 -> 0 | Y6: =V6+W6+X6 -> 0 | Z6: =R6*Paramètres!$B$10 -> 0 | AA6: =S6*Paramètres!$B$10 -> 0 | AC6: =Z6+AA6+AB6 -> 0 | AD6: =U6 -> 0 | AE6: =ROUNDUP((U6/200)*2,0)*10 -> 0 | AF6: =IF(B6="",0,Paramètres!$B$53*1.5) -> 0 | AG6: =IF(C6="",0,Paramètres!$B$53*1.5) -> 0 | AL6: =(U6*Paramètres!$B$53)*3 -> 0 | AM6: =N6 -> 0 | AO6: =U6*Paramètres!$B$72*Paramètres!$B$73 -> 0 | AQ6: =(Y6+AC6)*Paramètres!$B$42*Paramètres!$B$53 -> 0 | AR6: =ROUNDUP(D6*Paramètres!$B$23*Paramètres!$B$26,-1) -> 0 | AS6: =Paramètres!$B$53*Paramètres!$B$69 -> 50000 | AT6: =+AQ6+AR6+AS6 -> 50000
A7: 5 | J7: =F7*Paramètres!$B$3 -> 0 | K7: =J7*G7 -> 0 | L7: =J7*H7 -> 0 | M7: =J7*I7 -> 0 | N7: =ROUNDUP(J7*Paramètres!$B$19,-1) -> 0 | O7: =N7 -> 0 | P7: =O7/10 -> 0 | Q7: =ROUNDUP((O7+P7)/100,-1) -> 0 | R7: =ROUNDUP(+K7/Paramètres!$B$4/Paramètres!$B$53,0) -> 0 | S7: =ROUNDUP(+L7/Paramètres!$B$6/Paramètres!$B$53,0) -> 0 | U7: =R7+S7+T7 -> 0 | V7: =R7*Paramètres!$B$7 -> 0 | W7: =S7*Paramètres!$B$9 -> 0 | Y7: =V7+W7+X7 -> 0 | Z7: =R7*Paramètres!$B$10 -> 0 | AA7: =S7*Paramètres!$B$10 -> 0 | AC7: =Z7+AA7+AB7 -> 0 | AD7: =U7 -> 0 | AE7: =ROUNDUP((U7/200)*2,0)*10 -> 0 | AF7: =IF(B7="",0,Paramètres!$B$53*1.5) -> 0 | AG7: =IF(C7="",0,Paramètres!$B$53*1.5) -> 0 | AL7: =(U7*Paramètres!$B$53)*3 -> 0 | AM7: =N7 -> 0 | AO7: =U7*Paramètres!$B$72*Paramètres!$B$73 -> 0 | AQ7: =(Y7+AC7)*Paramètres!$B$42*Paramètres!$B$53 -> 0 | AR7: =ROUNDUP(D7*Paramètres!$B$23*Paramètres!$B$26,-1) -> 0 | AS7: =Paramètres!$B$53*Paramètres!$B$69 -> 50000 | AT7: =+AQ7+AR7+AS7 -> 50000
A8: 6 | J8: =F8*Paramètres!$B$3 -> 0 | K8: =J8*G8 -> 0 | L8: =J8*H8 -> 0 | M8: =J8*I8 -> 0 | N8: =ROUNDUP(J8*Paramètres!$B$19,-1) -> 0 | O8: =N8 -> 0 | P8: =O8/10 -> 0 | Q8: =ROUNDUP((O8+P8)/100,-1) -> 0 | R8: =ROUNDUP(+K8/Paramètres!$B$4/Paramètres!$B$53,0) -> 0 | S8: =ROUNDUP(+L8/Paramètres!$B$6/Paramètres!$B$53,0) -> 0 | U8: =R8+S8+T8 -> 0 | V8: =R8*Paramètres!$B$7 -> 0 | W8: =S8*Paramètres!$B$9 -> 0 | Y8: =V8+W8+X8 -> 0 | Z8: =R8*Paramètres!$B$10 -> 0 | AA8: =S8*Paramètres!$B$10 -> 0 | AC8: =Z8+AA8+AB8 -> 0 | AD8: =U8 -> 0 | AE8: =ROUNDUP((U8/200)*2,0)*10 -> 0 | AF8: =IF(B8="",0,Paramètres!$B$53*1.5) -> 0 | AG8: =IF(C8="",0,Paramètres!$B$53*1.5) -> 0 | AL8: =(U8*Paramètres!$B$53)*3 -> 0 | AM8: =N8 -> 0 | AO8: =U8*Paramètres!$B$72*Paramètres!$B$73 -> 0 | AQ8: =(Y8+AC8)*Paramètres!$B$42*Paramètres!$B$53 -> 0 | AR8: =ROUNDUP(D8*Paramètres!$B$23*Paramètres!$B$26,-1) -> 0 | AS8: =Paramètres!$B$53*Paramètres!$B$69 -> 50000 | AT8: =+AQ8+AR8+AS8 -> 50000
A9: 7 | J9: =F9*Paramètres!$B$3 -> 0 | K9: =J9*G9 -> 0 | L9: =J9*H9 -> 0 | M9: =J9*I9 -> 0 | N9: =ROUNDUP(J9*Paramètres!$B$19,-1) -> 0 | O9: =N9 -> 0 | P9: =O9/10 -> 0 | Q9: =ROUNDUP((O9+P9)/100,-1) -> 0 | R9: =ROUNDUP(+K9/Paramètres!$B$4/Paramètres!$B$53,0) -> 0 | S9: =ROUNDUP(+L9/Paramètres!$B$6/Paramètres!$B$53,0) -> 0 | U9: =R9+S9+T9 -> 0 | V9: =R9*Paramètres!$B$7 -> 0 | W9: =S9*Paramètres!$B$9 -> 0 | Y9: =V9+W9+X9 -> 0 | Z9: =R9*Paramètres!$B$10 -> 0 | AA9: =S9*Paramètres!$B$10 -> 0 | AC9: =Z9+AA9+AB9 -> 0 | AD9: =U9 -> 0 | AE9: =ROUNDUP((U9/200)*2,0)*10 -> 0 | AF9: =IF(B9="",0,Paramètres!$B$53*1.5) -> 0 | AG9: =IF(C9="",0,Paramètres!$B$53*1.5) -> 0 | AL9: =(U9*Paramètres!$B$53)*3 -> 0 | AM9: =N9 -> 0 | AO9: =U9*Paramètres!$B$72*Paramètres!$B$73 -> 0 | AQ9: =(Y9+AC9)*Paramètres!$B$42*Paramètres!$B$53 -> 0 | AR9: =ROUNDUP(D9*Paramètres!$B$23*Paramètres!$B$26,-1) -> 0 | AS9: =Paramètres!$B$53*Paramètres!$B$69 -> 50000 | AT9: =+AQ9+AR9+AS9 -> 50000
A10: 8 | J10: =F10*Paramètres!$B$3 -> 0 | K10: =J10*G10 -> 0 | L10: =J10*H10 -> 0 | M10: =J10*I10 -> 0 | N10: =ROUNDUP(J10*Paramètres!$B$19,-1) -> 0 | O10: =N10 -> 0 | P10: =O10/10 -> 0 | Q10: =ROUNDUP((O10+P10)/100,-1) -> 0 | R10: =ROUNDUP(+K10/Paramètres!$B$4/Paramètres!$B$53,0) -> 0 | S10: =ROUNDUP(+L10/Paramètres!$B$6/Paramètres!$B$53,0) -> 0 | U10: =R10+S10+T10 -> 0 | V10: =R10*Paramètres!$B$7 -> 0 | W10: =S10*Paramètres!$B$9 -> 0 | Y10: =V10+W10+X10 -> 0 | Z10: =R10*Paramètres!$B$10 -> 0 | AA10: =S10*Paramètres!$B$10 -> 0 | AC10: =Z10+AA10+AB10 -> 0 | AD10: =U10 -> 0 | AE10: =ROUNDUP((U10/200)*2,0)*10 -> 0 | AF10: =IF(B10="",0,Paramètres!$B$53*1.5) -> 0 | AG10: =IF(C10="",0,Paramètres!$B$53*1.5) -> 0 | AL10: =(U10*Paramètres!$B$53)*3 -> 0 | AM10: =N10 -> 0 | AO10: =U10*Paramètres!$B$72*Paramètres!$B$73 -> 0 | AQ10: =(Y10+AC10)*Paramètres!$B$42*Paramètres!$B$53 -> 0 | AR10: =ROUNDUP(D10*Paramètres!$B$23*Paramètres!$B$26,-1) -> 0 | AS10: =Paramètres!$B$53*Paramètres!$B$69 -> 50000 | AT10: =+AQ10+AR10+AS10 -> 50000
A11: 9 | J11: =F11*Paramètres!$B$3 -> 0 | K11: =J11*G11 -> 0 | L11: =J11*H11 -> 0 | M11: =J11*I11 -> 0 | N11: =ROUNDUP(J11*Paramètres!$B$19,-1) -> 0 | O11: =N11 -> 0 | P11: =O11/10 -> 0 | Q11: =ROUNDUP((O11+P11)/100,-1) -> 0 | R11: =ROUNDUP(+K11/Paramètres!$B$4/Paramètres!$B$53,0) -> 0 | S11: =ROUNDUP(+L11/Paramètres!$B$6/Paramètres!$B$53,0) -> 0 | U11: =R11+S11+T11 -> 0 | V11: =R11*Paramètres!$B$7 -> 0 | W11: =S11*Paramètres!$B$9 -> 0 | Y11: =V11+W11+X11 -> 0 | Z11: =R11*Paramètres!$B$10 -> 0 | AA11: =S11*Paramètres!$B$10 -> 0 | AC11: =Z11+AA11+AB11 -> 0 | AD11: =U11 -> 0 | AE11: =ROUNDUP((U11/200)*2,0)*10 -> 0 | AF11: =IF(B11="",0,Paramètres!$B$53*1.5) -> 0 | AG11: =IF(C11="",0,Paramètres!$B$53*1.5) -> 0 | AL11: =(U11*Paramètres!$B$53)*3 -> 0 | AM11: =N11 -> 0 | AO11: =U11*Paramètres!$B$72*Paramètres!$B$73 -> 0 | AQ11: =(Y11+AC11)*Paramètres!$B$42*Paramètres!$B$53 -> 0 | AR11: =ROUNDUP(D11*Paramètres!$B$23*Paramètres!$B$26,-1) -> 0 | AS11: =Paramètres!$B$53*Paramètres!$B$69 -> 50000 | AT11: =+AQ11+AR11+AS11 -> 50000
A12: 10 | J12: =F12*Paramètres!$B$3 -> 0 | K12: =J12*G12 -> 0 | L12: =J12*H12 -> 0 | M12: =J12*I12 -> 0 | N12: =ROUNDUP(J12*Paramètres!$B$19,-1) -> 0 | O12: =N12 -> 0 | P12: =O12/10 -> 0 | Q12: =ROUNDUP((O12+P12)/100,-1) -> 0 | R12: =ROUNDUP(+K12/Paramètres!$B$4/Paramètres!$B$53,0) -> 0 | S12: =ROUNDUP(+L12/Paramètres!$B$6/Paramètres!$B$53,0) -> 0 | U12: =R12+S12+T12 -> 0 | V12: =R12*Paramètres!$B$7 -> 0 | W12: =S12*Paramètres!$B$9 -> 0 | Y12: =V12+W12+X12 -> 0 | Z12: =R12*Paramètres!$B$10 -> 0 | AA12: =S12*Paramètres!$B$10 -> 0 | AC12: =Z12+AA12+AB12 -> 0 | AD12: =U12 -> 0 | AE12: =ROUNDUP((U12/200)*2,0)*10 -> 0 | AF12: =IF(B12="",0,Paramètres!$B$53*1.5) -> 0 | AG12: =IF(C12="",0,Paramètres!$B$53*1.5) -> 0 | AL12: =(U12*Paramètres!$B$53)*3 -> 0 | AM12: =N12 -> 0 | AO12: =U12*Paramètres!$B$72*Paramètres!$B$73 -> 0 | AQ12: =(Y12+AC12)*Paramètres!$B$42*Paramètres!$B$53 -> 0 | AR12: =ROUNDUP(D12*Paramètres!$B$23*Paramètres!$B$26,-1) -> 0 | AS12: =Paramètres!$B$53*Paramètres!$B$69 -> 50000 | AT12: =+AQ12+AR12+AS12 -> 50000
A13: 11 | J13: =F13*Paramètres!$B$3 -> 0 | K13: =J13*G13 -> 0 | L13: =J13*H13 -> 0 | M13: =J13*I13 -> 0 | N13: =ROUNDUP(J13*Paramètres!$B$19,-1) -> 0 | O13: =N13 -> 0 | P13: =O13/10 -> 0 | Q13: =ROUNDUP((O13+P13)/100,-1) -> 0 | R13: =ROUNDUP(+K13/Paramètres!$B$4/Paramètres!$B$53,0) -> 0 | S13: =ROUNDUP(+L13/Paramètres!$B$6/Paramètres!$B$53,0) -> 0 | U13: =R13+S13+T13 -> 0 | V13: =R13*Paramètres!$B$7 -> 0 | W13: =S13*Paramètres!$B$9 -> 0 | Y13: =V13+W13+X13 -> 0 | Z13: =R13*Paramètres!$B$10 -> 0 | AA13: =S13*Paramètres!$B$10 -> 0 | AC13: =Z13+AA13+AB13 -> 0 | AD13: =U13 -> 0 | AE13: =ROUNDUP((U13/200)*2,0)*10 -> 0 | AF13: =IF(B13="",0,Paramètres!$B$53*1.5) -> 0 | AG13: =IF(C13="",0,Paramètres!$B$53*1.5) -> 0 | AL13: =(U13*Paramètres!$B$53)*3 -> 0 | AM13: =N13 -> 0 | AO13: =U13*Paramètres!$B$72*Paramètres!$B$73 -> 0 | AQ13: =(Y13+AC13)*Paramètres!$B$42*Paramètres!$B$53 -> 0 | AR13: =ROUNDUP(D13*Paramètres!$B$23*Paramètres!$B$26,-1) -> 0 | AS13: =Paramètres!$B$53*Paramètres!$B$69 -> 50000 | AT13: =+AQ13+AR13+AS13 -> 50000
A14: 12 | J14: =F14*Paramètres!$B$3 -> 0 | K14: =J14*G14 -> 0 | L14: =J14*H14 -> 0 | M14: =J14*I14 -> 0 | N14: =ROUNDUP(J14*Paramètres!$B$19,-1) -> 0 | O14: =N14 -> 0 | P14: =O14/10 -> 0 | Q14: =ROUNDUP((O14+P14)/100,-1) -> 0 | R14: =ROUNDUP(+K14/Paramètres!$B$4/Paramètres!$B$53,0) -> 0 | S14: =ROUNDUP(+L14/Paramètres!$B$6/Paramètres!$B$53,0) -> 0 | U14: =R14+S14+T14 -> 0 | V14: =R14*Paramètres!$B$7 -> 0 | W14: =S14*Paramètres!$B$9 -> 0 | Y14: =V14+W14+X14 -> 0 | Z14: =R14*Paramètres!$B$10 -> 0 | AA14: =S14*Paramètres!$B$10 -> 0 | AC14: =Z14+AA14+AB14 -> 0 | AD14: =U14 -> 0 | AE14: =ROUNDUP((U14/200)*2,0)*10 -> 0 | AF14: =IF(B14="",0,Paramètres!$B$53*1.5) -> 0 | AG14: =IF(C14="",0,Paramètres!$B$53*1.5) -> 0 | AL14: =(U14*Paramètres!$B$53)*3 -> 0 | AM14: =N14 -> 0 | AO14: =U14*Paramètres!$B$72*Paramètres!$B$73 -> 0 | AQ14: =(Y14+AC14)*Paramètres!$B$42*Paramètres!$B$53 -> 0 | AR14: =ROUNDUP(D14*Paramètres!$B$23*Paramètres!$B$26,-1) -> 0 | AS14: =Paramètres!$B$53*Paramètres!$B$69 -> 50000 | AT14: =+AQ14+AR14+AS14 -> 50000
A15: 13 | J15: =F15*Paramètres!$B$3 -> 0 | K15: =J15*G15 -> 0 | L15: =J15*H15 -> 0 | M15: =J15*I15 -> 0 | N15: =ROUNDUP(J15*Paramètres!$B$19,-1) -> 0 | O15: =N15 -> 0 | P15: =O15/10 -> 0 | Q15: =ROUNDUP((O15+P15)/100,-1) -> 0 | R15: =ROUNDUP(+K15/Paramètres!$B$4/Paramètres!$B$53,0) -> 0 | S15: =ROUNDUP(+L15/Paramètres!$B$6/Paramètres!$B$53,0) -> 0 | U15: =R15+S15+T15 -> 0 | V15: =R15*Paramètres!$B$7 -> 0 | W15: =S15*Paramètres!$B$9 -> 0 | Y15: =V15+W15+X15 -> 0 | Z15: =R15*Paramètres!$B$10 -> 0 | AA15: =S15*Paramètres!$B$10 -> 0 | AC15: =Z15+AA15+AB15 -> 0 | AD15: =U15 -> 0 | AE15: =ROUNDUP((U15/200)*2,0)*10 -> 0 | AF15: =IF(B15="",0,Paramètres!$B$53*1.5) -> 0 | AG15: =IF(C15="",0,Paramètres!$B$53*1.5) -> 0 | AL15: =(U15*Paramètres!$B$53)*3 -> 0 | AM15: =N15 -> 0 | AO15: =U15*Paramètres!$B$72*Paramètres!$B$73 -> 0 | AQ15: =(Y15+AC15)*Paramètres!$B$42*Paramètres!$B$53 -> 0 | AR15: =ROUNDUP(D15*Paramètres!$B$23*Paramètres!$B$26,-1) -> 0 | AS15: =Paramètres!$B$53*Paramètres!$B$69 -> 50000 | AT15: =+AQ15+AR15+AS15 -> 50000
... A62: 60 | J62: =F62*Paramètres!$B$3 -> 0 | K62: =J62*G62 -> 0 | L62: =J62*H62 -> 0 | M62: =J62*I62 -> 0 | N62: =ROUNDUP(J62*Paramètres!$B$19,-1) -> 0 | O62: =N62 -> 0 | P62: =O62/10 -> 0 | Q62: =ROUNDUP((O62+P62)/100,-1) -> 0 | R62: =ROUNDUP(+K62/Paramètres!$B$4/Paramètres!$B$53,0) -> 0 | S62: =ROUNDUP(+L62/Paramètres!$B$6/Paramètres!$B$53,0) -> 0 | U62: =R62+S62+T62 -> 0 | V62: =R62*Paramètres!$B$7 -> 0 | W62: =S62*Paramètres!$B$9 -> 0 | Y62: =V62+W62+X62 -> 0 | Z62: =R62*Paramètres!$B$10 -> 0 | AA62: =S62*Paramètres!$B$10 -> 0 | AC62: =Z62+AA62+AB62 -> 0 | AD62: =U62 -> 0 | AE62: =ROUNDUP((U62/200)*2,0)*10 -> 0 | AF62: =IF(B62="",0,Paramètres!$B$53*1.5) -> 0 | AG62: =IF(C62="",0,Paramètres!$B$53*1.5) -> 0 | AL62: =(U62*Paramètres!$B$53)*3 -> 0 | AM62: =N62 -> 0 | AO62: =U62*Paramètres!$B$72*Paramètres!$B$73 -> 0 | AQ62: =(Y62+AC62)*Paramètres!$B$42*Paramètres!$B$53 -> 0 | AR62: =ROUNDUP(D62*Paramètres!$B$23*Paramètres!$B$26,-1) -> 0 | AS62: =Paramètres!$B$53*Paramètres!$B$69 -> 50000 | AT62: =+AQ62+AR62+AS62 -> 50000
J63: =F63*Paramètres!$B$3 -> 0 | K63: =J63*G63 -> 0 | L63: =J63*H63 -> 0 | M63: =J63*I63 -> 0 | N63: =ROUNDUP(J63*Paramètres!$B$19,-1) -> 0 | O63: =N63 -> 0 | P63: =O63/10 -> 0 | Q63: =ROUNDUP((O63+P63)/100,-1) -> 0 | R63: =ROUNDUP(+K63/Paramètres!$B$4/Paramètres!$B$53,0) -> 0 | S63: =ROUNDUP(+L63/Paramètres!$B$6/Paramètres!$B$53,0) -> 0 | U63: =R63+S63+T63 -> 0 | V63: =R63*Paramètres!$B$7 -> 0 | W63: =S63*Paramètres!$B$9 -> 0 | Y63: =V63+W63+X63 -> 0 | Z63: =R63*Paramètres!$B$10 -> 0 | AA63: =S63*Paramètres!$B$10 -> 0 | AC63: =Z63+AA63+AB63 -> 0 | AD63: =U63 -> 0 | AE63: =ROUNDUP((U63/200)*2,0)*10 -> 0 | AF63: =IF(B63="",0,Paramètres!$B$53*1.5) -> 0 | AG63: =IF(C63="",0,Paramètres!$B$53*1.5) -> 0 | AL63: =(U63*Paramètres!$B$53)*3 -> 0 | AM63: =N63 -> 0 | AO63: =U63*Paramètres!$B$72*Paramètres!$B$73 -> 0 | AQ63: =(Y63+AC63)*Paramètres!$B$42*Paramètres!$B$53 -> 0 | AR63: =ROUNDUP(D63*Paramètres!$B$23*Paramètres!$B$26,-1) -> 0 | AS63: =Paramètres!$B$53*Paramètres!$B$69 -> 50000 | AT63: =+AQ63+AR63+AS63 -> 50000
J64: =F64*Paramètres!$B$3 -> 0 | K64: =J64*G64 -> 0 | L64: =J64*H64 -> 0 | M64: =J64*I64 -> 0 | N64: =ROUNDUP(J64*Paramètres!$B$19,-1) -> 0 | O64: =N64 -> 0 | P64: =O64/10 -> 0 | Q64: =ROUNDUP((O64+P64)/100,-1) -> 0 | R64: =ROUNDUP(+K64/Paramètres!$B$4/Paramètres!$B$53,0) -> 0 | S64: =ROUNDUP(+L64/Paramètres!$B$6/Paramètres!$B$53,0) -> 0 | U64: =R64+S64+T64 -> 0 | V64: =R64*Paramètres!$B$7 -> 0 | W64: =S64*Paramètres!$B$9 -> 0 | Y64: =V64+W64+X64 -> 0 | Z64: =R64*Paramètres!$B$10 -> 0 | AA64: =S64*Paramètres!$B$10 -> 0 | AC64: =Z64+AA64+AB64 -> 0 | AD64: =U64 -> 0 | AE64: =ROUNDUP((U64/200)*2,0)*10 -> 0 | AF64: =IF(B64="",0,Paramètres!$B$53*1.5) -> 0 | AG64: =IF(C64="",0,Paramètres!$B$53*1.5) -> 0 | AL64: =(U64*Paramètres!$B$53)*3 -> 0 | AM64: =N64 -> 0 | AO64: =U64*Paramètres!$B$72*Paramètres!$B$73 -> 0 | AQ64: =(Y64+AC64)*Paramètres!$B$42*Paramètres!$B$53 -> 0 | AR64: =ROUNDUP(D64*Paramètres!$B$23*Paramètres!$B$26,-1) -> 0 | AS64: =Paramètres!$B$53*Paramètres!$B$69 -> 50000 | AT64: =+AQ64+AR64+AS64 -> 50000
J65: =F65*Paramètres!$B$3 -> 0 | K65: =J65*G65 -> 0 | L65: =J65*H65 -> 0 | M65: =J65*I65 -> 0 | N65: =ROUNDUP(J65*Paramètres!$B$19,-1) -> 0 | O65: =N65 -> 0 | P65: =O65/10 -> 0 | Q65: =ROUNDUP((O65+P65)/100,-1) -> 0 | R65: =ROUNDUP(+K65/Paramètres!$B$4/Paramètres!$B$53,0) -> 0 | S65: =ROUNDUP(+L65/Paramètres!$B$6/Paramètres!$B$53,0) -> 0 | U65: =R65+S65+T65 -> 0 | V65: =R65*Paramètres!$B$7 -> 0 | W65: =S65*Paramètres!$B$9 -> 0 | Y65: =V65+W65+X65 -> 0 | Z65: =R65*Paramètres!$B$10 -> 0 | AA65: =S65*Paramètres!$B$10 -> 0 | AC65: =Z65+AA65+AB65 -> 0 | AD65: =U65 -> 0 | AE65: =ROUNDUP((U65/200)*2,0)*10 -> 0 | AF65: =IF(B65="",0,Paramètres!$B$53*1.5) -> 0 | AG65: =IF(C65="",0,Paramètres!$B$53*1.5) -> 0 | AL65: =(U65*Paramètres!$B$53)*3 -> 0 | AM65: =N65 -> 0 | AO65: =U65*Paramètres!$B$72*Paramètres!$B$73 -> 0 | AQ65: =(Y65+AC65)*Paramètres!$B$42*Paramètres!$B$53 -> 0 | AR65: =ROUNDUP(D65*Paramètres!$B$23*Paramètres!$B$26,-1) -> 0 | AS65: =Paramètres!$B$53*Paramètres!$B$69 -> 50000 | AT65: =+AQ65+AR65+AS65 -> 50000
J66: =F66*Paramètres!$B$3 -> 0 | K66: =J66*G66 -> 0 | L66: =J66*H66 -> 0 | M66: =J66*I66 -> 0 | N66: =ROUNDUP(J66*Paramètres!$B$19,-1) -> 0 | O66: =N66 -> 0 | P66: =O66/10 -> 0 | Q66: =ROUNDUP((O66+P66)/100,-1) -> 0 | R66: =ROUNDUP(+K66/Paramètres!$B$4/Paramètres!$B$53,0) -> 0 | S66: =ROUNDUP(+L66/Paramètres!$B$6/Paramètres!$B$53,0) -> 0 | U66: =R66+S66+T66 -> 0 | V66: =R66*Paramètres!$B$7 -> 0 | W66: =S66*Paramètres!$B$9 -> 0 | Y66: =V66+W66+X66 -> 0 | Z66: =R66*Paramètres!$B$10 -> 0 | AA66: =S66*Paramètres!$B$10 -> 0 | AC66: =Z66+AA66+AB66 -> 0 | AD66: =U66 -> 0 | AE66: =ROUNDUP((U66/200)*2,0)*10 -> 0 | AF66: =IF(B66="",0,Paramètres!$B$53*1.5) -> 0 | AG66: =IF(C66="",0,Paramètres!$B$53*1.5) -> 0 | AL66: =(U66*Paramètres!$B$53)*3 -> 0 | AM66: =N66 -> 0 | AO66: =U66*Paramètres!$B$72*Paramètres!$B$73 -> 0 | AQ66: =(Y66+AC66)*Paramètres!$B$42*Paramètres!$B$53 -> 0 | AR66: =ROUNDUP(D66*Paramètres!$B$23*Paramètres!$B$26,-1) -> 0 | AS66: =Paramètres!$B$53*Paramètres!$B$69 -> 50000 | AT66: =+AQ66+AR66+AS66 -> 50000
J67: =F67*Paramètres!$B$3 -> 0 | K67: =J67*G67 -> 0 | L67: =J67*H67 -> 0 | M67: =J67*I67 -> 0 | N67: =ROUNDUP(J67*Paramètres!$B$19,-1) -> 0 | O67: =N67 -> 0 | P67: =O67/10 -> 0 | Q67: =ROUNDUP((O67+P67)/100,-1) -> 0 | R67: =ROUNDUP(+K67/Paramètres!$B$4/Paramètres!$B$53,0) -> 0 | S67: =ROUNDUP(+L67/Paramètres!$B$6/Paramètres!$B$53,0) -> 0 | U67: =R67+S67+T67 -> 0 | V67: =R67*Paramètres!$B$7 -> 0 | W67: =S67*Paramètres!$B$9 -> 0 | Y67: =V67+W67+X67 -> 0 | Z67: =R67*Paramètres!$B$10 -> 0 | AA67: =S67*Paramètres!$B$10 -> 0 | AC67: =Z67+AA67+AB67 -> 0 | AD67: =U67 -> 0 | AE67: =ROUNDUP((U67/200)*2,0)*10 -> 0 | AF67: =IF(B67="",0,Paramètres!$B$53*1.5) -> 0 | AG67: =IF(C67="",0,Paramètres!$B$53*1.5) -> 0 | AL67: =(U67*Paramètres!$B$53)*3 -> 0 | AM67: =N67 -> 0 | AO67: =U67*Paramètres!$B$72*Paramètres!$B$73 -> 0 | AQ67: =(Y67+AC67)*Paramètres!$B$42*Paramètres!$B$53 -> 0 | AR67: =ROUNDUP(D67*Paramètres!$B$23*Paramètres!$B$26,-1) -> 0 | AS67: =Paramètres!$B$53*Paramètres!$B$69 -> 50000 | AT67: =+AQ67+AR67+AS67 -> 50000
J68: =F68*Paramètres!$B$3 -> 0 | K68: =J68*G68 -> 0 | L68: =J68*H68 -> 0 | M68: =J68*I68 -> 0 | N68: =ROUNDUP(J68*Paramètres!$B$19,-1) -> 0 | O68: =N68 -> 0 | P68: =O68/10 -> 0 | Q68: =ROUNDUP((O68+P68)/100,-1) -> 0 | R68: =ROUNDUP(+K68/Paramètres!$B$4/Paramètres!$B$53,0) -> 0 | S68: =ROUNDUP(+L68/Paramètres!$B$6/Paramètres!$B$53,0) -> 0 | U68: =R68+S68+T68 -> 0 | V68: =R68*Paramètres!$B$7 -> 0 | W68: =S68*Paramètres!$B$9 -> 0 | Y68: =V68+W68+X68 -> 0 | Z68: =R68*Paramètres!$B$10 -> 0 | AA68: =S68*Paramètres!$B$10 -> 0 | AC68: =Z68+AA68+AB68 -> 0 | AD68: =U68 -> 0 | AE68: =ROUNDUP((U68/200)*2,0)*10 -> 0 | AF68: =IF(B68="",0,Paramètres!$B$53*1.5) -> 0 | AG68: =IF(C68="",0,Paramètres!$B$53*1.5) -> 0 | AL68: =(U68*Paramètres!$B$53)*3 -> 0 | AM68: =N68 -> 0 | AO68: =U68*Paramètres!$B$72*Paramètres!$B$73 -> 0 | AQ68: =(Y68+AC68)*Paramètres!$B$42*Paramètres!$B$53 -> 0 | AR68: =ROUNDUP(D68*Paramètres!$B$23*Paramètres!$B$26,-1) -> 0 | AS68: =Paramètres!$B$53*Paramètres!$B$69 -> 50000 | AT68: =+AQ68+AR68+AS68 -> 50000
J69: =F69*Paramètres!$B$3 -> 0 | K69: =J69*G69 -> 0 | L69: =J69*H69 -> 0 | M69: =J69*I69 -> 0 | N69: =ROUNDUP(J69*Paramètres!$B$19,-1) -> 0 | O69: =N69 -> 0 | P69: =O69/10 -> 0 | Q69: =ROUNDUP((O69+P69)/100,-1) -> 0 | R69: =ROUNDUP(+K69/Paramètres!$B$4/Paramètres!$B$53,0) -> 0 | S69: =ROUNDUP(+L69/Paramètres!$B$6/Paramètres!$B$53,0) -> 0 | U69: =R69+S69+T69 -> 0 | V69: =R69*Paramètres!$B$7 -> 0 | W69: =S69*Paramètres!$B$9 -> 0 | Y69: =V69+W69+X69 -> 0 | Z69: =R69*Paramètres!$B$10 -> 0 | AA69: =S69*Paramètres!$B$10 -> 0 | AC69: =Z69+AA69+AB69 -> 0 | AD69: =U69 -> 0 | AE69: =ROUNDUP((U69/200)*2,0)*10 -> 0 | AF69: =IF(B69="",0,Paramètres!$B$53*1.5) -> 0 | AG69: =IF(C69="",0,Paramètres!$B$53*1.5) -> 0 | AL69: =(U69*Paramètres!$B$53)*3 -> 0 | AM69: =N69 -> 0 | AO69: =U69*Paramètres!$B$72*Paramètres!$B$73 -> 0 | AQ69: =(Y69+AC69)*Paramètres!$B$42*Paramètres!$B$53 -> 0 | AR69: =ROUNDUP(D69*Paramètres!$B$23*Paramètres!$B$26,-1) -> 0 | AS69: =Paramètres!$B$53*Paramètres!$B$69 -> 50000 | AT69: =+AQ69+AR69+AS69 -> 50000
J70: =F70*Paramètres!$B$3 -> 0 | K70: =J70*G70 -> 0 | L70: =J70*H70 -> 0 | M70: =J70*I70 -> 0 | N70: =ROUNDUP(J70*Paramètres!$B$19,-1) -> 0 | O70: =N70 -> 0 | P70: =O70/10 -> 0 | Q70: =ROUNDUP((O70+P70)/100,-1) -> 0 | R70: =ROUNDUP(+K70/Paramètres!$B$4/Paramètres!$B$53,0) -> 0 | S70: =ROUNDUP(+L70/Paramètres!$B$6/Paramètres!$B$53,0) -> 0 | U70: =R70+S70+T70 -> 0 | V70: =R70*Paramètres!$B$7 -> 0 | W70: =S70*Paramètres!$B$9 -> 0 | Y70: =V70+W70+X70 -> 0 | Z70: =R70*Paramètres!$B$10 -> 0 | AA70: =S70*Paramètres!$B$10 -> 0 | AC70: =Z70+AA70+AB70 -> 0 | AD70: =U70 -> 0 | AE70: =ROUNDUP((U70/200)*2,0)*10 -> 0 | AF70: =IF(B70="",0,Paramètres!$B$53*1.5) -> 0 | AG70: =IF(C70="",0,Paramètres!$B$53*1.5) -> 0 | AL70: =(U70*Paramètres!$B$53)*3 -> 0 | AM70: =N70 -> 0 | AO70: =U70*Paramètres!$B$72*Paramètres!$B$73 -> 0 | AQ70: =(Y70+AC70)*Paramètres!$B$42*Paramètres!$B$53 -> 0 | AR70: =ROUNDUP(D70*Paramètres!$B$23*Paramètres!$B$26,-1) -> 0 | AS70: =Paramètres!$B$53*Paramètres!$B$69 -> 50000 | AT70: =+AQ70+AR70+AS70 -> 50000
J71: =F71*Paramètres!$B$3 -> 0 | K71: =J71*G71 -> 0 | L71: =J71*H71 -> 0 | M71: =J71*I71 -> 0 | N71: =ROUNDUP(J71*Paramètres!$B$19,-1) -> 0 | O71: =N71 -> 0 | P71: =O71/10 -> 0 | Q71: =ROUNDUP((O71+P71)/100,-1) -> 0 | R71: =ROUNDUP(+K71/Paramètres!$B$4/Paramètres!$B$53,0) -> 0 | S71: =ROUNDUP(+L71/Paramètres!$B$6/Paramètres!$B$53,0) -> 0 | U71: =R71+S71+T71 -> 0 | V71: =R71*Paramètres!$B$7 -> 0 | W71: =S71*Paramètres!$B$9 -> 0 | Y71: =V71+W71+X71 -> 0 | Z71: =R71*Paramètres!$B$10 -> 0 | AA71: =S71*Paramètres!$B$10 -> 0 | AC71: =Z71+AA71+AB71 -> 0 | AD71: =U71 -> 0 | AE71: =ROUNDUP((U71/200)*2,0)*10 -> 0 | AF71: =IF(B71="",0,Paramètres!$B$53*1.5) -> 0 | AG71: =IF(C71="",0,Paramètres!$B$53*1.5) -> 0 | AL71: =(U71*Paramètres!$B$53)*3 -> 0 | AM71: =N71 -> 0 | AO71: =U71*Paramètres!$B$72*Paramètres!$B$73 -> 0 | AQ71: =(Y71+AC71)*Paramètres!$B$42*Paramètres!$B$53 -> 0 | AR71: =ROUNDUP(D71*Paramètres!$B$23*Paramètres!$B$26,-1) -> 0 | AS71: =Paramètres!$B$53*Paramètres!$B$69 -> 50000 | AT71: =+AQ71+AR71+AS71 -> 50000
A72: =COUNTA(A3:A71) -> 60 | B72: Aires de santé | C72: =SUM(C3:C71) -> 0 | D72: =SUM(D3:D71) -> 0 | E72: =SUM(E3:E71) -> 0 | F72: =SUM(F3:F71) -> 0 | J72: =SUM(J3:J71) -> 0 | K72: =SUM(K3:K71) -> 0 | L72: =SUM(L3:L71) -> 0 | M72: =SUM(M3:M71) -> 0 | N72: =SUM(N3:N71) -> 0 | O72: =SUM(O3:O71) -> 0 | P72: =SUM(P3:P71) -> 0 | Q72: =SUM(Q3:Q71) -> 0 | ... S72: =SUM(S3:S71) -> 0 | U72: =R72+S72+T72 -> 0 | V72: =SUM(V3:V71) -> 0 | W72: =SUM(W3:W71) -> 0 | Y72: =SUM(Y3:Y71)+X72 -> 0 | Z72: =SUM(Z3:Z71) -> 0 | AA72: =SUM(AA3:AA71) -> 0 | AB72: =T72*Paramètres!B10 -> 0 | AC72: =SUM(AC3:AC71)+AB72 -> 0 | AD72: =SUM(AD3:AD71) -> 0 | AE72: =SUM(AE3:AE71) -> 0 | AF72: =SUM(AF3:AF71) -> 0 | AG72: =SUM(AG3:AG71) -> 0 | AH72: =IF(Q72=0,0,Paramètres!$B$53*2) -> 0 | AI72: =IF(N72=0,0,Paramètres!$B$53*3) -> 0 | AJ72: =Paramètres!B53*20*1.5 -> 300 | AK72: =Paramètres!B53*3*1.5 -> 45 | AL72: =SUM(AL3:AL71) -> 0 | AM72: =SUM(AM3:AM71) -> 0 | AN72: =SUM(AN3:AN71) -> 0 | AO72: =SUM(AO3:AO71) -> 0 | AQ72: =SUM(AQ3:AQ71) -> 0 | AR72: =SUM(AR3:AR71) -> 0 | AS72: =SUM(AS3:AS71) -> 3450000 | AT72: =SUM(AQ72:AS72) -> 3450000
AS74: Total: | AT74: =+AN72+AO72+AQ72+AR72+AS72 -> 3450000

Sheet DISTRICT6
G1: % à Couvrir par stratégies | K1: Population Cibles à vacciner par stratégies | O1: Seringues | R1: nombre équipes | V1: Nombres d'agents | Z1: Nombres de volontaires | AD1: Intrants | AQ1: Coûts | AU1: Incinération déchets | AW1: Formations vaccinateurs volontaires | BE1: Formation opérateurs
A2: N° | B2: Aires de santé | C2: Nombre villages | D2: Distance à parcourir SA | E2: Distance à parcourir EM | F2: POP TOTAL 2016 | G2: CF | H2: SA | I2: EM | J2: Cible Totale | K2: CF | L2: SA | M2: EMS | N2: Nombre doses de MenAfiVac | O2: Seringues Autobloquantes (SAB) | P2: Seringues de dilution (S D) | Q2: Boites de sécurité (BS) | R2: CF | S2: SA | T2: EMS | U2: Total | V2: CF | W2: SA | X2: EMS plus chauffeurs | Y2: Total agents vaccinateurs | Z2: CF | AA2: SA | AB2: EMS | AC2: Total volontaires | AD2: Besoins en coton (2 rouleaux de 500g par équipe) | AE2: Fiches de pointage | AF2: Fiche synthèse journalière Aire de santé | AG2: Fiche synthèse journalière utilisation du matériel d'injection | AH2: Fiche de réception/déstruction déchets | AI2: Fiches synthèse élimimation déchets au niveau district sanitaire | AJ2: Fiches monitorage et d'évaluation rapide | AK2: Fiches de synthèse | AL2: Besoins en sachets poubelles | AM2: Cartes de vaccination | AN2: Module par équipe | AO2: Nombre de Gants | AP2: Nombre boites de Gants | AQ2: Perdiem vaccinateurs/volontaires centre fixe et avancée | AR2: Perdiem vaccinateurs/volontaires équipes mobiles | AS2: Coûts de déplacement stratégie avancée | AT2: Coûts de déplacement des Equipes Mobiles | AU2: Aménagement Fosse | AV2: Frais d'incinération déchets (opérateurs) F CFA | AW2: Frais Transport | AX2: Perdiem participants | AY2: Perdiem Facilitateurs district | AZ2: Frais de facilitation des formateurs district | BA2: Pauses | BB2: Total Formation | BC2: Coût coordination au niveau aire de santé | BD2: Coût Gants | BE2: Perdiem | BF2: Pause | BG2: Total | BH2: Forfait gestion MAPI | BI2: Coûts Totaux
A3: 1 | J3: =F3*Paramètres!$B$3 -> 0 | K3: =J3*G3 -> 0 | L3: =J3*H3 -> 0 | M3: =J3*I3 -> 0 | N3: =ROUNDUP(J3*Paramètres!$B$19,-1) -> 0 | O3: =N3 -> 0 | P3: =O3/10 -> 0 | Q3: =ROUNDUP((O3+P3)/100,-1) -> 0 | R3: =ROUNDUP(+K3/Paramètres!$B$4/Paramètres!$B$53,0) -> 0 | S3: =ROUNDUP(+L3/Paramètres!$B$6/Paramètres!$B$53,0) -> 0 | U3: =R3+S3+T3 -> 0 | V3: =R3*Paramètres!$B$7 -> 0 | W3: =S3*Paramètres!$B$9 -> 0 | Y3: =V3+W3+X3 -> 0 | Z3: =R3*Paramètres!$B$10 -> 0 | AA3: =S3*Paramètres!$B$10 -> 0 | AC3: =Z3+AA3+AB3 -> 0 | AD3: =U3 -> 0 | AE3: =ROUNDUP((U3/200)*2,0)*10 -> 0 | AF3: =IF(B3="",0,Paramètres!$B$53*1.5) -> 0 | AG3: =IF(C3="",0,Paramètres!$B$53*1.5) -> 0 | AL3: =(U3*Paramètres!$B$53)*3 -> 0 | AM3: =N3 -> 0 | AN3: =U3*Paramètres!$B$75 -> 0 | AO3: =U3*Paramètres!$B$72*Paramètres!$B$73 -> 0 | AQ3: =(Y3+AC3)*Paramètres!$B$42*Paramètres!$B$53 -> 0 | AS3: =ROUNDUP(D3*Paramètres!$B$23*Paramètres!$B$26,-1) -> 0 | BI3: =AQ3+AS3 -> 0
A4: 2 | J4: =F4*Paramètres!$B$3 -> 0 | K4: =J4*G4 -> 0 | L4: =J4*H4 -> 0 | M4: =J4*I4 -> 0 | N4: =ROUNDUP(J4*Paramètres!$B$19,-1) -> 0 | O4: =N4 -> 0 | P4: =O4/10 -> 0 | Q4: =ROUNDUP((O4+P4)/100,-1) -> 0 | R4: =ROUNDUP(+K4/Paramètres!$B$4/Paramètres!$B$53,0) -> 0 | S4: =ROUNDUP(+L4/Paramètres!$B$6/Paramètres!$B$53,0) -> 0 | U4: =R4+S4+T4 -> 0 | V4: =R4*Paramètres!$B$7 -> 0 | W4: =S4*Paramètres!$B$9 -> 0 | Y4: =V4+W4+X4 -> 0 | Z4: =R4*Paramètres!$B$10 -> 0 | AA4: =S4*Paramètres!$B$10 -> 0 | AC4: =Z4+AA4+AB4 -> 0 | AD4: =U4 -> 0 | AE4: =ROUNDUP((U4/200)*2,0)*10 -> 0 | AF4: =IF(B4="",0,Paramètres!$B$53*1.5) -> 0 | AG4: =IF(C4="",0,Paramètres!$B$53*1.5) -> 0 | AL4: =(U4*Paramètres!$B$53)*3 -> 0 | AM4: =N4 -> 0 | AN4: =U4*Paramètres!$B$75 -> 0 | AO4: =U4*Paramètres!$B$72*Paramètres!$B$73 -> 0 | AQ4: =(Y4+AC4)*Paramètres!$B$42*Paramètres!$B$53 -> 0 | AS4: =ROUNDUP(D4*Paramètres!$B$23*Paramètres!$B$26,-1) -> 0 | BI4: =AQ4+AS4 -> 0
A5: 3 | J5: =F5*Paramètres!$B$3 -> 0 | K5: =J5*G5 -> 0 | L5: =J5*H5 -> 0 | M5: =J5*I5 -> 0 | N5: =ROUNDUP(J5*Paramètres!$B$19,-1) -> 0 | O5: =N5 -> 0 | P5: =O5/10 -> 0 | Q5: =ROUNDUP((O5+P5)/100,-1) -> 0 | R5: =ROUNDUP(+K5/Paramètres!$B$4/Paramètres!$B$53,0) -> 0 | S5: =ROUNDUP(+L5/Paramètres!$B$6/Paramètres!$B$53,0) -> 0 | U5: =R5+S5+T5 -> 0 | V5: =R5*Paramètres!$B$7 -> 0 | W5: =S5*Paramètres!$B$9 -> 0 | Y5: =V5+W5+X5 -> 0 | Z5: =R5*Paramètres!$B$10 -> 0 | AA5: =S5*Paramètres!$B$10 -> 0 | AC5: =Z5+AA5+AB5 -> 0 | AD5: =U5 -> 0 | AE5: =ROUNDUP((U5/200)*2,0)*10 -> 0 | AF5: =IF(B5="",0,Paramètres!$B$53*1.5) -> 0 | AG5: =IF(C5="",0,Paramètres!$B$53*1.5) -> 0 | AL5: =(U5*Paramètres!$B$53)*3 -> 0 | AM5: =N5 -> 0 | AN5: =U5*Paramètres!$B$75 -> 0 | AO5: =U5*Paramètres!$B$72*Paramètres!$B$73 -> 0 | AQ5: =(Y5+AC5)*Paramètres!$B$42*Paramètres!$B$53 -> 0 | AS5: =ROUNDUP(D5*Paramètres!$B$23*Paramètres!$B$26,-1) -> 0 | BI5: =AQ5+AS5 -> 0
A6: 4 | J6: =F6*Paramètres!$B$3 -> 0 | K6: =J6*G6 -> 0 | L6: =J6*H6 -> 0 | M6: =J6*I6 -> 0 | N6: =ROUNDUP(J6*Paramètres!$B$19,-1) -> 0 | O6: =N6 -> 0 | P6: =O6/10 -> 0 | Q6: =ROUNDUP((O6+P6)/100,-1) -> 0 | R6: =ROUNDUP(+K6/Paramètres!$B$4/Paramètres!$B$53,0) -> 0 | S6: =ROUNDUP(+L6/Paramètres!$B$6/Paramètres!$B$53,0) -> 0 | U6: =R6+S6+T6 -> 0 | V6: =R6*Paramètres!$B$7 -> 0 | W6: =S6*Paramètres!$B$9 -> 0 | Y6: =V6+W6+X6 -> 0 | Z6: =R6*Paramètres!$B$10 -> 0 | AA6: =S6*Paramètres!$B$10 -> 0 | AC6: =Z6+AA6+AB6 -> 0 | AD6: =U6 -> 0 | AE6: =ROUNDUP((U6/200)*2,0)*10 -> 0 | AF6: =IF(B6="",0,Paramètres!$B$53*1.5) -> 0 | AG6: =IF(C6="",0,Paramètres!$B$53*1.5) -> 0 | AL6: =(U6*Paramètres!$B$53)*3 -> 0 | AM6: =N6 -> 0 | AN6: =U6*Paramètres!$B$75 -> 0 | AO6: =U6*Paramètres!$B$72*Paramètres!$B$73 -> 0 | AQ6: =(Y6+AC6)*Paramètres!$B$42*Paramètres!$B$53 -> 0 | AS6: =ROUNDUP(D6*Paramètres!$B$23*Paramètres!$B$26,-1) -> 0 | BI6: =AQ6+AS6 -> 0
A7: 5 | J7: =F7*Paramètres!$B$3 -> 0 | K7: =J7*G7 -> 0 | L7: =J7*H7 -> 0 | M7: =J7*I7 -> 0 | N7: =ROUNDUP(J7*Paramètres!$B$19,-1) -> 0 | O7: =N7 -> 0 | P7: =O7/10 -> 0 | Q7: =ROUNDUP((O7+P7)/100,-1) -> 0 | R7: =ROUNDUP(+K7/Paramètres!$B$4/Paramètres!$B$53,0) -> 0 | S7: =ROUNDUP(+L7/Paramètres!$B$6/Paramètres!$B$53,0) -> 0 | U7: =R7+S7+T7 -> 0 | V7: =R7*Paramètres!$B$7 -> 0 | W7: =S7*Paramètres!$B$9 -> 0 | Y7: =V7+W7+X7 -> 0 | Z7: =R7*Paramètres!$B$10 -> 0 | AA7: =S7*Paramètres!$B$10 -> 0 | AC7: =Z7+AA7+AB7 -> 0 | AD7: =U7 -> 0 | AE7: =ROUNDUP((U7/200)*2,0)*10 -> 0 | AF7: =IF(B7="",0,Paramètres!$B$53*1.5) -> 0 | AG7: =IF(C7="",0,Paramètres!$B$53*1.5) -> 0 | AL7: =(U7*Paramètres!$B$53)*3 -> 0 | AM7: =N7 -> 0 | AN7: =U7*Paramètres!$B$75 -> 0 | AO7: =U7*Paramètres!$B$72*Paramètres!$B$73 -> 0 | AQ7: =(Y7+AC7)*Paramètres!$B$42*Paramètres!$B$53 -> 0 | AS7: =ROUNDUP(D7*Paramètres!$B$23*Paramètres!$B$26,-1) -> 0 | BI7: =AQ7+AS7 -> 0
A8: 6 | J8: =F8*Paramètres!$B$3 -> 0 | K8: =J8*G8 -> 0 | L8: =J8*H8 -> 0 | M8: =J8*I8 -> 0 | N8: =ROUNDUP(J8*Paramètres!$B$19,-1) -> 0 | O8: =N8 -> 0 | P8: =O8/10 -> 0 | Q8: =ROUNDUP((O8+P8)/100,-1) -> 0 | R8: =ROUNDUP(+K8/Paramètres!$B$4/Paramètres!$B$53,0) -> 0 | S8: =ROUNDUP(+L8/Paramètres!$B$6/Paramètres!$B$53,0) -> 0 | U8: =R8+S8+T8 -> 0 | V8: =R8*Paramètres!$B$7 -> 0 | W8: =S8*Paramètres!$B$9 -> 0 | Y8: =V8+W8+X8 -> 0 | Z8: =R8*Paramètres!$B$10 -> 0 | AA8: =S8*Paramètres!$B$10 -> 0 | AC8: =Z8+AA8+AB8 -> 0 | AD8: =U8 -> 0 | AE8: =ROUNDUP((U8/200)*2,0)*10 -> 0 | AF8: =IF(B8="",0,Paramètres!$B$53*1.5) -> 0 | AG8: =IF(C8="",0,Paramètres!$B$53*1.5) -> 0 | AL8: =(U8*Paramètres!$B$53)*3 -> 0 | AM8: =N8 -> 0 | AN8: =U8*Paramètres!$B$75 -> 0 | AO8: =U8*Paramètres!$B$72*Paramètres!$B$73 -> 0 | AQ8: =(Y8+AC8)*Paramètres!$B$42*Paramètres!$B$53 -> 0 | AS8: =ROUNDUP(D8*Paramètres!$B$23*Paramètres!$B$26,-1) -> 0 | BI8: =AQ8+AS8 -> 0
A9: 7 | J9: =F9*Paramètres!$B$3 -> 0 | K9: =J9*G9 -> 0 | L9: =J9*H9 -> 0 | M9: =J9*I9 -> 0 | N9: =ROUNDUP(J9*Paramètres!$B$19,-1) -> 0 | O9: =N9 -> 0 | P9: =O9/10 -> 0 | Q9: =ROUNDUP((O9+P9)/100,-1) -> 0 | R9: =ROUNDUP(+K9/Paramètres!$B$4/Paramètres!$B$53,0) -> 0 | S9: =ROUNDUP(+L9/Paramètres!$B$6/Paramètres!$B$53,0) -> 0 | U9: =R9+S9+T9 -> 0 | V9: =R9*Paramètres!$B$7 -> 0 | W9: =S9*Paramètres!$B$9 -> 0 | Y9: =V9+W9+X9 -> 0 | Z9: =R9*Paramètres!$B$10 -> 0 | AA9: =S9*Paramètres!$B$10 -> 0 | AC9: =Z9+AA9+AB9 -> 0 | AD9: =U9 -> 0 | AE9: =ROUNDUP((U9/200)*2,0)*10 -> 0 | AF9: =IF(B9="",0,Paramètres!$B$53*1.5) -> 0 | AG9: =IF(C9="",0,Paramètres!$B$53*1.5) -> 0 | AL9: =(U9*Paramètres!$B$53)*3 -> 0 | AM9: =N9 -> 0 | AN9: =U9*Paramètres!$B$75 -> 0 | AO9: =U9*Paramètres!$B$72*Paramètres!$B$73 -> 0 | AQ9: =(Y9+AC9)*Paramètres!$B$42*Paramètres!$B$53 -> 0 | AS9: =ROUNDUP(D9*Paramètres!$B$23*Paramètres!$B$26,-1) -> 0 | BI9: =AQ9+AS9 -> 0
A10: 8 | J10: =F10*Paramètres!$B$3 -> 0 | K10: =J10*G10 -> 0 | L10: =J10*H10 -> 0 | M10: =J10*I10 -> 0 | N10: =ROUNDUP(J10*Paramètres!$B$19,-1) -> 0 | O10: =N10 -> 0 | P10: =O10/10 -> 0 | Q10: =ROUNDUP((O10+P10)/100,-1) -> 0 | R10: =ROUNDUP(+K10/Paramètres!$B$4/Paramètres!$B$53,0) -> 0 | S10: =ROUNDUP(+L10/Paramètres!$B$6/Paramètres!$B$53,0) -> 0 | U10: =R10+S10+T10 -> 0 | V10: =R10*Paramètres!$B$7 -> 0 | W10: =S10*Paramètres!$B$9 -> 0 | Y10: =V10+W10+X10 -> 0 | Z10: =R10*Paramètres!$B$10 -> 0 | AA10: =S10*Paramètres!$B$10 -> 0 | AC10: =Z10+AA10+AB10 -> 0 | AD10: =U10 -> 0 | AE10: =ROUNDUP((U10/200)*2,0)*10 -> 0 | AF10: =IF(B10="",0,Paramètres!$B$53*1.5) -> 0 | AG10: =IF(C10="",0,Paramètres!$B$53*1.5) -> 0 | AL10: =(U10*Paramètres!$B$53)*3 -> 0 | AM10: =N10 -> 0 | AN10: =U10*Paramètres!$B$75 -> 0 | AO10: =U10*Paramètres!$B$72*Paramètres!$B$73 -> 0 | AQ10: =(Y10+AC10)*Paramètres!$B$42*Paramètres!$B$53 -> 0 | AS10: =ROUNDUP(D10*Paramètres!$B$23*Paramètres!$B$26,-1) -> 0 | BI10: =AQ10+AS10 -> 0
A11: 9 | J11: =F11*Paramètres!$B$3 -> 0 | K11: =J11*G11 -> 0 | L11: =J11*H11 -> 0 | M11: =J11*I11 -> 0 | N11: =ROUNDUP(J11*Paramètres!$B$19,-1) -> 0 | O11: =N11 -> 0 | P11: =O11/10 -> 0 | Q11: =ROUNDUP((O11+P11)/100,-1) -> 0 | R11: =ROUNDUP(+K11/Paramètres!$B$4/Paramètres!$B$53,0) -> 0 | S11: =ROUNDUP(+L11/Paramètres!$B$6/Paramètres!$B$53,0) -> 0 | U11: =R11+S11+T11 -> 0 | V11: =R11*Paramètres!$B$7 -> 0 | W11: =S11*Paramètres!$B$9 -> 0 | Y11: =V11+W11+X11 -> 0 | Z11: =R11*Paramètres!$B$10 -> 0 | AA11: =S11*Paramètres!$B$10 -> 0 | AC11: =Z11+AA11+AB11 -> 0 | AD11: =U11 -> 0 | AE11: =ROUNDUP((U11/200)*2,0)*10 -> 0 | AF11: =IF(B11="",0,Paramètres!$B$53*1.5) -> 0 | AG11: =IF(C11="",0,Paramètres!$B$53*1.5) -> 0 | AL11: =(U11*Paramètres!$B$53)*3 -> 0 | AM11: =N11 -> 0 | AN11: =U11*Paramètres!$B$75 -> 0 | AO11: =U11*Paramètres!$B$72*Paramètres!$B$73 -> 0 | AQ11: =(Y11+AC11)*Paramètres!$B$42*Paramètres!$B$53 -> 0 | AS11: =ROUNDUP(D11*Paramètres!$B$23*Paramètres!$B$26,-1) -> 0 | BI11: =AQ11+AS11 -> 0
A12: 10 | J12: =F12*Paramètres!$B$3 -> 0 | K12: =J12*G12 -> 0 | L12: =J12*H12 -> 0 | M12: =J12*I12 -> 0 | N12: =ROUNDUP(J12*Paramètres!$B$19,-1) -> 0 | O12: =N12 -> 0 | P12: =O12/10 -> 0 | Q12: =ROUNDUP((O12+P12)/100,-1) -> 0 | R12: =ROUNDUP(+K12/Paramètres!$B$4/Paramètres!$B$53,0) -> 0 | S12: =ROUNDUP(+L12/Paramètres!$B$6/Paramètres!$B$53,0) -> 0 | U12: =R12+S12+T12 -> 0 | V12: =R12*Paramètres!$B$7 -> 0 | W12: =S12*Paramètres!$B$9 -> 0 | Y12: =V12+W12+X12 -> 0 | Z12: =R12*Paramètres!$B$10 -> 0 | AA12: =S12*Paramètres!$B$10 -> 0 | AC12: =Z12+AA12+AB12 -> 0 | AD12: =U12 -> 0 | AE12: =ROUNDUP((U12/200)*2,0)*10 -> 0 | AF12: =IF(B12="",0,Paramètres!$B$53*1.5) -> 0 | AG12: =IF(C12="",0,Paramètres!$B$53*1.5) -> 0 | AL12: =(U12*Paramètres!$B$53)*3 -> 0 | AM12: =N12 -> 0 | AN12: =U12*Paramètres!$B$75 -> 0 | AO12: =U12*Paramètres!$B$72*Paramètres!$B$73 -> 0 | AQ12: =(Y12+AC12)*Paramètres!$B$42*Paramètres!$B$53 -> 0 | AS12: =ROUNDUP(D12*Paramètres!$B$23*Paramètres!$B$26,-1) -> 0 | BI12: =AQ12+AS12 -> 0
A13: 11 | J13: =F13*Paramètres!$B$3 -> 0 | K13: =J13*G13 -> 0 | L13: =J13*H13 -> 0 | M13: =J13*I13 -> 0 | N13: =ROUNDUP(J13*Paramètres!$B$19,-1) -> 0 | O13: =N13 -> 0 | P13: =O13/10 -> 0 | Q13: =ROUNDUP((O13+P13)/100,-1) -> 0 | R13: =ROUNDUP(+K13/Paramètres!$B$4/Paramètres!$B$53,0) -> 0 | S13: =ROUNDUP(+L13/Paramètres!$B$6/Paramètres!$B$53,0) -> 0 | U13: =R13+S13+T13 -> 0 | V13: =R13*Paramètres!$B$7 -> 0 | W13: =S13*Paramètres!$B$9 -> 0 | Y13: =V13+W13+X13 -> 0 | Z13: =R13*Paramètres!$B$10 -> 0 | AA13: =S13*Paramètres!$B$10 -> 0 | AC13: =Z13+AA13+AB13 -> 0 | AD13: =U13 -> 0 | AE13: =ROUNDUP((U13/200)*2,0)*10 -> 0 | AF13: =IF(B13="",0,Paramètres!$B$53*1.5) -> 0 | AG13: =IF(C13="",0,Paramètres!$B$53*1.5) -> 0 | AL13: =(U13*Paramètres!$B$53)*3 -> 0 | AM13: =N13 -> 0 | AN13: =U13*Paramètres!$B$75 -> 0 | AO13: =U13*Paramètres!$B$72*Paramètres!$B$73 -> 0 | AQ13: =(Y13+AC13)*Paramètres!$B$42*Paramètres!$B$53 -> 0 | AS13: =ROUNDUP(D13*Paramètres!$B$23*Paramètres!$B$26,-1) -> 0 | BI13: =AQ13+AS13 -> 0
A14: 12 | J14: =F14*Paramètres!$B$3 -> 0 | K14: =J14*G14 -> 0 | L14: =J14*H14 -> 0 | M14: =J14*I14 -> 0 | N14: =ROUNDUP(J14*Paramètres!$B$19,-1) -> 0 | O14: =N14 -> 0 | P14: =O14/10 -> 0 | Q14: =ROUNDUP((O14+P14)/100,-1) -> 0 | R14: =ROUNDUP(+K14/Paramètres!$B$4/Paramètres!$B$53,0) -> 0 | S14: =ROUNDUP(+L14/Paramètres!$B$6/Paramètres!$B$53,0) -> 0 | U14: =R14+S14+T14 -> 0 | V14: =R14*Paramètres!$B$7 -> 0 | W14: =S14*Paramètres!$B$9 -> 0 | Y14: =V14+W14+X14 -> 0 | Z14: =R14*Paramètres!$B$10 -> 0 | AA14: =S14*Paramètres!$B$10 -> 0 | AC14: =Z14+AA14+AB14 -> 0 | AD14: =U14 -> 0 | AE14: =ROUNDUP((U14/200)*2,0)*10 -> 0 | AF14: =IF(B14="",0,Paramètres!$B$53*1.5) -> 0 | AG14: =IF(C14="",0,Paramètres!$B$53*1.5) -> 0 | AL14: =(U14*Paramètres!$B$53)*3 -> 0 | AM14: =N14 -> 0 | AN14: =U14*Paramètres!$B$75 -> 0 | AO14: =U14*Paramètres!$B$72*Paramètres!$B$73 -> 0 | AQ14: =(Y14+AC14)*Paramètres!$B$42*Paramètres!$B$53 -> 0 | AS14: =ROUNDUP(D14*Paramètres!$B$23*Paramètres!$B$26,-1) -> 0 | BI14: =AQ14+AS14 -> 0
... A53: 51 | J53: =F53*Paramètres!$B$3 -> 0 | K53: =J53*G53 -> 0 | L53: =J53*H53 -> 0 | M53: =J53*I53 -> 0 | N53: =ROUNDUP(J53*Paramètres!$B$19,-1) -> 0 | O53: =N53 -> 0 | P53: =O53/10 -> 0 | Q53: =ROUNDUP((O53+P53)/100,-1) -> 0 | R53: =ROUNDUP(+K53/Paramètres!$B$4/Paramètres!$B$53,0) -> 0 | S53: =ROUNDUP(+L53/Paramètres!$B$6/Paramètres!$B$53,0) -> 0 | U53: =R53+S53+T53 -> 0 | V53: =R53*Paramètres!$B$7 -> 0 | W53: =S53*Paramètres!$B$9 -> 0 | Y53: =V53+W53+X53 -> 0 | Z53: =R53*Paramètres!$B$10 -> 0 | AA53: =S53*Paramètres!$B$10 -> 0 | AC53: =Z53+AA53+AB53 -> 0 | AD53: =U53 -> 0 | AE53: =ROUNDUP((U53/200)*2,0)*10 -> 0 | AF53: =IF(B53="",0,Paramètres!$B$53*1.5) -> 0 | AG53: =IF(C53="",0,Paramètres!$B$53*1.5) -> 0 | AL53: =(U53*Paramètres!$B$53)*3 -> 0 | AM53: =N53 -> 0 | AN53: =U53*Paramètres!$B$75 -> 0 | AO53: =U53*Paramètres!$B$72*Paramètres!$B$73 -> 0 | AQ53: =(Y53+AC53)*Paramètres!$B$42*Paramètres!$B$53 -> 0 | AS53: =ROUNDUP(D53*Paramètres!$B$23*Paramètres!$B$26,-1) -> 0 | BI53: =AQ53+AS53 -> 0
J54: =F54*Paramètres!$B$3 -> 0 | K54: =J54*G54 -> 0 | L54: =J54*H54 -> 0 | M54: =J54*I54 -> 0 | N54: =ROUNDUP(J54*Paramètres!$B$19,-1) -> 0 | O54: =N54 -> 0 | P54: =O54/10 -> 0 | Q54: =ROUNDUP((O54+P54)/100,-1) -> 0 | R54: =ROUNDUP(+K54/Paramètres!$B$4/Paramètres!$B$53,0) -> 0 | S54: =ROUNDUP(+L54/Paramètres!$B$6/Paramètres!$B$53,0) -> 0 | U54: =R54+S54+T54 -> 0 | V54: =R54*Paramètres!$B$7 -> 0 | W54: =S54*Paramètres!$B$9 -> 0 | Y54: =V54+W54+X54 -> 0 | Z54: =R54*Paramètres!$B$10 -> 0 | AA54: =S54*Paramètres!$B$10 -> 0 | AC54: =Z54+AA54+AB54 -> 0 | AD54: =U54 -> 0 | AE54: =ROUNDUP((U54/200)*2,0)*10 -> 0 | AF54: =IF(B54="",0,Paramètres!$B$53*1.5) -> 0 | AG54: =IF(C54="",0,Paramètres!$B$53*1.5) -> 0 | AL54: =(U54*Paramètres!$B$53)*3 -> 0 | AM54: =N54 -> 0 | AN54: =U54*Paramètres!$B$75 -> 0 | AO54: =U54*Paramètres!$B$72*Paramètres!$B$73 -> 0 | AQ54: =(Y54+AC54)*Paramètres!$B$42*Paramètres!$B$53 -> 0 | AS54: =ROUNDUP(D54*Paramètres!$B$23*Paramètres!$B$26,-1) -> 0 | BI54: =AQ54+AS54 -> 0
J55: =F55*Paramètres!$B$3 -> 0 | K55: =J55*G55 -> 0 | L55: =J55*H55 -> 0 | M55: =J55*I55 -> 0 | N55: =ROUNDUP(J55*Paramètres!$B$19,-1) -> 0 | O55: =N55 -> 0 | P55: =O55/10 -> 0 | Q55: =ROUNDUP((O55+P55)/100,-1) -> 0 | R55: =ROUNDUP(+K55/Paramètres!$B$4/Paramètres!$B$53,0) -> 0 | S55: =ROUNDUP(+L55/Paramètres!$B$6/Paramètres!$B$53,0) -> 0 | U55: =R55+S55+T55 -> 0 | V55: =R55*Paramètres!$B$7 -> 0 | W55: =S55*Paramètres!$B$9 -> 0 | Y55: =V55+W55+X55 -> 0 | Z55: =R55*Paramètres!$B$10 -> 0 | AA55: =S55*Paramètres!$B$10 -> 0 | AC55: =Z55+AA55+AB55 -> 0 | AD55: =U55 -> 0 | AE55: =ROUNDUP((U55/200)*2,0)*10 -> 0 | AF55: =IF(B55="",0,Paramètres!$B$53*1.5) -> 0 | AG55: =IF(C55="",0,Paramètres!$B$53*1.5) -> 0 | AL55: =(U55*Paramètres!$B$53)*3 -> 0 | AM55: =N55 -> 0 | AN55: =U55*Paramètres!$B$75 -> 0 | AO55: =U55*Paramètres!$B$72*Paramètres!$B$73 -> 0 | AQ55: =(Y55+AC55)*Paramètres!$B$42*Paramètres!$B$53 -> 0 | AS55: =ROUNDUP(D55*Paramètres!$B$23*Paramètres!$B$26,-1) -> 0 | BI55: =AQ55+AS55 -> 0
J56: =F56*Paramètres!$B$3 -> 0 | K56: =J56*G56 -> 0 | L56: =J56*H56 -> 0 | M56: =J56*I56 -> 0 | N56: =ROUNDUP(J56*Paramètres!$B$19,-1) -> 0 | O56: =N56 -> 0 | P56: =O56/10 -> 0 | Q56: =ROUNDUP((O56+P56)/100,-1) -> 0 | R56: =ROUNDUP(+K56/Paramètres!$B$4/Paramètres!$B$53,0) -> 0 | S56: =ROUNDUP(+L56/Paramètres!$B$6/Paramètres!$B$53,0) -> 0 | U56: =R56+S56+T56 -> 0 | V56: =R56*Paramètres!$B$7 -> 0 | W56: =S56*Paramètres!$B$9 -> 0 | Y56: =V56+W56+X56 -> 0 | Z56: =R56*Paramètres!$B$10 -> 0 | AA56: =S56*Paramètres!$B$10 -> 0 | AC56: =Z56+AA56+AB56 -> 0 | AD56: =U56 -> 0 | AE56: =ROUNDUP((U56/200)*2,0)*10 -> 0 | AF56: =IF(B56="",0,Paramètres!$B$53*1.5) -> 0 | AG56: =IF(C56="",0,Paramètres!$B$53*1.5) -> 0 | AL56: =(U56*Paramètres!$B$53)*3 -> 0 | AM56: =N56 -> 0 | AN56: =U56*Paramètres!$B$75 -> 0 | AO56: =U56*Paramètres!$B$72*Paramètres!$B$73 -> 0 | AQ56: =(Y56+AC56)*Paramètres!$B$42*Paramètres!$B$53 -> 0 | AS56: =ROUNDUP(D56*Paramètres!$B$23*Paramètres!$B$26,-1) -> 0 | BI56: =AQ56+AS56 -> 0
J57: =F57*Paramètres!$B$3 -> 0 | K57: =J57*G57 -> 0 | L57: =J57*H57 -> 0 | M57: =J57*I57 -> 0 | N57: =ROUNDUP(J57*Paramètres!$B$19,-1) -> 0 | O57: =N57 -> 0 | P57: =O57/10 -> 0 | Q57: =ROUNDUP((O57+P57)/100,-1) -> 0 | R57: =ROUNDUP(+K57/Paramètres!$B$4/Paramètres!$B$53,0) -> 0 | S57: =ROUNDUP(+L57/Paramètres!$B$6/Paramètres!$B$53,0) -> 0 | U57: =R57+S57+T57 -> 0 | V57: =R57*Paramètres!$B$7 -> 0 | W57: =S57*Paramètres!$B$9 -> 0 | Y57: =V57+W57+X57 -> 0 | Z57: =R57*Paramètres!$B$10 -> 0 | AA57: =S57*Paramètres!$B$10 -> 0 | AC57: =Z57+AA57+AB57 -> 0 | AD57: =U57 -> 0 | AE57: =ROUNDUP((U57/200)*2,0)*10 -> 0 | AF57: =IF(B57="",0,Paramètres!$B$53*1.5) -> 0 | AG57: =IF(C57="",0,Paramètres!$B$53*1.5) -> 0 | AL57: =(U57*Paramètres!$B$53)*3 -> 0 | AM57: =N57 -> 0 | AN57: =U57*Paramètres!$B$75 -> 0 | AO57: =U57*Paramètres!$B$72*Paramètres!$B$73 -> 0 | AQ57: =(Y57+AC57)*Paramètres!$B$42*Paramètres!$B$53 -> 0 | AS57: =ROUNDUP(D57*Paramètres!$B$23*Paramètres!$B$26,-1) -> 0 | BI57: =AQ57+AS57 -> 0
J58: =F58*Paramètres!$B$3 -> 0 | K58: =J58*G58 -> 0 | L58: =J58*H58 -> 0 | M58: =J58*I58 -> 0 | N58: =ROUNDUP(J58*Paramètres!$B$19,-1) -> 0 | O58: =N58 -> 0 | P58: =O58/10 -> 0 | Q58: =ROUNDUP((O58+P58)/100,-1) -> 0 | R58: =ROUNDUP(+K58/Paramètres!$B$4/Paramètres!$B$53,0) -> 0 | S58: =ROUNDUP(+L58/Paramètres!$B$6/Paramètres!$B$53,0) -> 0 | U58: =R58+S58+T58 -> 0 | V58: =R58*Paramètres!$B$7 -> 0 | W58: =S58*Paramètres!$B$9 -> 0 | Y58: =V58+W58+X58 -> 0 | Z58: =R58*Paramètres!$B$10 -> 0 | AA58: =S58*Paramètres!$B$10 -> 0 | AC58: =Z58+AA58+AB58 -> 0 | AD58: =U58 -> 0 | AE58: =ROUNDUP((U58/200)*2,0)*10 -> 0 | AF58: =IF(B58="",0,Paramètres!$B$53*1.5) -> 0 | AG58: =IF(C58="",0,Paramètres!$B$53*1.5) -> 0 | AL58: =(U58*Paramètres!$B$53)*3 -> 0 | AM58: =N58 -> 0 | AN58: =U58*Paramètres!$B$75 -> 0 | AO58: =U58*Paramètres!$B$72*Paramètres!$B$73 -> 0 | AQ58: =(Y58+AC58)*Paramètres!$B$42*Paramètres!$B$53 -> 0 | AS58: =ROUNDUP(D58*Paramètres!$B$23*Paramètres!$B$26,-1) -> 0 | BI58: =AQ58+AS58 -> 0
J59: =F59*Paramètres!$B$3 -> 0 | K59: =J59*G59 -> 0 | L59: =J59*H59 -> 0 | M59: =J59*I59 -> 0 | N59: =ROUNDUP(J59*Paramètres!$B$19,-1) -> 0 | O59: =N59 -> 0 | P59: =O59/10 -> 0 | Q59: =ROUNDUP((O59+P59)/100,-1) -> 0 | R59: =ROUNDUP(+K59/Paramètres!$B$4/Paramètres!$B$53,0) -> 0 | S59: =ROUNDUP(+L59/Paramètres!$B$6/Paramètres!$B$53,0) -> 0 | U59: =R59+S59+T59 -> 0 | V59: =R59*Paramètres!$B$7 -> 0 | W59: =S59*Paramètres!$B$9 -> 0 | Y59: =V59+W59+X59 -> 0 | Z59: =R59*Paramètres!$B$10 -> 0 | AA59: =S59*Paramètres!$B$10 -> 0 | AC59: =Z59+AA59+AB59 -> 0 | AD59: =U59 -> 0 | AE59: =ROUNDUP((U59/200)*2,0)*10 -> 0 | AF59: =IF(B59="",0,Paramètres!$B$53*1.5) -> 0 | AG59: =IF(C59="",0,Paramètres!$B$53*1.5) -> 0 | AL59: =(U59*Paramètres!$B$53)*3 -> 0 | AM59: =N59 -> 0 | AN59: =U59*Paramètres!$B$75 -> 0 | AO59: =U59*Paramètres!$B$72*Paramètres!$B$73 -> 0 | AQ59: =(Y59+AC59)*Paramètres!$B$42*Paramètres!$B$53 -> 0 | AS59: =ROUNDUP(D59*Paramètres!$B$23*Paramètres!$B$26,-1) -> 0 | BI59: =AQ59+AS59 -> 0
J60: =F60*Paramètres!$B$3 -> 0 | K60: =J60*G60 -> 0 | L60: =J60*H60 -> 0 | M60: =J60*I60 -> 0 | N60: =ROUNDUP(J60*Paramètres!$B$19,-1) -> 0 | O60: =N60 -> 0 | P60: =O60/10 -> 0 | Q60: =ROUNDUP((O60+P60)/100,-1) -> 0 | R60: =ROUNDUP(+K60/Paramètres!$B$4/Paramètres!$B$53,0) -> 0 | S60: =ROUNDUP(+L60/Paramètres!$B$6/Paramètres!$B$53,0) -> 0 | U60: =R60+S60+T60 -> 0 | V60: =R60*Paramètres!$B$7 -> 0 | W60: =S60*Paramètres!$B$9 -> 0 | Y60: =V60+W60+X60 -> 0 | Z60: =R60*Paramètres!$B$10 -> 0 | AA60: =S60*Paramètres!$B$10 -> 0 | AC60: =Z60+AA60+AB60 -> 0 | AD60: =U60 -> 0 | AE60: =ROUNDUP((U60/200)*2,0)*10 -> 0 | AF60: =IF(B60="",0,Paramètres!$B$53*1.5) -> 0 | AG60: =IF(C60="",0,Paramètres!$B$53*1.5) -> 0 | AL60: =(U60*Paramètres!$B$53)*3 -> 0 | AM60: =N60 -> 0 | AN60: =U60*Paramètres!$B$75 -> 0 | AO60: =U60*Paramètres!$B$72*Paramètres!$B$73 -> 0 | AQ60: =(Y60+AC60)*Paramètres!$B$42*Paramètres!$B$53 -> 0 | AS60: =ROUNDUP(D60*Paramètres!$B$23*Paramètres!$B$26,-1) -> 0 | BI60: =AQ60+AS60 -> 0
J61: =F61*Paramètres!$B$3 -> 0 | K61: =J61*G61 -> 0 | L61: =J61*H61 -> 0 | M61: =J61*I61 -> 0 | N61: =ROUNDUP(J61*Paramètres!$B$19,-1) -> 0 | O61: =N61 -> 0 | P61: =O61/10 -> 0 | Q61: =ROUNDUP((O61+P61)/100,-1) -> 0 | R61: =ROUNDUP(+K61/Paramètres!$B$4/Paramètres!$B$53,0) -> 0 | S61: =ROUNDUP(+L61/Paramètres!$B$6/Paramètres!$B$53,0) -> 0 | U61: =R61+S61+T61 -> 0 | V61: =R61*Paramètres!$B$7 -> 0 | W61: =S61*Paramètres!$B$9 -> 0 | Y61: =V61+W61+X61 -> 0 | Z61: =R61*Paramètres!$B$10 -> 0 | AA61: =S61*Paramètres!$B$10 -> 0 | AC61: =Z61+AA61+AB61 -> 0 | AD61: =U61 -> 0 | AE61: =ROUNDUP((U61/200)*2,0)*10 -> 0 | AF61: =IF(B61="",0,Paramètres!$B$53*1.5) -> 0 | AG61: =IF(C61="",0,Paramètres!$B$53*1.5) -> 0 | AL61: =(U61*Paramètres!$B$53)*3 -> 0 | AM61: =N61 -> 0 | AN61: =U61*Paramètres!$B$75 -> 0 | AO61: =U61*Paramètres!$B$72*Paramètres!$B$73 -> 0 | AQ61: =(Y61+AC61)*Paramètres!$B$42*Paramètres!$B$53 -> 0 | AS61: =ROUNDUP(D61*Paramètres!$B$23*Paramètres!$B$26,-1) -> 0 | BI61: =AQ61+AS61 -> 0
J62: =F62*Paramètres!$B$3 -> 0 | K62: =J62*G62 -> 0 | L62: =J62*H62 -> 0 | M62: =J62*I62 -> 0 | N62: =ROUNDUP(J62*Paramètres!$B$19,-1) -> 0 | O62: =N62 -> 0 | P62: =O62/10 -> 0 | Q62: =ROUNDUP((O62+P62)/100,-1) -> 0 | R62: =ROUNDUP(+K62/Paramètres!$B$4/Paramètres!$B$53,0) -> 0 | S62: =ROUNDUP(+L62/Paramètres!$B$6/Paramètres!$B$53,0) -> 0 | U62: =R62+S62+T62 -> 0 | V62: =R62*Paramètres!$B$7 -> 0 | W62: =S62*Paramètres!$B$9 -> 0 | Y62: =V62+W62+X62 -> 0 | Z62: =R62*Paramètres!$B$10 -> 0 | AA62: =S62*Paramètres!$B$10 -> 0 | AC62: =Z62+AA62+AB62 -> 0 | AD62: =U62 -> 0 | AE62: =ROUNDUP((U62/200)*2,0)*10 -> 0 | AF62: =IF(B62="",0,Paramètres!$B$53*1.5) -> 0 | AG62: =IF(C62="",0,Paramètres!$B$53*1.5) -> 0 | AL62: =(U62*Paramètres!$B$53)*3 -> 0 | AM62: =N62 -> 0 | AN62: =U62*Paramètres!$B$75 -> 0 | AO62: =U62*Paramètres!$B$72*Paramètres!$B$73 -> 0 | AQ62: =(Y62+AC62)*Paramètres!$B$42*Paramètres!$B$53 -> 0 | AS62: =ROUNDUP(D62*Paramètres!$B$23*Paramètres!$B$26,-1) -> 0 | BI62: =AQ62+AS62 -> 0
J63: =F63*Paramètres!$B$3 -> 0 | K63: =J63*G63 -> 0 | L63: =J63*H63 -> 0 | M63: =J63*I63 -> 0 | N63: =ROUNDUP(J63*Paramètres!$B$19,-1) -> 0 | O63: =N63 -> 0 | P63: =O63/10 -> 0 | Q63: =ROUNDUP((O63+P63)/100,-1) -> 0 | R63: =ROUNDUP(+K63/Paramètres!$B$4/Paramètres!$B$53,0) -> 0 | S63: =ROUNDUP(+L63/Paramètres!$B$6/Paramètres!$B$53,0) -> 0 | U63: =R63+S63+T63 -> 0 | V63: =R63*Paramètres!$B$7 -> 0 | W63: =S63*Paramètres!$B$9 -> 0 | Y63: =V63+W63+X63 -> 0 | Z63: =R63*Paramètres!$B$10 -> 0 | AA63: =S63*Paramètres!$B$10 -> 0 | AC63: =Z63+AA63+AB63 -> 0 | AD63: =U63 -> 0 | AE63: =ROUNDUP((U63/200)*2,0)*10 -> 0 | AF63: =IF(B63="",0,Paramètres!$B$53*1.5) -> 0 | AG63: =IF(C63="",0,Paramètres!$B$53*1.5) -> 0 | AL63: =(U63*Paramètres!$B$53)*3 -> 0 | AM63: =N63 -> 0 | AN63: =U63*Paramètres!$B$75 -> 0 | AO63: =U63*Paramètres!$B$72*Paramètres!$B$73 -> 0 | AQ63: =(Y63+AC63)*Paramètres!$B$42*Paramètres!$B$53 -> 0 | AS63: =ROUNDUP(D63*Paramètres!$B$23*Paramètres!$B$26,-1) -> 0 | BI63: =AQ63+AS63 -> 0
J64: =F64*Paramètres!$B$3 -> 0 | K64: =J64*G64 -> 0 | L64: =J64*H64 -> 0 | M64: =J64*I64 -> 0 | N64: =ROUNDUP(J64*Paramètres!$B$19,-1) -> 0 | O64: =N64 -> 0 | P64: =O64/10 -> 0 | Q64: =ROUNDUP((O64+P64)/100,-1) -> 0 | R64: =ROUNDUP(+K64/Paramètres!$B$4/Paramètres!$B$53,0) -> 0 | S64: =ROUNDUP(+L64/Paramètres!$B$6/Paramètres!$B$53,0) -> 0 | U64: =R64+S64+T64 -> 0 | V64: =R64*Paramètres!$B$7 -> 0 | W64: =S64*Paramètres!$B$9 -> 0 | Y64: =V64+W64+X64 -> 0 | Z64: =R64*Paramètres!$B$10 -> 0 | AA64: =S64*Paramètres!$B$10 -> 0 | AC64: =Z64+AA64+AB64 -> 0 | AD64: =U64 -> 0 | AE64: =ROUNDUP((U64/200)*2,0)*10 -> 0 | AF64: =IF(B64="",0,Paramètres!$B$53*1.5) -> 0 | AG64: =IF(C64="",0,Paramètres!$B$53*1.5) -> 0 | AL64: =(U64*Paramètres!$B$53)*3 -> 0 | AM64: =N64 -> 0 | AN64: =U64*Paramètres!$B$75 -> 0 | AO64: =U64*Paramètres!$B$72*Paramètres!$B$73 -> 0 | AQ64: =(Y64+AC64)*Paramètres!$B$42*Paramètres!$B$53 -> 0 | AS64: =ROUNDUP(D64*Paramètres!$B$23*Paramètres!$B$26,-1) -> 0 | BI64: =AQ64+AS64 -> 0
J65: =F65*Paramètres!$B$3 -> 0 | K65: =J65*G65 -> 0 | L65: =J65*H65 -> 0 | M65: =J65*I65 -> 0 | N65: =ROUNDUP(J65*Paramètres!$B$19,-1) -> 0 | O65: =N65 -> 0 | P65: =O65/10 -> 0 | Q65: =ROUNDUP((O65+P65)/100,-1) -> 0 | R65: =ROUNDUP(+K65/Paramètres!$B$4/Paramètres!$B$53,0) -> 0 | S65: =ROUNDUP(+L65/Paramètres!$B$6/Paramètres!$B$53,0) -> 0 | U65: =R65+S65+T65 -> 0 | V65: =R65*Paramètres!$B$7 -> 0 | W65: =S65*Paramètres!$B$9 -> 0 | Y65: =V65+W65+X65 -> 0 | Z65: =R65*Paramètres!$B$10 -> 0 | AA65: =S65*Paramètres!$B$10 -> 0 | AC65: =Z65+AA65+AB65 -> 0 | AD65: =U65 -> 0 | AE65: =ROUNDUP((U65/200)*2,0)*10 -> 0 | AF65: =IF(B65="",0,Paramètres!$B$53*1.5) -> 0 | AG65: =IF(C65="",0,Paramètres!$B$53*1.5) -> 0 | AL65: =(U65*Paramètres!$B$53)*3 -> 0 | AM65: =N65 -> 0 | AN65: =U65*Paramètres!$B$75 -> 0 | AO65: =U65*Paramètres!$B$72*Paramètres!$B$73 -> 0 | AQ65: =(Y65+AC65)*Paramètres!$B$42*Paramètres!$B$53 -> 0 | AS65: =ROUNDUP(D65*Paramètres!$B$23*Paramètres!$B$26,-1) -> 0 | BI65: =AQ65+AS65 -> 0
... J71: =F71*Paramètres!$B$3 -> 0 | K71: =J71*G71 -> 0 | L71: =J71*H71 -> 0 | M71: =J71*I71 -> 0 | N71: =ROUNDUP(J71*Paramètres!$B$19,-1) -> 0 | O71: =N71 -> 0 | P71: =O71/10 -> 0 | Q71: =ROUNDUP((O71+P71)/100,-1) -> 0 | R71: =ROUNDUP(+K71/Paramètres!$B$4/Paramètres!$B$53,0) -> 0 | S71: =ROUNDUP(+L71/Paramètres!$B$6/Paramètres!$B$53,0) -> 0 | U71: =R71+S71+T71 -> 0 | V71: =R71*Paramètres!$B$7 -> 0 | W71: =S71*Paramètres!$B$9 -> 0 | Y71: =V71+W71+X71 -> 0 | Z71: =R71*Paramètres!$B$10 -> 0 | AA71: =S71*Paramètres!$B$10 -> 0 | AC71: =Z71+AA71+AB71 -> 0 | AD71: =U71 -> 0 | AE71: =ROUNDUP((U71/200)*2,0)*10 -> 0 | AF71: =IF(B71="",0,Paramètres!$B$53*1.5) -> 0 | AG71: =IF(C71="",0,Paramètres!$B$53*1.5) -> 0 | AL71: =(U71*Paramètres!$B$53)*3 -> 0 | AM71: =N71 -> 0 | AN71: =U71*Paramètres!$B$75 -> 0 | AO71: =U71*Paramètres!$B$72*Paramètres!$B$73 -> 0 | AQ71: =(Y71+AC71)*Paramètres!$B$42*Paramètres!$B$53 -> 0 | AS71: =ROUNDUP(D71*Paramètres!$B$23*Paramètres!$B$26,-1) -> 0 | BI71: =AQ71+AS71 -> 0
A72: 0 | B72: District | C72: =SUM(C3:C71) -> 0 | D72: =SUM(D3:D71) -> 0 | E72: =SUM(E3:E71) -> 0 | J72: =SUM(J3:J71) -> 0 | K72: =SUM(K3:K71) -> 0 | L72: =SUM(L3:L71) -> 0 | M72: =SUM(M3:M71) -> 0 | N72: =SUM(N3:N71) -> 0 | O72: =SUM(O3:O71) -> 0 | P72: =SUM(P3:P71) -> 0 | Q72: =SUM(Q3:Q71) -> 0 | ... S72: =SUM(S3:S71) -> 0 | T72: =ROUNDUP(+M72/Paramètres!$B$5/Paramètres!$B$53,0) -> 0 | U72: =R72+S72+T72 -> 0 | V72: =SUM(V3:V71) -> 0 | W72: =SUM(W3:W71) -> 0 | X72: =(T72*Paramètres!B8+T72) -> 0 | Y72: =SUM(Y3:Y71) -> 0 | Z72: =SUM(Z3:Z71) -> 0 | AA72: =SUM(AA3:AA71) -> 0 | AB72: =T72*Paramètres!B10 -> 0 | AC72: =SUM(AC3:AC71) -> 0 | AD72: =SUM(AD3:AD71) -> 0 | AE72: =SUM(AE3:AE71) -> 0 | AF72: =SUM(AF3:AF71) -> 0 | AG72: =SUM(AG3:AG71) -> 0 | AH72: =IF(Q72=0,0,Paramètres!$B$53*2) -> 0 | AI72: =IF(N72=0,0,Paramètres!$B$53*3) -> 0 | AL72: =SUM(AL3:AL71) -> 0 | AM72: =SUM(AM3:AM71) -> 0 | AN72: =SUM(AN3:AN71) -> 0 | AO72: =SUM(AO3:AO71) -> 0 | AP72: =ROUNDUP(AO72/Paramètres!B74,-1) -> 0 | AQ72: =SUM(AQ3:AQ71) -> 0 | AR72: =(X72+AB72)*Paramètres!B42*Paramètres!$B$53 -> 0 | AS72: =SUM(AS3:AS71) -> 0 | AT72: =ROUNDUP(E72*Paramètres!$B$22*Paramètres!$B$25,-1) -> 0 | AU72: =Paramètres!B51*0 -> 0 | AV72: =ROUNDUP(Q72*Paramètres!$B$52+Paramètres!$B$27*30,-3)*0 -> 0 | AW72: =(A72+Y72+AB72+AC72)*Paramètres!$B$60 -> 0 | AX72: =(A72+X72+Y72+AB72+AC72)*Paramètres!$B$63*Paramètres!$B$66 -> 0 | AY72: =Paramètres!$B$64*Paramètres!$B$66*Paramètres!$B$63*0 -> 0 | AZ72: =Paramètres!$B$64*Paramètres!$B$66*Paramètres!$B$79*0 -> 0 | BA72: =(X72+Y72+AB72+AC72+Paramètres!$B$64)*Paramètres!$B$61*Paramètres!$B$66*0 -> 0 | BB72: =AW72+AX72+AY72+BA72+AZ72 -> 0 | BC72: =A72*Paramètres!$B$69*Paramètres!$B$53 -> 0 | BD72: =AP72*Paramètres!$B$70 -> 0 | BE72: =Paramètres!B76*Paramètres!$B$66*Paramètres!$B$62*0 -> 0 | BF72: =Paramètres!B76*Paramètres!$B$61*0 -> 0 | BG72: =BE72+BF72 -> 0 | BH72: =Paramètres!B77*0 -> 0 | BI72: =AQ72+AS72+AU72+AV72 -> 0

Sheet DISTRICT7
G1: % à Couvrir par stratégies | K1: Population Cibles à vacciner par stratégies | O1: Seringues | R1: nombre équipes | V1: Nombres d'agents | Z1: Nombres de volontaires | AD1: Intrants | AQ1: Coûts | AU1: Incinération déchets | AW1: Formations vaccinateurs volontaires | BE1: Formation opérateurs
A2: N° | B2: Aires de santé | C2: Nombre villages | D2: Distance à parcourir SA | E2: Distance à parcourir EM | F2: POP TOTAL 2016 | G2: CF | H2: SA | I2: EM | J2: Cible Totale | K2: CF | L2: SA | M2: EMS | N2: Nombre doses de MenAfiVac | O2: Seringues Autobloquantes (SAB) | P2: Seringues de dilution (S D) | Q2: Boites de sécurité (BS) | R2: CF | S2: SA | T2: EMS | U2: Total | V2: CF | W2: SA | X2: EMS plus chauffeurs | Y2: Total agents vaccinateurs | Z2: CF | AA2: SA | AB2: EMS | AC2: Total volontaires | AD2: Besoins en coton (2 rouleaux de 500g par équipe) | AE2: Fiches de pointage | AF2: Fiche synthèse journalière Aire de santé | AG2: Fiche synthèse journalière utilisation du matériel d'injection | AH2: Fiche de réception/déstruction déchets | AI2: Fiches synthèse élimimation déchets au niveau district sanitaire | AJ2: Fiches monitorage et d'évaluation rapide | AK2: Fiches de synthèse | AL2: Besoins en sachets poubelles | AM2: Cartes de vaccination | AN2: Module par équipe | AO2: Nombre de Gants | AP2: Nombre boites de Gants | AQ2: Perdiem vaccinateurs/volontaires centre fixe et avancée | AR2: Perdiem vaccinateurs/volontaires équipes mobiles | AS2: Coûts de déplacement stratégie avancée | AT2: Coûts de déplacement des Equipes Mobiles | AU2: Aménagement Fosse | AV2: Frais d'incinération déchets (opérateurs) F CFA | AW2: Frais Transport | AX2: Perdiem participants | AY2: Perdiem Facilitateurs district | AZ2: Frais de facilitation des formateurs district | BA2: Pauses | BB2: Total Formation | BC2: Coût coordination au niveau aire de santé | BD2: Coût Gants | BE2: Perdiem | BF2: Pause | BG2: Total | BH2: Forfait gestion MAPI | BI2: Coûts Totaux
