Workbook

Sheet Index
B3: IMMUNIZATION & VACCINE DEVELOPMENT (IVD) PROGRAMME
B5: REC PLANNING TOOL FOR ESTIMATING BUDGET AND LOGISTICS
G8: INPUT SHEETS (TO BE FILLED AT CHMT LEVEL)
G15: OUTPUT SHEETS

Sheet Var
B3: SETTING UP VARIABLES
B4: (Enter norms for budget allocation and vaccine details as per the immunization schedule)
B7: Name of Region: | G7: Name of Council: | K7: Planning Year:
B10: NORMS TO BE USED FOR ESTIMATION OF BUDGETARY REQUIREMENTS
B12: 1. Extra duty allowance:
B14: 1.1 | C14: Health facility staff in outreach teams/mobile teams | J14: . @ TZS / member / day
B16: 1.2 | C16: Community members in outreach teams/mobile teams | J16: . @ TZS / member / day
B18: 1.3 | C18: Officer for transporting vaccines from district HQ to health facilities | J18: . @ TZS / member / day
B20: 1.4 | C20: Driver for transporting vaccines from district HQ to health facilities | J20: . @ TZS / member / day
B22: 2. Per diem allowance in case of overnight stay:
B24: 2.1 | C24: Health Facility staff in outreach teams | J24: . @ TZS / member / night
B26: 2.2 | C26: Officer for transporting vaccines from district HQ to health facilities | J26: . @ TZS / member / night
B28: 2.3 | C28: Driver for transporting vaccines from district HQ to health facilities | J28: . @ TZS / member / night
B30: 3. Transportation cost:
B32: 3.1 | C32: Cost of fuel | J32: .@ TZS / Litre fuel
B34: 3.2 | C34: Kilometers per litre of fuel | J34: .@ Km / Litre fuel
B36: 3.3 | C36: Running cost per litre of fuel | J36: .@ TZS / Km | N36: =IFERROR((N32/N34),"")
B38: 4. Cold chain maintenance cost:
B40: 4.1 | C40: Refilling cost of LP Gas Cylinders | J40: .@ TZS / Cylinder
B42: 4.2 | C42: Purchase of new LP Gas Cylinders | J42: .@ TZS / Cylinder
B44: DETAILS OF VACCINES AS PER THE IMMUNIZATION SCHEDULE
B46: Vaccine & Diluents | E46: Doses per vial | G46: Doses required | I46: Mode of administration | K46: Wastage Rate (%) | M46: Syringe used | P46: Reconstitution (Yes/No)
B48: BCG | E48: 20 | G48: 1 | I48: Injectable | K48: 70 | M48: 0.05 ml AD syringe | P48: YES
B50: OPV | E50: 20 | G50: 4 | I50: Oral | K50: 10 | M50: Not applicable | P50: NO
B52: PCV 13 | E52: 1 | G52: 3 | I52: Injectable | K52: 5 | M52: 0.5 ml AD syringe | P52: NO
B54: Rota | E54: 1 | G54: 2 | I54: Oral | K54: 5 | M54: Not applicable | P54: NO
B56: Penta | E56: 10 | G56: 3 | I56: Injectable | K56: 10 | M56: 0.5 ml AD syringe | P56: NO
B58: MR | E58: 10 | G58: 2 | I58: Injectable | K58: 18 | M58: 0.5 ml AD syringe | P58: YES
B60: TT | E60: 20 | G60: 2 | I60: Injectable | K60: 10 | M60: 0.5 ml AD syringe | P60: NO
B62: IPV | E62: 5 | G62: 1 | I62: Injectable | K62: 10 | M62: 0.5 ml AD syringe | P62: NO
B64: HPV | E64: 1 | G64: 2 | I64: Injectable | K64: 5 | M64: 0.5 ml AD syringe | P64: NO
B66: OTHER REQUIREMENTS
B68: Safety boxes: | D68: Number of syringes that can be disposed in one safety box (including AD and disposable syringes): | N68: 100
Q74: List creation:
Q75: doses required | R75: route of admin. | S75: Syringe | U75: Recons.
Q76: 1 | R76: Oral | S76: 0.05 ml AD syringe | U76: YES
Q77: 2 | R77: Injectable | S77: 0.5 ml AD syringe | U77: NO
Q78: 3 | S78: Not applicable
Q79: 4
Q80: 5

Sheet CHMTCmTm
BB1: Monday | BC1: 1 | BD1: YES
BB2: Tuesday | BC2: 2 | BD2: NO
I3: COMPILATION SHEET FOR HEALTH FACILITY PLANS | BB3: Wednesday | BC3: 3
I4: (Health Facility level plans are to be compiled in this template at the CMHT level) | BB4: Thursday | BC4: 4
AZ5: Outreach Session | BB5: Friday
B6: Name of Region: | F6: =IF(Var!D7=0,"",Var!D7) | K6: Name of Council: | O6: =IF(Var!I7=0,"",Var!I7) | T6: Planning Year: | W6: =IF(Var!N7=0,"",Var!N7) | AZ6: Mobile Clinic | BB6: Saturday
AZ7: Health Facility
B8: Name of Health Facility | F8: 1 | I8: 2.1 | K8: 2.2 | M8: 2.3 | O8: 3 | R8: 4 | T8: 5 | V8: 6 | AA8: 7.1 | AE8: 7.2 | AI8: 8.1 | AM8: 8.2 | AP8: 9 | AR8: 10 | AT8: 11 | AW8: 12 | BA8: counts
F9: Name of village | I9: Annual Beneficiaries | O9: Immunization services to be provided by… | R9: Weekday for organizing outreach/mobile clinic | T9: Week number for organizing outreach/mobile clinic | V9: Location/address of outreach session/mobile clinic in village | AA9: Team members from health facility | AI9: Team members from community | AP9: Distance of village from facility (Km) | AR9: Fare for transporting vaccines to outreach | AT9: Name of village leader | AW9: Overnight stay (YES/NO) | BA9: outreach | BB9: =COUNTIF(CHMTCmTm!O12:P264,"Outreach Session") -> 0
I10: Pregnant Women | K10: Surviving infants | M10: 12-24 month children | Q10: CODE | Z10: F1 | AA10: Facility staff 1 | AD10: F2 | AE10: Facility staff 2 | AH10: C1 | AI10: Community Member 1 | AL10: C2 | AM10: Community Member 2 | BA10: mobile | BB10: =COUNTIF(CHMTCmTm!O12:P264,"Mobile Clinic") -> 0
E11: =SUBTOTAL(9,E12:E264) -> 0 | F11: =E11 -> 0 | I11: =SUBTOTAL(9,I12:J264) -> 0 | K11: =SUBTOTAL(9,K12:L264) -> 0 | M11: =SUBTOTAL(9,M12:N264) -> 0 | Z11: =SUBTOTAL(9,Z12:Z264) -> 0 | AA11: =Z11 -> 0 | AD11: =SUBTOTAL(9,AD12:AD264) -> 0 | AE11: =AD11 -> 0 | AH11: =SUBTOTAL(9,AH12:AH264) -> 0 | AI11: =AH11 -> 0 | AL11: =SUBTOTAL(9,AL12:AL264) -> 0 | AM11: =AL11 -> 0 | AR11: =SUBTOTAL(9,AR12:AS264) -> 0 | AW11: =AZ11 -> 0 | AZ11: =SUBTOTAL(9,AZ12:BA264) -> 0 | BA11: facility | BB11: =COUNTIF(CHMTCmTm!O12:P264,"Health Facility") -> 0
E12: =IF(F12="",0,1) -> 0 | Q12: =IF(O12="Health Facility",3,IF(O12="Outreach Session",1,IF(O12="Mobile Clinic",2))) -> FALSE | Z12: =IF(AA12="",0,1) -> 0 | AD12: =IF(AE12="",0,1) -> 0 | AH12: =IF(AI12="",0,1) -> 0 | AL12: =IF(AM12="",0,1) -> 0 | AZ12: =IF(AW12="YES",1,0) -> 0
E13: =IF(F13="",0,1) -> 0 | Q13: =IF(O13="Health Facility",3,IF(O13="Outreach Session",1,IF(O13="Mobile Clinic",2))) -> FALSE | Z13: =IF(AA13="",0,1) -> 0 | AD13: =IF(AE13="",0,1) -> 0 | AH13: =IF(AI13="",0,1) -> 0 | AL13: =IF(AM13="",0,1) -> 0 | AZ13: =IF(AW13="YES",1,0) -> 0
E14: =IF(F14="",0,1) -> 0 | Q14: =IF(O14="Health Facility",3,IF(O14="Outreach Session",1,IF(O14="Mobile Clinic",2))) -> FALSE | Z14: =IF(AA14="",0,1) -> 0 | AD14: =IF(AE14="",0,1) -> 0 | AH14: =IF(AI14="",0,1) -> 0 | AL14: =IF(AM14="",0,1) -> 0 | AZ14: =IF(AW14="YES",1,0) -> 0
E15: =IF(F15="",0,1) -> 0 | Q15: =IF(O15="Health Facility",3,IF(O15="Outreach Session",1,IF(O15="Mobile Clinic",2))) -> FALSE | Z15: =IF(AA15="",0,1) -> 0 | AD15: =IF(AE15="",0,1) -> 0 | AH15: =IF(AI15="",0,1) -> 0 | AL15: =IF(AM15="",0,1) -> 0 | AZ15: =IF(AW15="YES",1,0) -> 0
E16: =IF(F16="",0,1) -> 0 | Q16: =IF(O16="Health Facility",3,IF(O16="Outreach Session",1,IF(O16="Mobile Clinic",2))) -> FALSE | Z16: =IF(AA16="",0,1) -> 0 | AD16: =IF(AE16="",0,1) -> 0 | AH16: =IF(AI16="",0,1) -> 0 | AL16: =IF(AM16="",0,1) -> 0 | AZ16: =IF(AW16="YES",1,0) -> 0
E17: =IF(F17="",0,1) -> 0 | Q17: =IF(O17="Health Facility",3,IF(O17="Outreach Session",1,IF(O17="Mobile Clinic",2))) -> FALSE | Z17: =IF(AA17="",0,1) -> 0 | AD17: =IF(AE17="",0,1) -> 0 | AH17: =IF(AI17="",0,1) -> 0 | AL17: =IF(AM17="",0,1) -> 0 | AZ17: =IF(AW17="YES",1,0) -> 0
E18: =IF(F18="",0,1) -> 0 | Q18: =IF(O18="Health Facility",3,IF(O18="Outreach Session",1,IF(O18="Mobile Clinic",2))) -> FALSE | Z18: =IF(AA18="",0,1) -> 0 | AD18: =IF(AE18="",0,1) -> 0 | AH18: =IF(AI18="",0,1) -> 0 | AL18: =IF(AM18="",0,1) -> 0 | AZ18: =IF(AW18="YES",1,0) -> 0
E19: =IF(F19="",0,1) -> 0 | Q19: =IF(O19="Health Facility",3,IF(O19="Outreach Session",1,IF(O19="Mobile Clinic",2))) -> FALSE | Z19: =IF(AA19="",0,1) -> 0 | AD19: =IF(AE19="",0,1) -> 0 | AH19: =IF(AI19="",0,1) -> 0 | AL19: =IF(AM19="",0,1) -> 0 | AZ19: =IF(AW19="YES",1,0) -> 0
E20: =IF(F20="",0,1) -> 0 | Q20: =IF(O20="Health Facility",3,IF(O20="Outreach Session",1,IF(O20="Mobile Clinic",2))) -> FALSE | Z20: =IF(AA20="",0,1) -> 0 | AD20: =IF(AE20="",0,1) -> 0 | AH20: =IF(AI20="",0,1) -> 0 | AL20: =IF(AM20="",0,1) -> 0 | AZ20: =IF(AW20="YES",1,0) -> 0
E21: =IF(F21="",0,1) -> 0 | Q21: =IF(O21="Health Facility",3,IF(O21="Outreach Session",1,IF(O21="Mobile Clinic",2))) -> FALSE | Z21: =IF(AA21="",0,1) -> 0 | AD21: =IF(AE21="",0,1) -> 0 | AH21: =IF(AI21="",0,1) -> 0 | AL21: =IF(AM21="",0,1) -> 0 | AZ21: =IF(AW21="YES",1,0) -> 0
E22: =IF(F22="",0,1) -> 0 | Q22: =IF(O22="Health Facility",3,IF(O22="Outreach Session",1,IF(O22="Mobile Clinic",2))) -> FALSE | Z22: =IF(AA22="",0,1) -> 0 | AD22: =IF(AE22="",0,1) -> 0 | AH22: =IF(AI22="",0,1) -> 0 | AL22: =IF(AM22="",0,1) -> 0 | AZ22: =IF(AW22="YES",1,0) -> 0
E23: =IF(F23="",0,1) -> 0 | Q23: =IF(O23="Health Facility",3,IF(O23="Outreach Session",1,IF(O23="Mobile Clinic",2))) -> FALSE | Z23: =IF(AA23="",0,1) -> 0 | AD23: =IF(AE23="",0,1) -> 0 | AH23: =IF(AI23="",0,1) -> 0 | AL23: =IF(AM23="",0,1) -> 0 | AZ23: =IF(AW23="YES",1,0) -> 0
... E192: =IF(F192="",0,1) -> 0 | Q192: =IF(O192="Health Facility",3,IF(O192="Outreach Session",1,IF(O192="Mobile Clinic",2))) -> FALSE | Z192: =IF(AA192="",0,1) -> 0 | AD192: =IF(AE192="",0,1) -> 0 | AH192: =IF(AI192="",0,1) -> 0 | AL192: =IF(AM192="",0,1) -> 0 | AZ192: =IF(AW192="YES",1,0) -> 0
E193: =IF(F193="",0,1) -> 0 | AH193: =IF(AI193="",0,1) -> 0 | AL193: =IF(AM193="",0,1) -> 0 | AZ193: =IF(AW193="YES",1,0) -> 0
E194: =IF(F194="",0,1) -> 0 | AH194: =IF(AI194="",0,1) -> 0 | AL194: =IF(AM194="",0,1) -> 0 | AZ194: =IF(AW194="YES",1,0) -> 0
E195: =IF(F195="",0,1) -> 0 | AH195: =IF(AI195="",0,1) -> 0 | AL195: =IF(AM195="",0,1) -> 0 | AZ195: =IF(AW195="YES",1,0) -> 0
E196: =IF(F196="",0,1) -> 0 | AH196: =IF(AI196="",0,1) -> 0 | AL196: =IF(AM196="",0,1) -> 0 | AZ196: =IF(AW196="YES",1,0) -> 0
E197: =IF(F197="",0,1) -> 0 | Q197: =IF(O197="Health Facility",3,IF(O197="Outreach Session",1,IF(O197="Mobile Clinic",2))) -> FALSE | Z197: =IF(AA197="",0,1) -> 0 | AD197: =IF(AE197="",0,1) -> 0 | AH197: =IF(AI197="",0,1) -> 0 | AL197: =IF(AM197="",0,1) -> 0 | AZ197: =IF(AW197="YES",1,0) -> 0
E198: =IF(F198="",0,1) -> 0 | Q198: =IF(O198="Health Facility",3,IF(O198="Outreach Session",1,IF(O198="Mobile Clinic",2))) -> FALSE | Z198: =IF(AA198="",0,1) -> 0 | AD198: =IF(AE198="",0,1) -> 0 | AH198: =IF(AI198="",0,1) -> 0 | AL198: =IF(AM198="",0,1) -> 0 | AZ198: =IF(AW198="YES",1,0) -> 0
E199: =IF(F199="",0,1) -> 0 | Q199: =IF(O199="Health Facility",3,IF(O199="Outreach Session",1,IF(O199="Mobile Clinic",2))) -> FALSE | Z199: =IF(AA199="",0,1) -> 0 | AD199: =IF(AE199="",0,1) -> 0 | AH199: =IF(AI199="",0,1) -> 0 | AL199: =IF(AM199="",0,1) -> 0 | AZ199: =IF(AW199="YES",1,0) -> 0
E200: =IF(F200="",0,1) -> 0 | Q200: =IF(O200="Health Facility",3,IF(O200="Outreach Session",1,IF(O200="Mobile Clinic",2))) -> FALSE | Z200: =IF(AA200="",0,1) -> 0 | AD200: =IF(AE200="",0,1) -> 0 | AH200: =IF(AI200="",0,1) -> 0 | AL200: =IF(AM200="",0,1) -> 0 | AZ200: =IF(AW200="YES",1,0) -> 0
E201: =IF(F201="",0,1) -> 0 | Q201: =IF(O201="Health Facility",3,IF(O201="Outreach Session",1,IF(O201="Mobile Clinic",2))) -> FALSE | Z201: =IF(AA201="",0,1) -> 0 | AD201: =IF(AE201="",0,1) -> 0 | AH201: =IF(AI201="",0,1) -> 0 | AL201: =IF(AM201="",0,1) -> 0 | AZ201: =IF(AW201="YES",1,0) -> 0
E202: =IF(F202="",0,1) -> 0 | Q202: =IF(O202="Health Facility",3,IF(O202="Outreach Session",1,IF(O202="Mobile Clinic",2))) -> FALSE | Z202: =IF(AA202="",0,1) -> 0 | AD202: =IF(AE202="",0,1) -> 0 | AH202: =IF(AI202="",0,1) -> 0 | AL202: =IF(AM202="",0,1) -> 0 | AZ202: =IF(AW202="YES",1,0) -> 0
E203: =IF(F203="",0,1) -> 0 | Q203: =IF(O203="Health Facility",3,IF(O203="Outreach Session",1,IF(O203="Mobile Clinic",2))) -> FALSE | Z203: =IF(AA203="",0,1) -> 0 | AD203: =IF(AE203="",0,1) -> 0 | AH203: =IF(AI203="",0,1) -> 0 | AL203: =IF(AM203="",0,1) -> 0 | AZ203: =IF(AW203="YES",1,0) -> 0
E204: =IF(F204="",0,1) -> 0 | Q204: =IF(O204="Health Facility",3,IF(O204="Outreach Session",1,IF(O204="Mobile Clinic",2))) -> FALSE | Z204: =IF(AA204="",0,1) -> 0 | AD204: =IF(AE204="",0,1) -> 0 | AH204: =IF(AI204="",0,1) -> 0 | AL204: =IF(AM204="",0,1) -> 0 | AZ204: =IF(AW204="YES",1,0) -> 0
E205: =IF(F205="",0,1) -> 0 | Q205: =IF(O205="Health Facility",3,IF(O205="Outreach Session",1,IF(O205="Mobile Clinic",2))) -> FALSE | Z205: =IF(AA205="",0,1) -> 0 | AD205: =IF(AE205="",0,1) -> 0 | AH205: =IF(AI205="",0,1) -> 0 | AL205: =IF(AM205="",0,1) -> 0 | AZ205: =IF(AW205="YES",1,0) -> 0
E206: =IF(F206="",0,1) -> 0 | Q206: =IF(O206="Health Facility",3,IF(O206="Outreach Session",1,IF(O206="Mobile Clinic",2))) -> FALSE | Z206: =IF(AA206="",0,1) -> 0 | AD206: =IF(AE206="",0,1) -> 0 | AH206: =IF(AI206="",0,1) -> 0 | AL206: =IF(AM206="",0,1) -> 0 | AZ206: =IF(AW206="YES",1,0) -> 0
E207: =IF(F207="",0,1) -> 0 | Q207: =IF(O207="Health Facility",3,IF(O207="Outreach Session",1,IF(O207="Mobile Clinic",2))) -> FALSE | Z207: =IF(AA207="",0,1) -> 0 | AD207: =IF(AE207="",0,1) -> 0 | AH207: =IF(AI207="",0,1) -> 0 | AL207: =IF(AM207="",0,1) -> 0 | AZ207: =IF(AW207="YES",1,0) -> 0
E208: =IF(F208="",0,1) -> 0 | Q208: =IF(O208="Health Facility",3,IF(O208="Outreach Session",1,IF(O208="Mobile Clinic",2))) -> FALSE | Z208: =IF(AA208="",0,1) -> 0 | AD208: =IF(AE208="",0,1) -> 0 | AH208: =IF(AI208="",0,1) -> 0 | AL208: =IF(AM208="",0,1) -> 0 | AZ208: =IF(AW208="YES",1,0) -> 0
...

Sheet CoChMn
B3: COLD CHAIN MAINTENANCE PLAN
B4: (Information in this worksheet is to be filled from planning template for health facilities)
B6: Region: | D6: =IF(Var!D7=0,"",Var!D7) | G6: Council: | I6: =IF(Var!I7=0,"",Var!I7) | K6: Planning Year: | N6: =IF(Var!N7=0,"",Var!N7)
B8: Number of new LP Gas Cylinders need to be purchased at council level during the planning year:
B10: Name of Health Facility | F10: Number of LP Gas Cylinders required every month | I10: Whether electricity used for cold chain maintenance (YES/NO) | L10: Elec. Use | M10: Approximate cost of electricity for cold chain per month (in TZS)
E11: #
E12: HF
B13: =E13 -> 0 | E13: =SUBTOTAL(9,E14:E63) -> 0 | F13: =SUBTOTAL(9,F14:H63) -> 0 | I13: =L13 -> 0 | L13: =SUBTOTAL(9,L14:L63) -> 0 | M13: =SUBTOTAL(9,M14:O63) -> 0 | S13: list of facilities for facility plan
E14: =IF(B14="",0,1) -> 0 | L14: =IF(I14="YES",1,0) -> 0 | S14: =IF(B14=0,"",B14)
E15: =IF(B15="",0,1) -> 0 | L15: =IF(I15="YES",1,0) -> 0 | S15: =IF(B15=0,"",B15)
E16: =IF(B16="",0,1) -> 0 | L16: =IF(I16="YES",1,0) -> 0 | S16: =IF(B16=0,"",B16)
E17: =IF(B17="",0,1) -> 0 | L17: =IF(I17="YES",1,0) -> 0 | S17: =IF(B17=0,"",B17)
E18: =IF(B18="",0,1) -> 0 | L18: =IF(I18="YES",1,0) -> 0 | S18: =IF(B18=0,"",B18)
E19: =IF(B19="",0,1) -> 0 | L19: =IF(I19="YES",1,0) -> 0 | S19: =IF(B19=0,"",B19)
E20: =IF(B20="",0,1) -> 0 | L20: =IF(I20="YES",1,0) -> 0 | S20: =IF(B20=0,"",B20)
E21: =IF(B21="",0,1) -> 0 | L21: =IF(I21="YES",1,0) -> 0 | S21: =IF(B21=0,"",B21)
E22: =IF(B22="",0,1) -> 0 | L22: =IF(I22="YES",1,0) -> 0 | S22: =IF(B22=0,"",B22)
E23: =IF(B23="",0,1) -> 0 | L23: =IF(I23="YES",1,0) -> 0 | S23: =IF(B23=0,"",B23)
E24: =IF(B24="",0,1) -> 0 | L24: =IF(I24="YES",1,0) -> 0 | S24: =IF(B24=0,"",B24)
E25: =IF(B25="",0,1) -> 0 | L25: =IF(I25="YES",1,0) -> 0 | S25: =IF(B25=0,"",B25)
... E63: =IF(B63="",0,1) -> 0 | L63: =IF(I63="YES",1,0) -> 0 | S63: =IF(B63=0,"",B63)
P64: List generation
P65: Cylinders | Q65: Use elec.
P66: 1 | Q66: YES
P67: 2 | Q67: NO
P68: 3
P69: 4
P70: 5

Sheet VacDelHQ
B3: VACCINE DELIVERY PLAN FOR DISTRICT HEADQUARTER
B4: (This plan will be based on route map showing different routes for vaccine delivery from district HQ)
B6: Name of Region: | E6: =IF('C for c'!C2=0,"",'C for c'!C2) | H6: Name of Council: | K6: =IF('C for c'!C3=0,"",'C for c'!C3) | N6: Planning Year: | Q6: =IF('C for c'!C4=0,"",'C for c'!C4)
B8: Route Number | D8: Vehicle Number | E8: Number of facilities covered | F8: Names of health facilities (mention names in order of transporting) | O8: Total distance covered in Km. (including return travel) | Q8: Extra duty allowance entitlement (Yes / No) | S8: Whether overnight stay required (Yes / No) | T8: extra dty officer | U8: extra duty driver | V8: overnight
Q9: Officer | R9: Driver
E10: =SUBTOTAL(9,E11:E26) -> 0 | O10: =SUBTOTAL(9,O11:P26) -> 0 | Q10: =T10 -> 0 | R10: =U10 -> 0 | S10: =V10 -> 0 | T10: =SUM(T11:T26) -> 0 | U10: =SUM(U11:U26) -> 0 | V10: =SUM(V11:V26) -> 0
T11: =IF(Q11="YES",1,0) -> 0 | U11: =IF(R11="YES",1,0) -> 0 | V11: =IF(S11="YES",1,0) -> 0
T12: =IF(Q12="YES",1,0) -> 0 | U12: =IF(R12="YES",1,0) -> 0 | V12: =IF(S12="YES",1,0) -> 0
T13: =IF(Q13="YES",1,0) -> 0 | U13: =IF(R13="YES",1,0) -> 0 | V13: =IF(S13="YES",1,0) -> 0
T14: =IF(Q14="YES",1,0) -> 0 | U14: =IF(R14="YES",1,0) -> 0 | V14: =IF(S14="YES",1,0) -> 0
T15: =IF(Q15="YES",1,0) -> 0 | U15: =IF(R15="YES",1,0) -> 0 | V15: =IF(S15="YES",1,0) -> 0
T16: =IF(Q16="YES",1,0) -> 0 | U16: =IF(R16="YES",1,0) -> 0 | V16: =IF(S16="YES",1,0) -> 0
T17: =IF(Q17="YES",1,0) -> 0 | U17: =IF(R17="YES",1,0) -> 0 | V17: =IF(S17="YES",1,0) -> 0
T18: =IF(Q18="YES",1,0) -> 0 | U18: =IF(R18="YES",1,0) -> 0 | V18: =IF(S18="YES",1,0) -> 0
T19: =IF(Q19="YES",1,0) -> 0 | U19: =IF(R19="YES",1,0) -> 0 | V19: =IF(S19="YES",1,0) -> 0
T20: =IF(Q20="YES",1,0) -> 0 | U20: =IF(R20="YES",1,0) -> 0 | V20: =IF(S20="YES",1,0) -> 0
T21: =IF(Q21="YES",1,0) -> 0 | U21: =IF(R21="YES",1,0) -> 0 | V21: =IF(S21="YES",1,0) -> 0
T22: =IF(Q22="YES",1,0) -> 0 | U22: =IF(R22="YES",1,0) -> 0 | V22: =IF(S22="YES",1,0) -> 0
... T26: =IF(Q26="YES",1,0) -> 0 | U26: =IF(R26="YES",1,0) -> 0 | V26: =IF(S26="YES",1,0) -> 0
T28: list generation
T29: total facilities | U29: overnight
T30: 1 | U30: YES
T31: 2 | U31: NO
T32: 3
T33: 4
T34: 5
T35: 6
T36: 7
T37: 8
T38: 9
T39: 10

Sheet CHMTCmTmforFac
B3: Filter name of the facility to get service delivery plan for that facility. For getting plan summary for the selected health facility, also filter name of the facility in cold chain maintenance plan
B4: HEALTH FACILITY PLAN | I4: Region: | L4: =IF(Var!D7=0,"",Var!D7) | O4: Council: | R4: =IF(Var!I7=0,"",Var!I7) | V4: Year: | W4: =IF(Var!N7=0,"",Var!N7)
B9: Name of Health Facility | F9: 1 | I9: 2.1 | K9: 2.2 | M9: 2.3 | O9: 3 | R9: 4 | T9: 5 | V9: 6 | AA9: 7.1 | AE9: 7.2 | AI9: 8.1 | AM9: 8.2 | AP9: 9 | AR9: 10 | AT9: 11 | AW9: 12
F10: Name of village | I10: Annual Beneficiaries | O10: Immunization services to be provided by… | R10: Weekday for organizing outreach/mobile clinic | T10: Week number for organizing outreach/mobile clinic | V10: Location/address of outreach session/mobile clinic in village | AA10: Team members from health facility | AI10: Team members from community | AP10: Distance of village from facility (Km) | AR10: Fare for transporting vaccines to outreach | AT10: Name of village leader | AW10: Overnight stay (YES/NO) | BC10: counts
I11: Pregnant Women | K11: Surviving infants | M11: 12-24 month children | Q11: CODE | Z11: F1 | AA11: Facility staff 1 | AD11: F2 | AE11: Facility staff 2 | AH11: C1 | AI11: Community Member 1 | AL11: C2 | AM11: Community Member 2 | BC11: =SUBTOTAL(9,BC13:BC265) -> 0 | BD11: =SUBTOTAL(9,BD13:BD265) -> 0 | BE11: =SUBTOTAL(9,BE13:BE265) -> 0
E12: =SUBTOTAL(9,E13:E265) -> 0 | F12: =E12 -> 0 | I12: =SUBTOTAL(9,I13:J265) -> 0 | K12: =SUBTOTAL(9,K13:L265) -> 0 | M12: =SUBTOTAL(9,M13:N265) -> 0 | Z12: =SUBTOTAL(9,Z13:Z265) -> 0 | AA12: =Z12 -> 0 | AD12: =SUBTOTAL(9,AD13:AD265) -> 0 | AE12: =AD12 -> 0 | AH12: =SUBTOTAL(9,AH13:AH265) -> 0 | AI12: =AH12 -> 0 | AL12: =SUBTOTAL(9,AL13:AL265) -> 0 | AM12: =AL12 -> 0 | AR12: =SUBTOTAL(9,AR13:AS265) -> 0 | AW12: =AZ12 -> 0 | AZ12: =SUBTOTAL(9,AZ13:AZ265) -> 0 | BC12: Outreach | BD12: Mobile | BE12: Facility
B13: =IF(CHMTCmTm!B12=0,"",CHMTCmTm!B12) | E13: =CHMTCmTm!E12 -> 0 | F13: =IF(CHMTCmTm!F12=0,"",CHMTCmTm!F12) | I13: =IF(CHMTCmTm!I12=0,"",CHMTCmTm!I12) | K13: =IF(CHMTCmTm!K12=0,"",CHMTCmTm!K12) | M13: =IF(CHMTCmTm!M12=0,"",CHMTCmTm!M12) | O13: =IF(CHMTCmTm!O12=0,"",CHMTCmTm!O12) | Q13: =CHMTCmTm!Q12 -> FALSE | R13: =IF(CHMTCmTm!R12=0,"",CHMTCmTm!R12) | T13: =IF(CHMTCmTm!T12=0,"",CHMTCmTm!T12) | V13: =IF(CHMTCmTm!V12=0,"",CHMTCmTm!V12) | Z13: =CHMTCmTm!Z12 -> 0 | AA13: =IF(CHMTCmTm!AA12=0,"",CHMTCmTm!AA12) | AD13: =CHMTCmTm!AD12 -> 0 | AE13: =IF(CHMTCmTm!AE12=0,"",CHMTCmTm!AE12) | AH13: =CHMTCmTm!AH12 -> 0 | AI13: =IF(CHMTCmTm!AI12=0,"",CHMTCmTm!AI12) | AL13: =CHMTCmTm!AL12 -> 0 | AM13: =IF(CHMTCmTm!AM12=0,"",CHMTCmTm!AM12) | AP13: =IF(CHMTCmTm!AP12=0,"",CHMTCmTm!AP12) | AR13: =IF(CHMTCmTm!AR12=0,"",CHMTCmTm!AR12) | AT13: =IF(CHMTCmTm!AT12=0,"",CHMTCmTm!AT12) | AW13: =IF(CHMTCmTm!AW12=0,"",CHMTCmTm!AW12) | AZ13: =CHMTCmTm!AZ12 -> 0 | BC13: =COUNTIF(CHMTCmTm!O12, "Outreach Session") -> 0 | BD13: =COUNTIF(CHMTCmTm!O12, "Mobile Clinic") -> 0 | BE13: =COUNTIF(CHMTCmTm!O12, "Health Facility") -> 0
B14: =IF(CHMTCmTm!B13=0,"",CHMTCmTm!B13) | E14: =CHMTCmTm!E13 -> 0 | F14: =IF(CHMTCmTm!F13=0,"",CHMTCmTm!F13) | I14: =IF(CHMTCmTm!I13=0,"",CHMTCmTm!I13) | K14: =IF(CHMTCmTm!K13=0,"",CHMTCmTm!K13) | M14: =IF(CHMTCmTm!M13=0,"",CHMTCmTm!M13) | O14: =IF(CHMTCmTm!O13=0,"",CHMTCmTm!O13) | Q14: =CHMTCmTm!Q13 -> FALSE | R14: =IF(CHMTCmTm!R13=0,"",CHMTCmTm!R13) | T14: =IF(CHMTCmTm!T13=0,"",CHMTCmTm!T13) | V14: =IF(CHMTCmTm!V13=0,"",CHMTCmTm!V13) | Z14: =CHMTCmTm!Z13 -> 0 | AA14: =IF(CHMTCmTm!AA13=0,"",CHMTCmTm!AA13) | AD14: =CHMTCmTm!AD13 -> 0 | AE14: =IF(CHMTCmTm!AE13=0,"",CHMTCmTm!AE13) | AH14: =CHMTCmTm!AH13 -> 0 | AI14: =IF(CHMTCmTm!AI13=0,"",CHMTCmTm!AI13) | AL14: =CHMTCmTm!AL13 -> 0 | AM14: =IF(CHMTCmTm!AM13=0,"",CHMTCmTm!AM13) | AP14: =IF(CHMTCmTm!AP13=0,"",CHMTCmTm!AP13) | AR14: =IF(CHMTCmTm!AR13=0,"",CHMTCmTm!AR13) | AT14: =IF(CHMTCmTm!AT13=0,"",CHMTCmTm!AT13) | AW14: =IF(CHMTCmTm!AW13=0,"",CHMTCmTm!AW13) | AZ14: =CHMTCmTm!AZ13 -> 0 | BC14: =COUNTIF(CHMTCmTm!O13, "Outreach Session") -> 0 | BD14: =COUNTIF(CHMTCmTm!O13, "Mobile Clinic") -> 0 | BE14: =COUNTIF(CHMTCmTm!O13, "Health Facility") -> 0
B15: =IF(CHMTCmTm!B14=0,"",CHMTCmTm!B14) | E15: =CHMTCmTm!E14 -> 0 | F15: =IF(CHMTCmTm!F14=0,"",CHMTCmTm!F14) | I15: =IF(CHMTCmTm!I14=0,"",CHMTCmTm!I14) | K15: =IF(CHMTCmTm!K14=0,"",CHMTCmTm!K14) | M15: =IF(CHMTCmTm!M14=0,"",CHMTCmTm!M14) | O15: =IF(CHMTCmTm!O14=0,"",CHMTCmTm!O14) | Q15: =CHMTCmTm!Q14 -> FALSE | R15: =IF(CHMTCmTm!R14=0,"",CHMTCmTm!R14) | T15: =IF(CHMTCmTm!T14=0,"",CHMTCmTm!T14) | V15: =IF(CHMTCmTm!V14=0,"",CHMTCmTm!V14) | Z15: =CHMTCmTm!Z14 -> 0 | AA15: =IF(CHMTCmTm!AA14=0,"",CHMTCmTm!AA14) | AD15: =CHMTCmTm!AD14 -> 0 | AE15: =IF(CHMTCmTm!AE14=0,"",CHMTCmTm!AE14) | AH15: =CHMTCmTm!AH14 -> 0 | AI15: =IF(CHMTCmTm!AI14=0,"",CHMTCmTm!AI14) | AL15: =CHMTCmTm!AL14 -> 0 | AM15: =IF(CHMTCmTm!AM14=0,"",CHMTCmTm!AM14) | AP15: =IF(CHMTCmTm!AP14=0,"",CHMTCmTm!AP14) | AR15: =IF(CHMTCmTm!AR14=0,"",CHMTCmTm!AR14) | AT15: =IF(CHMTCmTm!AT14=0,"",CHMTCmTm!AT14) | AW15: =IF(CHMTCmTm!AW14=0,"",CHMTCmTm!AW14) | AZ15: =CHMTCmTm!AZ14 -> 0 | BC15: =COUNTIF(CHMTCmTm!O14, "Outreach Session") -> 0 | BD15: =COUNTIF(CHMTCmTm!O14, "Mobile Clinic") -> 0 | BE15: =COUNTIF(CHMTCmTm!O14, "Health Facility") -> 0
B16: =IF(CHMTCmTm!B15=0,"",CHMTCmTm!B15) | E16: =CHMTCmTm!E15 -> 0 | F16: =IF(CHMTCmTm!F15=0,"",CHMTCmTm!F15) | I16: =IF(CHMTCmTm!I15=0,"",CHMTCmTm!I15) | K16: =IF(CHMTCmTm!K15=0,"",CHMTCmTm!K15) | M16: =IF(CHMTCmTm!M15=0,"",CHMTCmTm!M15) | O16: =IF(CHMTCmTm!O15=0,"",CHMTCmTm!O15) | Q16: =CHMTCmTm!Q15 -> FALSE | R16: =IF(CHMTCmTm!R15=0,"",CHMTCmTm!R15) | T16: =IF(CHMTCmTm!T15=0,"",CHMTCmTm!T15) | V16: =IF(CHMTCmTm!V15=0,"",CHMTCmTm!V15) | Z16: =CHMTCmTm!Z15 -> 0 | AA16: =IF(CHMTCmTm!AA15=0,"",CHMTCmTm!AA15) | AD16: =CHMTCmTm!AD15 -> 0 | AE16: =IF(CHMTCmTm!AE15=0,"",CHMTCmTm!AE15) | AH16: =CHMTCmTm!AH15 -> 0 | AI16: =IF(CHMTCmTm!AI15=0,"",CHMTCmTm!AI15) | AL16: =CHMTCmTm!AL15 -> 0 | AM16: =IF(CHMTCmTm!AM15=0,"",CHMTCmTm!AM15) | AP16: =IF(CHMTCmTm!AP15=0,"",CHMTCmTm!AP15) | AR16: =IF(CHMTCmTm!AR15=0,"",CHMTCmTm!AR15) | AT16: =IF(CHMTCmTm!AT15=0,"",CHMTCmTm!AT15) | AW16: =IF(CHMTCmTm!AW15=0,"",CHMTCmTm!AW15) | AZ16: =CHMTCmTm!AZ15 -> 0 | BC16: =COUNTIF(CHMTCmTm!O15, "Outreach Session") -> 0 | BD16: =COUNTIF(CHMTCmTm!O15, "Mobile Clinic") -> 0 | BE16: =COUNTIF(CHMTCmTm!O15, "Health Facility") -> 0
B17: =IF(CHMTCmTm!B16=0,"",CHMTCmTm!B16) | E17: =CHMTCmTm!E16 -> 0 | F17: =IF(CHMTCmTm!F16=0,"",CHMTCmTm!F16) | I17: =IF(CHMTCmTm!I16=0,"",CHMTCmTm!I16) | K17: =IF(CHMTCmTm!K16=0,"",CHMTCmTm!K16) | M17: =IF(CHMTCmTm!M16=0,"",CHMTCmTm!M16) | O17: =IF(CHMTCmTm!O16=0,"",CHMTCmTm!O16) | Q17: =CHMTCmTm!Q16 -> FALSE | R17: =IF(CHMTCmTm!R16=0,"",CHMTCmTm!R16) | T17: =IF(CHMTCmTm!T16=0,"",CHMTCmTm!T16) | V17: =IF(CHMTCmTm!V16=0,"",CHMTCmTm!V16) | Z17: =CHMTCmTm!Z16 -> 0 | AA17: =IF(CHMTCmTm!AA16=0,"",CHMTCmTm!AA16) | AD17: =CHMTCmTm!AD16 -> 0 | AE17: =IF(CHMTCmTm!AE16=0,"",CHMTCmTm!AE16) | AH17: =CHMTCmTm!AH16 -> 0 | AI17: =IF(CHMTCmTm!AI16=0,"",CHMTCmTm!AI16) | AL17: =CHMTCmTm!AL16 -> 0 | AM17: =IF(CHMTCmTm!AM16=0,"",CHMTCmTm!AM16) | AP17: =IF(CHMTCmTm!AP16=0,"",CHMTCmTm!AP16) | AR17: =IF(CHMTCmTm!AR16=0,"",CHMTCmTm!AR16) | AT17: =IF(CHMTCmTm!AT16=0,"",CHMTCmTm!AT16) | AW17: =IF(CHMTCmTm!AW16=0,"",CHMTCmTm!AW16) | AZ17: =CHMTCmTm!AZ16 -> 0 | BC17: =COUNTIF(CHMTCmTm!O16, "Outreach Session") -> 0 | BD17: =COUNTIF(CHMTCmTm!O16, "Mobile Clinic") -> 0 | BE17: =COUNTIF(CHMTCmTm!O16, "Health Facility") -> 0
B18: =IF(CHMTCmTm!B17=0,"",CHMTCmTm!B17) | E18: =CHMTCmTm!E17 -> 0 | F18: =IF(CHMTCmTm!F17=0,"",CHMTCmTm!F17) | I18: =IF(CHMTCmTm!I17=0,"",CHMTCmTm!I17) | K18: =IF(CHMTCmTm!K17=0,"",CHMTCmTm!K17) | M18: =IF(CHMTCmTm!M17=0,"",CHMTCmTm!M17) | O18: =IF(CHMTCmTm!O17=0,"",CHMTCmTm!O17) | Q18: =CHMTCmTm!Q17 -> FALSE | R18: =IF(CHMTCmTm!R17=0,"",CHMTCmTm!R17) | T18: =IF(CHMTCmTm!T17=0,"",CHMTCmTm!T17) | V18: =IF(CHMTCmTm!V17=0,"",CHMTCmTm!V17) | Z18: =CHMTCmTm!Z17 -> 0 | AA18: =IF(CHMTCmTm!AA17=0,"",CHMTCmTm!AA17) | AD18: =CHMTCmTm!AD17 -> 0 | AE18: =IF(CHMTCmTm!AE17=0,"",CHMTCmTm!AE17) | AH18: =CHMTCmTm!AH17 -> 0 | AI18: =IF(CHMTCmTm!AI17=0,"",CHMTCmTm!AI17) | AL18: =CHMTCmTm!AL17 -> 0 | AM18: =IF(CHMTCmTm!AM17=0,"",CHMTCmTm!AM17) | AP18: =IF(CHMTCmTm!AP17=0,"",CHMTCmTm!AP17) | AR18: =IF(CHMTCmTm!AR17=0,"",CHMTCmTm!AR17) | AT18: =IF(CHMTCmTm!AT17=0,"",CHMTCmTm!AT17) | AW18: =IF(CHMTCmTm!AW17=0,"",CHMTCmTm!AW17) | AZ18: =CHMTCmTm!AZ17 -> 0 | BC18: =COUNTIF(CHMTCmTm!O17, "Outreach Session") -> 0 | BD18: =COUNTIF(CHMTCmTm!O17, "Mobile Clinic") -> 0 | BE18: =COUNTIF(CHMTCmTm!O17, "Health Facility") -> 0
B19: =IF(CHMTCmTm!B18=0,"",CHMTCmTm!B18) | E19: =CHMTCmTm!E18 -> 0 | F19: =IF(CHMTCmTm!F18=0,"",CHMTCmTm!F18) | I19: =IF(CHMTCmTm!I18=0,"",CHMTCmTm!I18) | K19: =IF(CHMTCmTm!K18=0,"",CHMTCmTm!K18) | M19: =IF(CHMTCmTm!M18=0,"",CHMTCmTm!M18) | O19: =IF(CHMTCmTm!O18=0,"",CHMTCmTm!O18) | Q19: =CHMTCmTm!Q18 -> FALSE | R19: =IF(CHMTCmTm!R18=0,"",CHMTCmTm!R18) | T19: =IF(CHMTCmTm!T18=0,"",CHMTCmTm!T18) | V19: =IF(CHMTCmTm!V18=0,"",CHMTCmTm!V18) | Z19: =CHMTCmTm!Z18 -> 0 | AA19: =IF(CHMTCmTm!AA18=0,"",CHMTCmTm!AA18) | AD19: =CHMTCmTm!AD18 -> 0 | AE19: =IF(CHMTCmTm!AE18=0,"",CHMTCmTm!AE18) | AH19: =CHMTCmTm!AH18 -> 0 | AI19: =IF(CHMTCmTm!AI18=0,"",CHMTCmTm!AI18) | AL19: =CHMTCmTm!AL18 -> 0 | AM19: =IF(CHMTCmTm!AM18=0,"",CHMTCmTm!AM18) | AP19: =IF(CHMTCmTm!AP18=0,"",CHMTCmTm!AP18) | AR19: =IF(CHMTCmTm!AR18=0,"",CHMTCmTm!AR18) | AT19: =IF(CHMTCmTm!AT18=0,"",CHMTCmTm!AT18) | AW19: =IF(CHMTCmTm!AW18=0,"",CHMTCmTm!AW18) | AZ19: =CHMTCmTm!AZ18 -> 0 | BC19: =COUNTIF(CHMTCmTm!O18, "Outreach Session") -> 0 | BD19: =COUNTIF(CHMTCmTm!O18, "Mobile Clinic") -> 0 | BE19: =COUNTIF(CHMTCmTm!O18, "Health Facility") -> 0
B20: =IF(CHMTCmTm!B19=0,"",CHMTCmTm!B19) | E20: =CHMTCmTm!E19 -> 0 | F20: =IF(CHMTCmTm!F19=0,"",CHMTCmTm!F19) | I20: =IF(CHMTCmTm!I19=0,"",CHMTCmTm!I19) | K20: =IF(CHMTCmTm!K19=0,"",CHMTCmTm!K19) | M20: =IF(CHMTCmTm!M19=0,"",CHMTCmTm!M19) | O20: =IF(CHMTCmTm!O19=0,"",CHMTCmTm!O19) | Q20: =CHMTCmTm!Q19 -> FALSE | R20: =IF(CHMTCmTm!R19=0,"",CHMTCmTm!R19) | T20: =IF(CHMTCmTm!T19=0,"",CHMTCmTm!T19) | V20: =IF(CHMTCmTm!V19=0,"",CHMTCmTm!V19) | Z20: =CHMTCmTm!Z19 -> 0 | AA20: =IF(CHMTCmTm!AA19=0,"",CHMTCmTm!AA19) | AD20: =CHMTCmTm!AD19 -> 0 | AE20: =IF(CHMTCmTm!AE19=0,"",CHMTCmTm!AE19) | AH20: =CHMTCmTm!AH19 -> 0 | AI20: =IF(CHMTCmTm!AI19=0,"",CHMTCmTm!AI19) | AL20: =CHMTCmTm!AL19 -> 0 | AM20: =IF(CHMTCmTm!AM19=0,"",CHMTCmTm!AM19) | AP20: =IF(CHMTCmTm!AP19=0,"",CHMTCmTm!AP19) | AR20: =IF(CHMTCmTm!AR19=0,"",CHMTCmTm!AR19) | AT20: =IF(CHMTCmTm!AT19=0,"",CHMTCmTm!AT19) | AW20: =IF(CHMTCmTm!AW19=0,"",CHMTCmTm!AW19) | AZ20: =CHMTCmTm!AZ19 -> 0 | BC20: =COUNTIF(CHMTCmTm!O19, "Outreach Session") -> 0 | BD20: =COUNTIF(CHMTCmTm!O19, "Mobile Clinic") -> 0 | BE20: =COUNTIF(CHMTCmTm!O19, "Health Facility") -> 0
B21: =IF(CHMTCmTm!B20=0,"",CHMTCmTm!B20) | E21: =CHMTCmTm!E20 -> 0 | F21: =IF(CHMTCmTm!F20=0,"",CHMTCmTm!F20) | I21: =IF(CHMTCmTm!I20=0,"",CHMTCmTm!I20) | K21: =IF(CHMTCmTm!K20=0,"",CHMTCmTm!K20) | M21: =IF(CHMTCmTm!M20=0,"",CHMTCmTm!M20) | O21: =IF(CHMTCmTm!O20=0,"",CHMTCmTm!O20) | Q21: =CHMTCmTm!Q20 -> FALSE | R21: =IF(CHMTCmTm!R20=0,"",CHMTCmTm!R20) | T21: =IF(CHMTCmTm!T20=0,"",CHMTCmTm!T20) | V21: =IF(CHMTCmTm!V20=0,"",CHMTCmTm!V20) | Z21: =CHMTCmTm!Z20 -> 0 | AA21: =IF(CHMTCmTm!AA20=0,"",CHMTCmTm!AA20) | AD21: =CHMTCmTm!AD20 -> 0 | AE21: =IF(CHMTCmTm!AE20=0,"",CHMTCmTm!AE20) | AH21: =CHMTCmTm!AH20 -> 0 | AI21: =IF(CHMTCmTm!AI20=0,"",CHMTCmTm!AI20) | AL21: =CHMTCmTm!AL20 -> 0 | AM21: =IF(CHMTCmTm!AM20=0,"",CHMTCmTm!AM20) | AP21: =IF(CHMTCmTm!AP20=0,"",CHMTCmTm!AP20) | AR21: =IF(CHMTCmTm!AR20=0,"",CHMTCmTm!AR20) | AT21: =IF(CHMTCmTm!AT20=0,"",CHMTCmTm!AT20) | AW21: =IF(CHMTCmTm!AW20=0,"",CHMTCmTm!AW20) | AZ21: =CHMTCmTm!AZ20 -> 0 | BC21: =COUNTIF(CHMTCmTm!O20, "Outreach Session") -> 0 | BD21: =COUNTIF(CHMTCmTm!O20, "Mobile Clinic") -> 0 | BE21: =COUNTIF(CHMTCmTm!O20, "Health Facility") -> 0
B22: =IF(CHMTCmTm!B21=0,"",CHMTCmTm!B21) | E22: =CHMTCmTm!E21 -> 0 | F22: =IF(CHMTCmTm!F21=0,"",CHMTCmTm!F21) | I22: =IF(CHMTCmTm!I21=0,"",CHMTCmTm!I21) | K22: =IF(CHMTCmTm!K21=0,"",CHMTCmTm!K21) | M22: =IF(CHMTCmTm!M21=0,"",CHMTCmTm!M21) | O22: =IF(CHMTCmTm!O21=0,"",CHMTCmTm!O21) | Q22: =CHMTCmTm!Q21 -> FALSE | R22: =IF(CHMTCmTm!R21=0,"",CHMTCmTm!R21) | T22: =IF(CHMTCmTm!T21=0,"",CHMTCmTm!T21) | V22: =IF(CHMTCmTm!V21=0,"",CHMTCmTm!V21) | Z22: =CHMTCmTm!Z21 -> 0 | AA22: =IF(CHMTCmTm!AA21=0,"",CHMTCmTm!AA21) | AD22: =CHMTCmTm!AD21 -> 0 | AE22: =IF(CHMTCmTm!AE21=0,"",CHMTCmTm!AE21) | AH22: =CHMTCmTm!AH21 -> 0 | AI22: =IF(CHMTCmTm!AI21=0,"",CHMTCmTm!AI21) | AL22: =CHMTCmTm!AL21 -> 0 | AM22: =IF(CHMTCmTm!AM21=0,"",CHMTCmTm!AM21) | AP22: =IF(CHMTCmTm!AP21=0,"",CHMTCmTm!AP21) | AR22: =IF(CHMTCmTm!AR21=0,"",CHMTCmTm!AR21) | AT22: =IF(CHMTCmTm!AT21=0,"",CHMTCmTm!AT21) | AW22: =IF(CHMTCmTm!AW21=0,"",CHMTCmTm!AW21) | AZ22: =CHMTCmTm!AZ21 -> 0 | BC22: =COUNTIF(CHMTCmTm!O21, "Outreach Session") -> 0 | BD22: =COUNTIF(CHMTCmTm!O21, "Mobile Clinic") -> 0 | BE22: =COUNTIF(CHMTCmTm!O21, "Health Facility") -> 0
B23: =IF(CHMTCmTm!B22=0,"",CHMTCmTm!B22) | E23: =CHMTCmTm!E22 -> 0 | F23: =IF(CHMTCmTm!F22=0,"",CHMTCmTm!F22) | I23: =IF(CHMTCmTm!I22=0,"",CHMTCmTm!I22) | K23: =IF(CHMTCmTm!K22=0,"",CHMTCmTm!K22) | M23: =IF(CHMTCmTm!M22=0,"",CHMTCmTm!M22) | O23: =IF(CHMTCmTm!O22=0,"",CHMTCmTm!O22) | Q23: =CHMTCmTm!Q22 -> FALSE | R23: =IF(CHMTCmTm!R22=0,"",CHMTCmTm!R22) | T23: =IF(CHMTCmTm!T22=0,"",CHMTCmTm!T22) | V23: =IF(CHMTCmTm!V22=0,"",CHMTCmTm!V22) | Z23: =CHMTCmTm!Z22 -> 0 | AA23: =IF(CHMTCmTm!AA22=0,"",CHMTCmTm!AA22) | AD23: =CHMTCmTm!AD22 -> 0 | AE23: =IF(CHMTCmTm!AE22=0,"",CHMTCmTm!AE22) | AH23: =CHMTCmTm!AH22 -> 0 | AI23: =IF(CHMTCmTm!AI22=0,"",CHMTCmTm!AI22) | AL23: =CHMTCmTm!AL22 -> 0 | AM23: =IF(CHMTCmTm!AM22=0,"",CHMTCmTm!AM22) | AP23: =IF(CHMTCmTm!AP22=0,"",CHMTCmTm!AP22) | AR23: =IF(CHMTCmTm!AR22=0,"",CHMTCmTm!AR22) | AT23: =IF(CHMTCmTm!AT22=0,"",CHMTCmTm!AT22) | AW23: =IF(CHMTCmTm!AW22=0,"",CHMTCmTm!AW22) | AZ23: =CHMTCmTm!AZ22 -> 0 | BC23: =COUNTIF(CHMTCmTm!O22, "Outreach Session") -> 0 | BD23: =COUNTIF(CHMTCmTm!O22, "Mobile Clinic") -> 0 | BE23: =COUNTIF(CHMTCmTm!O22, "Health Facility") -> 0
B24: =IF(CHMTCmTm!B23=0,"",CHMTCmTm!B23) | E24: =CHMTCmTm!E23 -> 0 | F24: =IF(CHMTCmTm!F23=0,"",CHMTCmTm!F23) | I24: =IF(CHMTCmTm!I23=0,"",CHMTCmTm!I23) | K24: =IF(CHMTCmTm!K23=0,"",CHMTCmTm!K23) | M24: =IF(CHMTCmTm!M23=0,"",CHMTCmTm!M23) | O24: =IF(CHMTCmTm!O23=0,"",CHMTCmTm!O23) | Q24: =CHMTCmTm!Q23 -> FALSE | R24: =IF(CHMTCmTm!R23=0,"",CHMTCmTm!R23) | T24: =IF(CHMTCmTm!T23=0,"",CHMTCmTm!T23) | V24: =IF(CHMTCmTm!V23=0,"",CHMTCmTm!V23) | Z24: =CHMTCmTm!Z23 -> 0 | AA24: =IF(CHMTCmTm!AA23=0,"",CHMTCmTm!AA23) | AD24: =CHMTCmTm!AD23 -> 0 | AE24: =IF(CHMTCmTm!AE23=0,"",CHMTCmTm!AE23) | AH24: =CHMTCmTm!AH23 -> 0 | AI24: =IF(CHMTCmTm!AI23=0,"",CHMTCmTm!AI23) | AL24: =CHMTCmTm!AL23 -> 0 | AM24: =IF(CHMTCmTm!AM23=0,"",CHMTCmTm!AM23) | AP24: =IF(CHMTCmTm!AP23=0,"",CHMTCmTm!AP23) | AR24: =IF(CHMTCmTm!AR23=0,"",CHMTCmTm!AR23) | AT24: =IF(CHMTCmTm!AT23=0,"",CHMTCmTm!AT23) | AW24: =IF(CHMTCmTm!AW23=0,"",CHMTCmTm!AW23) | AZ24: =CHMTCmTm!AZ23 -> 0 | BC24: =COUNTIF(CHMTCmTm!O23, "Outreach Session") -> 0 | BD24: =COUNTIF(CHMTCmTm!O23, "Mobile Clinic") -> 0 | BE24: =COUNTIF(CHMTCmTm!O23, "Health Facility") -> 0
... B27: =IF(CHMTCmTm!B26=0,"",CHMTCmTm!B26) | E27: =CHMTCmTm!E26 -> 0 | F27: =IF(CHMTCmTm!F26=0,"",CHMTCmTm!F26) | I27: =IF(CHMTCmTm!I26=0,"",CHMTCmTm!I26) | K27: =IF(CHMTCmTm!K26=0,"",CHMTCmTm!K26) | M27: =IF(CHMTCmTm!M26=0,"",CHMTCmTm!M26) | O27: =IF(CHMTCmTm!O26=0,"",CHMTCmTm!O26) | Q27: =CHMTCmTm!Q26 -> FALSE | R27: =IF(CHMTCmTm!R26=0,"",CHMTCmTm!R26) | T27: =IF(CHMTCmTm!T26=0,"",CHMTCmTm!T26) | V27: =IF(CHMTCmTm!V26=0,"",CHMTCmTm!V26) | Z27: =CHMTCmTm!Z26 -> 0 | AA27: =IF(CHMTCmTm!AA26=0,"",CHMTCmTm!AA26) | AD27: =CHMTCmTm!AD26 -> 0 | AE27: =IF(CHMTCmTm!AE26=0,"",CHMTCmTm!AE26) | AH27: =CHMTCmTm!AH26 -> 0 | AI27: =IF(CHMTCmTm!AI26=0,"",CHMTCmTm!AI26) | AL27: =CHMTCmTm!AL26 -> 0 | AM27: =IF(CHMTCmTm!AM26=0,"",CHMTCmTm!AM26) | AP27: =IF(CHMTCmTm!AP26=0,"",CHMTCmTm!AP26) | AR27: =IF(CHMTCmTm!AR26=0,"",CHMTCmTm!AR26) | AT27: =IF(CHMTCmTm!AT26=0,"",CHMTCmTm!AT26) | AW27: =IF(CHMTCmTm!AW26=0,"",CHMTCmTm!AW26) | AZ27: =CHMTCmTm!AZ26 -> 0 | BC27: =COUNTIF(CHMTCmTm!O26, "Outreach Session") -> 0 | BD27: =COUNTIF(CHMTCmTm!O26, "Mobile Clinic") -> 0 | BE27: =COUNTIF(CHMTCmTm!O26, "Health Facility") -> 0
B28: =IF(CHMTCmTm!B27=0,"",CHMTCmTm!B27) | E28: =IF(F28="",0,1) -> 0 | F28: =IF(CHMTCmTm!F27=0,"",CHMTCmTm!F27) | I28: =IF(CHMTCmTm!I27=0,"",CHMTCmTm!I27) | K28: =IF(CHMTCmTm!K27=0,"",CHMTCmTm!K27) | M28: =IF(CHMTCmTm!M27=0,"",CHMTCmTm!M27) | O28: =IF(CHMTCmTm!O27=0,"",CHMTCmTm!O27) | Q28: =IF(O28="Health Facility",3,IF(O28="Outreach Session",1,IF(O28="Mobile Clinic",2))) -> FALSE | R28: =IF(CHMTCmTm!R27=0,"",CHMTCmTm!R27) | T28: =IF(CHMTCmTm!T27=0,"",CHMTCmTm!T27) | V28: =IF(CHMTCmTm!V27=0,"",CHMTCmTm!V27) | Z28: =CHMTCmTm!Z27 -> 0 | AA28: =IF(CHMTCmTm!AA27=0,"",CHMTCmTm!AA27) | AD28: =CHMTCmTm!AD27 -> 0 | AE28: =IF(CHMTCmTm!AE27=0,"",CHMTCmTm!AE27) | AH28: =CHMTCmTm!AH27 -> 0 | AI28: =IF(CHMTCmTm!AI27=0,"",CHMTCmTm!AI27) | AL28: =CHMTCmTm!AL27 -> 0 | AM28: =IF(CHMTCmTm!AM27=0,"",CHMTCmTm!AM27) | AP28: =IF(CHMTCmTm!AP27=0,"",CHMTCmTm!AP27) | AR28: =IF(CHMTCmTm!AR27=0,"",CHMTCmTm!AR27) | AT28: =IF(CHMTCmTm!AT27=0,"",CHMTCmTm!AT27) | AW28: =IF(CHMTCmTm!AW27=0,"",CHMTCmTm!AW27) | AZ28: =CHMTCmTm!AZ27 -> 0 | BC28: =COUNTIF(CHMTCmTm!O27, "Outreach Session") -> 0 | BD28: =COUNTIF(CHMTCmTm!O27, "Mobile Clinic") -> 0 | BE28: =COUNTIF(CHMTCmTm!O27, "Health Facility") -> 0
B29: =IF(CHMTCmTm!B28=0,"",CHMTCmTm!B28) | E29: =IF(F29="",0,1) -> 0 | F29: =IF(CHMTCmTm!F28=0,"",CHMTCmTm!F28) | I29: =IF(CHMTCmTm!I28=0,"",CHMTCmTm!I28) | K29: =IF(CHMTCmTm!K28=0,"",CHMTCmTm!K28) | M29: =IF(CHMTCmTm!M28=0,"",CHMTCmTm!M28) | O29: =IF(CHMTCmTm!O28=0,"",CHMTCmTm!O28) | Q29: =IF(O29="Health Facility",3,IF(O29="Outreach Session",1,IF(O29="Mobile Clinic",2))) -> FALSE | R29: =IF(CHMTCmTm!R28=0,"",CHMTCmTm!R28) | T29: =IF(CHMTCmTm!T28=0,"",CHMTCmTm!T28) | V29: =IF(CHMTCmTm!V28=0,"",CHMTCmTm!V28) | Z29: =CHMTCmTm!Z28 -> 0 | AA29: =IF(CHMTCmTm!AA28=0,"",CHMTCmTm!AA28) | AD29: =CHMTCmTm!AD28 -> 0 | AE29: =IF(CHMTCmTm!AE28=0,"",CHMTCmTm!AE28) | AH29: =CHMTCmTm!AH28 -> 0 | AI29: =IF(CHMTCmTm!AI28=0,"",CHMTCmTm!AI28) | AL29: =CHMTCmTm!AL28 -> 0 | AM29: =IF(CHMTCmTm!AM28=0,"",CHMTCmTm!AM28) | AP29: =IF(CHMTCmTm!AP28=0,"",CHMTCmTm!AP28) | AR29: =IF(CHMTCmTm!AR28=0,"",CHMTCmTm!AR28) | AT29: =IF(CHMTCmTm!AT28=0,"",CHMTCmTm!AT28) | AW29: =IF(CHMTCmTm!AW28=0,"",CHMTCmTm!AW28) | AZ29: =CHMTCmTm!AZ28 -> 0 | BC29: =COUNTIF(CHMTCmTm!O28, "Outreach Session") -> 0 | BD29: =COUNTIF(CHMTCmTm!O28, "Mobile Clinic") -> 0 | BE29: =COUNTIF(CHMTCmTm!O28, "Health Facility") -> 0
B30: =IF(CHMTCmTm!B29=0,"",CHMTCmTm!B29) | E30: =IF(F30="",0,1) -> 0 | F30: =IF(CHMTCmTm!F29=0,"",CHMTCmTm!F29) | I30: =IF(CHMTCmTm!I29=0,"",CHMTCmTm!I29) | K30: =IF(CHMTCmTm!K29=0,"",CHMTCmTm!K29) | M30: =IF(CHMTCmTm!M29=0,"",CHMTCmTm!M29) | O30: =IF(CHMTCmTm!O29=0,"",CHMTCmTm!O29) | Q30: =IF(O30="Health Facility",3,IF(O30="Outreach Session",1,IF(O30="Mobile Clinic",2))) -> FALSE | R30: =IF(CHMTCmTm!R29=0,"",CHMTCmTm!R29) | T30: =IF(CHMTCmTm!T29=0,"",CHMTCmTm!T29) | V30: =IF(CHMTCmTm!V29=0,"",CHMTCmTm!V29) | Z30: =CHMTCmTm!Z29 -> 0 | AA30: =IF(CHMTCmTm!AA29=0,"",CHMTCmTm!AA29) | AD30: =CHMTCmTm!AD29 -> 0 | AE30: =IF(CHMTCmTm!AE29=0,"",CHMTCmTm!AE29) | AH30: =CHMTCmTm!AH29 -> 0 | AI30: =IF(CHMTCmTm!AI29=0,"",CHMTCmTm!AI29) | AL30: =CHMTCmTm!AL29 -> 0 | AM30: =IF(CHMTCmTm!AM29=0,"",CHMTCmTm!AM29) | AP30: =IF(CHMTCmTm!AP29=0,"",CHMTCmTm!AP29) | AR30: =IF(CHMTCmTm!AR29=0,"",CHMTCmTm!AR29) | AT30: =IF(CHMTCmTm!AT29=0,"",CHMTCmTm!AT29) | AW30: =IF(CHMTCmTm!AW29=0,"",CHMTCmTm!AW29) | AZ30: =CHMTCmTm!AZ29 -> 0 | BC30: =COUNTIF(CHMTCmTm!O29, "Outreach Session") -> 0 | BD30: =COUNTIF(CHMTCmTm!O29, "Mobile Clinic") -> 0 | BE30: =COUNTIF(CHMTCmTm!O29, "Health Facility") -> 0
B31: =IF(CHMTCmTm!B30=0,"",CHMTCmTm!B30) | E31: =IF(F31="",0,1) -> 0 | F31: =IF(CHMTCmTm!F30=0,"",CHMTCmTm!F30) | I31: =IF(CHMTCmTm!I30=0,"",CHMTCmTm!I30) | K31: =IF(CHMTCmTm!K30=0,"",CHMTCmTm!K30) | M31: =IF(CHMTCmTm!M30=0,"",CHMTCmTm!M30) | O31: =IF(CHMTCmTm!O30=0,"",CHMTCmTm!O30) | Q31: =IF(O31="Health Facility",3,IF(O31="Outreach Session",1,IF(O31="Mobile Clinic",2))) -> FALSE | R31: =IF(CHMTCmTm!R30=0,"",CHMTCmTm!R30) | T31: =IF(CHMTCmTm!T30=0,"",CHMTCmTm!T30) | V31: =IF(CHMTCmTm!V30=0,"",CHMTCmTm!V30) | Z31: =CHMTCmTm!Z30 -> 0 | AA31: =IF(CHMTCmTm!AA30=0,"",CHMTCmTm!AA30) | AD31: =CHMTCmTm!AD30 -> 0 | AE31: =IF(CHMTCmTm!AE30=0,"",CHMTCmTm!AE30) | AH31: =CHMTCmTm!AH30 -> 0 | AI31: =IF(CHMTCmTm!AI30=0,"",CHMTCmTm!AI30) | AL31: =CHMTCmTm!AL30 -> 0 | AM31: =IF(CHMTCmTm!AM30=0,"",CHMTCmTm!AM30) | AP31: =IF(CHMTCmTm!AP30=0,"",CHMTCmTm!AP30) | AR31: =IF(CHMTCmTm!AR30=0,"",CHMTCmTm!AR30) | AT31: =IF(CHMTCmTm!AT30=0,"",CHMTCmTm!AT30) | AW31: =IF(CHMTCmTm!AW30=0,"",CHMTCmTm!AW30) | AZ31: =CHMTCmTm!AZ30 -> 0 | BC31: =COUNTIF(CHMTCmTm!O30, "Outreach Session") -> 0 | BD31: =COUNTIF(CHMTCmTm!O30, "Mobile Clinic") -> 0 | BE31: =COUNTIF(CHMTCmTm!O30, "Health Facility") -> 0
B32: =IF(CHMTCmTm!B31=0,"",CHMTCmTm!B31) | E32: =IF(F32="",0,1) -> 0 | F32: =IF(CHMTCmTm!F31=0,"",CHMTCmTm!F31) | I32: =IF(CHMTCmTm!I31=0,"",CHMTCmTm!I31) | K32: =IF(CHMTCmTm!K31=0,"",CHMTCmTm!K31) | M32: =IF(CHMTCmTm!M31=0,"",CHMTCmTm!M31) | O32: =IF(CHMTCmTm!O31=0,"",CHMTCmTm!O31) | Q32: =IF(O32="Health Facility",3,IF(O32="Outreach Session",1,IF(O32="Mobile Clinic",2))) -> FALSE | R32: =IF(CHMTCmTm!R31=0,"",CHMTCmTm!R31) | T32: =IF(CHMTCmTm!T31=0,"",CHMTCmTm!T31) | V32: =IF(CHMTCmTm!V31=0,"",CHMTCmTm!V31) | Z32: =CHMTCmTm!Z31 -> 0 | AA32: =IF(CHMTCmTm!AA31=0,"",CHMTCmTm!AA31) | AD32: =CHMTCmTm!AD31 -> 0 | AE32: =IF(CHMTCmTm!AE31=0,"",CHMTCmTm!AE31) | AH32: =CHMTCmTm!AH31 -> 0 | AI32: =IF(CHMTCmTm!AI31=0,"",CHMTCmTm!AI31) | AL32: =CHMTCmTm!AL31 -> 0 | AM32: =IF(CHMTCmTm!AM31=0,"",CHMTCmTm!AM31) | AP32: =IF(CHMTCmTm!AP31=0,"",CHMTCmTm!AP31) | AR32: =IF(CHMTCmTm!AR31=0,"",CHMTCmTm!AR31) | AT32: =IF(CHMTCmTm!AT31=0,"",CHMTCmTm!AT31) | AW32: =IF(CHMTCmTm!AW31=0,"",CHMTCmTm!AW31) | AZ32: =CHMTCmTm!AZ31 -> 0 | BC32: =COUNTIF(CHMTCmTm!O31, "Outreach Session") -> 0 | BD32: =COUNTIF(CHMTCmTm!O31, "Mobile Clinic") -> 0 | BE32: =COUNTIF(CHMTCmTm!O31, "Health Facility") -> 0
B33: =IF(CHMTCmTm!B32=0,"",CHMTCmTm!B32) | E33: =IF(F33="",0,1) -> 0 | F33: =IF(CHMTCmTm!F32=0,"",CHMTCmTm!F32) | I33: =IF(CHMTCmTm!I32=0,"",CHMTCmTm!I32) | K33: =IF(CHMTCmTm!K32=0,"",CHMTCmTm!K32) | M33: =IF(CHMTCmTm!M32=0,"",CHMTCmTm!M32) | O33: =IF(CHMTCmTm!O32=0,"",CHMTCmTm!O32) | Q33: =IF(O33="Health Facility",3,IF(O33="Outreach Session",1,IF(O33="Mobile Clinic",2))) -> FALSE | R33: =IF(CHMTCmTm!R32=0,"",CHMTCmTm!R32) | T33: =IF(CHMTCmTm!T32=0,"",CHMTCmTm!T32) | V33: =IF(CHMTCmTm!V32=0,"",CHMTCmTm!V32) | Z33: =CHMTCmTm!Z32 -> 0 | AA33: =IF(CHMTCmTm!AA32=0,"",CHMTCmTm!AA32) | AD33: =CHMTCmTm!AD32 -> 0 | AE33: =IF(CHMTCmTm!AE32=0,"",CHMTCmTm!AE32) | AH33: =CHMTCmTm!AH32 -> 0 | AI33: =IF(CHMTCmTm!AI32=0,"",CHMTCmTm!AI32) | AL33: =CHMTCmTm!AL32 -> 0 | AM33: =IF(CHMTCmTm!AM32=0,"",CHMTCmTm!AM32) | AP33: =IF(CHMTCmTm!AP32=0,"",CHMTCmTm!AP32) | AR33: =IF(CHMTCmTm!AR32=0,"",CHMTCmTm!AR32) | AT33: =IF(CHMTCmTm!AT32=0,"",CHMTCmTm!AT32) | AW33: =IF(CHMTCmTm!AW32=0,"",CHMTCmTm!AW32) | AZ33: =CHMTCmTm!AZ32 -> 0 | BC33: =COUNTIF(CHMTCmTm!O32, "Outreach Session") -> 0 | BD33: =COUNTIF(CHMTCmTm!O32, "Mobile Clinic") -> 0 | BE33: =COUNTIF(CHMTCmTm!O32, "Health Facility") -> 0
B34: =IF(CHMTCmTm!B33=0,"",CHMTCmTm!B33) | E34: =IF(F34="",0,1) -> 0 | F34: =IF(CHMTCmTm!F33=0,"",CHMTCmTm!F33) | I34: =IF(CHMTCmTm!I33=0,"",CHMTCmTm!I33) | K34: =IF(CHMTCmTm!K33=0,"",CHMTCmTm!K33) | M34: =IF(CHMTCmTm!M33=0,"",CHMTCmTm!M33) | O34: =IF(CHMTCmTm!O33=0,"",CHMTCmTm!O33) | Q34: =IF(O34="Health Facility",3,IF(O34="Outreach Session",1,IF(O34="Mobile Clinic",2))) -> FALSE | R34: =IF(CHMTCmTm!R33=0,"",CHMTCmTm!R33) | T34: =IF(CHMTCmTm!T33=0,"",CHMTCmTm!T33) | V34: =IF(CHMTCmTm!V33=0,"",CHMTCmTm!V33) | Z34: =CHMTCmTm!Z33 -> 0 | AA34: =IF(CHMTCmTm!AA33=0,"",CHMTCmTm!AA33) | AD34: =CHMTCmTm!AD33 -> 0 | AE34: =IF(CHMTCmTm!AE33=0,"",CHMTCmTm!AE33) | AH34: =CHMTCmTm!AH33 -> 0 | AI34: =IF(CHMTCmTm!AI33=0,"",CHMTCmTm!AI33) | AL34: =CHMTCmTm!AL33 -> 0 | AM34: =IF(CHMTCmTm!AM33=0,"",CHMTCmTm!AM33) | AP34: =IF(CHMTCmTm!AP33=0,"",CHMTCmTm!AP33) | AR34: =IF(CHMTCmTm!AR33=0,"",CHMTCmTm!AR33) | AT34: =IF(CHMTCmTm!AT33=0,"",CHMTCmTm!AT33) | AW34: =IF(CHMTCmTm!AW33=0,"",CHMTCmTm!AW33) | AZ34: =CHMTCmTm!AZ33 -> 0 | BC34: =COUNTIF(CHMTCmTm!O33, "Outreach Session") -> 0 | BD34: =COUNTIF(CHMTCmTm!O33, "Mobile Clinic") -> 0 | BE34: =COUNTIF(CHMTCmTm!O33, "Health Facility") -> 0
B35: =IF(CHMTCmTm!B34=0,"",CHMTCmTm!B34) | E35: =IF(F35="",0,1) -> 0 | F35: =IF(CHMTCmTm!F34=0,"",CHMTCmTm!F34) | I35: =IF(CHMTCmTm!I34=0,"",CHMTCmTm!I34) | K35: =IF(CHMTCmTm!K34=0,"",CHMTCmTm!K34) | M35: =IF(CHMTCmTm!M34=0,"",CHMTCmTm!M34) | O35: =IF(CHMTCmTm!O34=0,"",CHMTCmTm!O34) | Q35: =IF(O35="Health Facility",3,IF(O35="Outreach Session",1,IF(O35="Mobile Clinic",2))) -> FALSE | R35: =IF(CHMTCmTm!R34=0,"",CHMTCmTm!R34) | T35: =IF(CHMTCmTm!T34=0,"",CHMTCmTm!T34) | V35: =IF(CHMTCmTm!V34=0,"",CHMTCmTm!V34) | Z35: =CHMTCmTm!Z34 -> 0 | AA35: =IF(CHMTCmTm!AA34=0,"",CHMTCmTm!AA34) | AD35: =CHMTCmTm!AD34 -> 0 | AE35: =IF(CHMTCmTm!AE34=0,"",CHMTCmTm!AE34) | AH35: =CHMTCmTm!AH34 -> 0 | AI35: =IF(CHMTCmTm!AI34=0,"",CHMTCmTm!AI34) | AL35: =CHMTCmTm!AL34 -> 0 | AM35: =IF(CHMTCmTm!AM34=0,"",CHMTCmTm!AM34) | AP35: =IF(CHMTCmTm!AP34=0,"",CHMTCmTm!AP34) | AR35: =IF(CHMTCmTm!AR34=0,"",CHMTCmTm!AR34) | AT35: =IF(CHMTCmTm!AT34=0,"",CHMTCmTm!AT34) | AW35: =IF(CHMTCmTm!AW34=0,"",CHMTCmTm!AW34) | AZ35: =CHMTCmTm!AZ34 -> 0 | BC35: =COUNTIF(CHMTCmTm!O34, "Outreach Session") -> 0 | BD35: =COUNTIF(CHMTCmTm!O34, "Mobile Clinic") -> 0 | BE35: =COUNTIF(CHMTCmTm!O34, "Health Facility") -> 0
B36: =IF(CHMTCmTm!B35=0,"",CHMTCmTm!B35) | E36: =IF(F36="",0,1) -> 0 | F36: =IF(CHMTCmTm!F35=0,"",CHMTCmTm!F35) | I36: =IF(CHMTCmTm!I35=0,"",CHMTCmTm!I35) | K36: =IF(CHMTCmTm!K35=0,"",CHMTCmTm!K35) | M36: =IF(CHMTCmTm!M35=0,"",CHMTCmTm!M35) | O36: =IF(CHMTCmTm!O35=0,"",CHMTCmTm!O35) | Q36: =IF(O36="Health Facility",3,IF(O36="Outreach Session",1,IF(O36="Mobile Clinic",2))) -> FALSE | R36: =IF(CHMTCmTm!R35=0,"",CHMTCmTm!R35) | T36: =IF(CHMTCmTm!T35=0,"",CHMTCmTm!T35) | V36: =IF(CHMTCmTm!V35=0,"",CHMTCmTm!V35) | Z36: =CHMTCmTm!Z35 -> 0 | AA36: =IF(CHMTCmTm!AA35=0,"",CHMTCmTm!AA35) | AD36: =CHMTCmTm!AD35 -> 0 | AE36: =IF(CHMTCmTm!AE35=0,"",CHMTCmTm!AE35) | AH36: =CHMTCmTm!AH35 -> 0 | AI36: =IF(CHMTCmTm!AI35=0,"",CHMTCmTm!AI35) | AL36: =CHMTCmTm!AL35 -> 0 | AM36: =IF(CHMTCmTm!AM35=0,"",CHMTCmTm!AM35) | AP36: =IF(CHMTCmTm!AP35=0,"",CHMTCmTm!AP35) | AR36: =IF(CHMTCmTm!AR35=0,"",CHMTCmTm!AR35) | AT36: =IF(CHMTCmTm!AT35=0,"",CHMTCmTm!AT35) | AW36: =IF(CHMTCmTm!AW35=0,"",CHMTCmTm!AW35) | AZ36: =CHMTCmTm!AZ35 -> 0 | BC36: =COUNTIF(CHMTCmTm!O35, "Outreach Session") -> 0 | BD36: =COUNTIF(CHMTCmTm!O35, "Mobile Clinic") -> 0 | BE36: =COUNTIF(CHMTCmTm!O35, "Health Facility") -> 0
B37: =IF(CHMTCmTm!B36=0,"",CHMTCmTm!B36) | E37: =IF(F37="",0,1) -> 0 | F37: =IF(CHMTCmTm!F36=0,"",CHMTCmTm!F36) | I37: =IF(CHMTCmTm!I36=0,"",CHMTCmTm!I36) | K37: =IF(CHMTCmTm!K36=0,"",CHMTCmTm!K36) | M37: =IF(CHMTCmTm!M36=0,"",CHMTCmTm!M36) | O37: =IF(CHMTCmTm!O36=0,"",CHMTCmTm!O36) | Q37: =IF(O37="Health Facility",3,IF(O37="Outreach Session",1,IF(O37="Mobile Clinic",2))) -> FALSE | R37: =IF(CHMTCmTm!R36=0,"",CHMTCmTm!R36) | T37: =IF(CHMTCmTm!T36=0,"",CHMTCmTm!T36) | V37: =IF(CHMTCmTm!V36=0,"",CHMTCmTm!V36) | Z37: =CHMTCmTm!Z36 -> 0 | AA37: =IF(CHMTCmTm!AA36=0,"",CHMTCmTm!AA36) | AD37: =CHMTCmTm!AD36 -> 0 | AE37: =IF(CHMTCmTm!AE36=0,"",CHMTCmTm!AE36) | AH37: =CHMTCmTm!AH36 -> 0 | AI37: =IF(CHMTCmTm!AI36=0,"",CHMTCmTm!AI36) | AL37: =CHMTCmTm!AL36 -> 0 | AM37: =IF(CHMTCmTm!AM36=0,"",CHMTCmTm!AM36) | AP37: =IF(CHMTCmTm!AP36=0,"",CHMTCmTm!AP36) | AR37: =IF(CHMTCmTm!AR36=0,"",CHMTCmTm!AR36) | AT37: =IF(CHMTCmTm!AT36=0,"",CHMTCmTm!AT36) | AW37: =IF(CHMTCmTm!AW36=0,"",CHMTCmTm!AW36) | AZ37: =CHMTCmTm!AZ36 -> 0 | BC37: =COUNTIF(CHMTCmTm!O36, "Outreach Session") -> 0 | BD37: =COUNTIF(CHMTCmTm!O36, "Mobile Clinic") -> 0 | BE37: =COUNTIF(CHMTCmTm!O36, "Health Facility") -> 0
B38: =IF(CHMTCmTm!B37=0,"",CHMTCmTm!B37) | E38: =IF(F38="",0,1) -> 0 | F38: =IF(CHMTCmTm!F37=0,"",CHMTCmTm!F37) | I38: =IF(CHMTCmTm!I37=0,"",CHMTCmTm!I37) | K38: =IF(CHMTCmTm!K37=0,"",CHMTCmTm!K37) | M38: =IF(CHMTCmTm!M37=0,"",CHMTCmTm!M37) | O38: =IF(CHMTCmTm!O37=0,"",CHMTCmTm!O37) | Q38: =IF(O38="Health Facility",3,IF(O38="Outreach Session",1,IF(O38="Mobile Clinic",2))) -> FALSE | R38: =IF(CHMTCmTm!R37=0,"",CHMTCmTm!R37) | T38: =IF(CHMTCmTm!T37=0,"",CHMTCmTm!T37) | V38: =IF(CHMTCmTm!V37=0,"",CHMTCmTm!V37) | Z38: =CHMTCmTm!Z37 -> 0 | AA38: =IF(CHMTCmTm!AA37=0,"",CHMTCmTm!AA37) | AD38: =CHMTCmTm!AD37 -> 0 | AE38: =IF(CHMTCmTm!AE37=0,"",CHMTCmTm!AE37) | AH38: =CHMTCmTm!AH37 -> 0 | AI38: =IF(CHMTCmTm!AI37=0,"",CHMTCmTm!AI37) | AL38: =CHMTCmTm!AL37 -> 0 | AM38: =IF(CHMTCmTm!AM37=0,"",CHMTCmTm!AM37) | AP38: =IF(CHMTCmTm!AP37=0,"",CHMTCmTm!AP37) | AR38: =IF(CHMTCmTm!AR37=0,"",CHMTCmTm!AR37) | AT38: =IF(CHMTCmTm!AT37=0,"",CHMTCmTm!AT37) | AW38: =IF(CHMTCmTm!AW37=0,"",CHMTCmTm!AW37) | AZ38: =CHMTCmTm!AZ37 -> 0 | BC38: =COUNTIF(CHMTCmTm!O37, "Outreach Session") -> 0 | BD38: =COUNTIF(CHMTCmTm!O37, "Mobile Clinic") -> 0 | BE38: =COUNTIF(CHMTCmTm!O37, "Health Facility") -> 0
B39: =IF(CHMTCmTm!B38=0,"",CHMTCmTm!B38) | E39: =IF(F39="",0,1) -> 0 | F39: =IF(CHMTCmTm!F38=0,"",CHMTCmTm!F38) | I39: =IF(CHMTCmTm!I38=0,"",CHMTCmTm!I38) | K39: =IF(CHMTCmTm!K38=0,"",CHMTCmTm!K38) | M39: =IF(CHMTCmTm!M38=0,"",CHMTCmTm!M38) | O39: =IF(CHMTCmTm!O38=0,"",CHMTCmTm!O38) | Q39: =IF(O39="Health Facility",3,IF(O39="Outreach Session",1,IF(O39="Mobile Clinic",2))) -> FALSE | R39: =IF(CHMTCmTm!R38=0,"",CHMTCmTm!R38) | T39: =IF(CHMTCmTm!T38=0,"",CHMTCmTm!T38) | V39: =IF(CHMTCmTm!V38=0,"",CHMTCmTm!V38) | Z39: =CHMTCmTm!Z38 -> 0 | AA39: =IF(CHMTCmTm!AA38=0,"",CHMTCmTm!AA38) | AD39: =CHMTCmTm!AD38 -> 0 | AE39: =IF(CHMTCmTm!AE38=0,"",CHMTCmTm!AE38) | AH39: =CHMTCmTm!AH38 -> 0 | AI39: =IF(CHMTCmTm!AI38=0,"",CHMTCmTm!AI38) | AL39: =CHMTCmTm!AL38 -> 0 | AM39: =IF(CHMTCmTm!AM38=0,"",CHMTCmTm!AM38) | AP39: =IF(CHMTCmTm!AP38=0,"",CHMTCmTm!AP38) | AR39: =IF(CHMTCmTm!AR38=0,"",CHMTCmTm!AR38) | AT39: =IF(CHMTCmTm!AT38=0,"",CHMTCmTm!AT38) | AW39: =IF(CHMTCmTm!AW38=0,"",CHMTCmTm!AW38) | AZ39: =CHMTCmTm!AZ38 -> 0 | BC39: =COUNTIF(CHMTCmTm!O38, "Outreach Session") -> 0 | BD39: =COUNTIF(CHMTCmTm!O38, "Mobile Clinic") -> 0 | BE39: =COUNTIF(CHMTCmTm!O38, "Health Facility") -> 0
... B265: =IF(CHMTCmTm!B264=0,"",CHMTCmTm!B264) | E265: =IF(F265="",0,1) -> 0 | F265: =IF(CHMTCmTm!F264=0,"",CHMTCmTm!F264) | I265: =IF(CHMTCmTm!I264=0,"",CHMTCmTm!I264) | K265: =IF(CHMTCmTm!K264=0,"",CHMTCmTm!K264) | M265: =IF(CHMTCmTm!M264=0,"",CHMTCmTm!M264) | O265: =IF(CHMTCmTm!O264=0,"",CHMTCmTm!O264) | Q265: =IF(O265="Health Facility",3,IF(O265="Outreach Session",1,IF(O265="Mobile Clinic",2))) -> FALSE | R265: =IF(CHMTCmTm!R264=0,"",CHMTCmTm!R264) | T265: =IF(CHMTCmTm!T264=0,"",CHMTCmTm!T264) | V265: =IF(CHMTCmTm!V264=0,"",CHMTCmTm!V264) | Z265: =CHMTCmTm!Z264 -> 0 | AA265: =IF(CHMTCmTm!AA264=0,"",CHMTCmTm!AA264) | AD265: =CHMTCmTm!AD264 -> 0 | AE265: =IF(CHMTCmTm!AE264=0,"",CHMTCmTm!AE264) | AH265: =CHMTCmTm!AH264 -> 0 | AI265: =IF(CHMTCmTm!AI264=0,"",CHMTCmTm!AI264) | AL265: =CHMTCmTm!AL264 -> 0 | AM265: =IF(CHMTCmTm!AM264=0,"",CHMTCmTm!AM264) | AP265: =IF(CHMTCmTm!AP264=0,"",CHMTCmTm!AP264) | AR265: =IF(CHMTCmTm!AR264=0,"",CHMTCmTm!AR264) | AT265: =IF(CHMTCmTm!AT264=0,"",CHMTCmTm!AT264) | AW265: =IF(CHMTCmTm!AW264=0,"",CHMTCmTm!AW264) | AZ265: =CHMTCmTm!AZ264 -> 0 | BC265: =COUNTIF(CHMTCmTm!O264, "Outreach Session") -> 0 | BD265: =COUNTIF(CHMTCmTm!O264, "Mobile Clinic") -> 0 | BE265: =COUNTIF(CHMTCmTm!O264, "Health Facility") -> 0

Sheet SumCncl
B3: IVD REC Plan Summary Sheet - Council level
B6: Name of Region: | F6: =IF('C for c'!C2=0,"",'C for c'!C2) | J6: Name of Council: | O6: =IF('C for c'!C3=0,"",'C for c'!C3) | S6: Planning Year: | W6: =IF('C for c'!C4=0,"",'C for c'!C4)
B8: Annual beneficiaries: | G8: Pregnant Women: | K8: =IF('C for c'!G2=0,"",'C for c'!G2) | N8: Surviving Infants: | R8: =IF('C for c'!G3=0,"",'C for c'!G3) | T8: 12-24 month children: | Y8: =IF('C for c'!G4=0,"",'C for c'!G4)
B10: Total villages: | F10: =IF('C for c'!D6=0,"",'C for c'!D6) | H10: Service delivery by: | L10: Health facility: | P10: =IF('C for c'!K4=0,"",'C for c'!K4) | Q10: Outreach: | T10: =IF('C for c'!K2=0,"",'C for c'!K2) | U10: Mobile clinic: | Y10: =IF('C for c'!K3=0,"",'C for c'!K3)
B14: 1. Operational plan for outreach immunization service delivery :
T15: Monthly | X15: Annual
B16: 1.1 Number of man-days/overnight stays for organizing outreach sessions/mobile clinics
B17: a | C17: Man-days planned for health facility staff organizing outreach & mobile clinics | T17: =IF('C for c'!H9=0,"",'C for c'!H9) | X17: =IFERROR(T17*12,"")
B18: b | C18: Man-days planned for community members at outreach sessions & mobile clinics | T18: =IF('C for c'!P9=0,"",'C for c'!P9) | X18: =IFERROR(T18*12,"")
B19: c | C19: Total overnight stays planned for health facility staff at outreach sessions | T19: =IF('C for c'!F11=0,"",'C for c'!F11) | X19: =IFERROR(T19*12,"")
B21: 1.2 Number of man-days/overnight stays for transportation of vaccines from district HQ
B22: a | C22: Total distance to be covered for transporting vaccines from district (in Km) | T22: =IF('C for c'!G18=0,"",'C for c'!G18) | X22: =IFERROR(T22*12,"")
B23: b | C23: Man-days planned for officer from district level | T23: =IF('C for c'!G19=0,"",'C for c'!G19) | X23: =IFERROR(T23*12,"")
B24: c | C24: Man-days planned for driver of vaccine van | T24: =IF('C for c'!G20=0,"",'C for c'!G20) | X24: =IFERROR(T24*12,"")
B25: d | C25: Over night stays planned for officer from district level | T25: =IF('C for c'!G21=0,"",'C for c'!G21) | X25: =IFERROR(T25*12,"")
B26: e | C26: Over night stays planned for driver of vaccine van | T26: =IF('C for c'!G22=0,"",'C for c'!G22) | X26: =IFERROR(T26*12,"")
B28: 1.3 Cold chain maintenance
B29: a | C29: Total number of LP gas cylinders required to be refilled | T29: =IF('C for c'!G13=0,"",'C for c'!G13) | X29: =IFERROR(T29*12,"")
B30: b | C30: Number of new LP gas cylinders to be purchased from CHMT level | X30: =IF('C for c'!G15=0,"",'C for c'!G15)
B31: c | C31: Health facilities using electricity for cold chain maintenance | T31: =IF('C for c'!G12=0,"",'C for c'!G12)
B35: 2. Estimate of budgetary requirements for the planning year (in TZS):
T36: Monthly | X36: Annual
B38: a | C38: Extra duty allowance to health facility staff at outreach sessions/mobile clincs | T38: =IF('C for c'!AA2=0,0,'C for c'!AA2) -> 0 | X38: =IFERROR(T38*12,"") -> 0
B39: b | C39: Extra duty allowance to community members at outreach sessions/mobile clinics | T39: =IF('C for c'!AA3=0,0,'C for c'!AA3) -> 0 | X39: =IFERROR(T39*12,"") -> 0
B40: c | C40: Overnight allowance (per diem) to facility staff at outreach sessions | T40: =IF('C for c'!AA4=0,0,'C for c'!AA4) -> 0 | X40: =IFERROR(T40*12,"") -> 0
B41: d | C41: Fare required for transporting vaccines to outreach sites | T41: =IF('C for c'!AA5=0,0,'C for c'!AA5) -> 0 | X41: =IFERROR(T41*12,"") -> 0
B43: e | C43: Budget for fuel to transport vaccines from district HQ to health facilities | T43: =IF('C for c'!AA7=0,0,'C for c'!AA7) -> 0 | X43: =IFERROR(T43*12,"") -> 0
B44: f | C44: Extra duty allowance to officer responsible for vaccine transport from district HQ | T44: =IF('C for c'!AA8=0,0,'C for c'!AA8) -> 0 | X44: =IFERROR(T44*12,"") -> 0
B45: g | C45: Extra duty allowance to driver of vaccine van | T45: =IF('C for c'!AA9=0,0,'C for c'!AA9) -> 0 | X45: =IFERROR(T45*12,"") -> 0
B46: h | C46: Overnight allowance to officer responsible for vaccine transport from district HQ | T46: =IF('C for c'!AA10=0,0,'C for c'!AA10) -> 0 | X46: =IFERROR(T46*12,"") -> 0
B47: i | C47: Overnight allowance to driver of vaccine van | T47: =IF('C for c'!AA11=0,0,'C for c'!AA11) -> 0 | X47: =IFERROR(T47*12,"") -> 0
B49: j | C49: Cost for refilling of LP gas cylinders | T49: =IF('C for c'!AA13=0,0,'C for c'!AA13) -> 0 | X49: =IFERROR(T49*12,"") -> 0
B50: k | C50: Cost for purchasing new LP gas cylinders at CHMT level | X50: =IF('C for c'!AA14=0,"",'C for c'!AA14)
B51: l | C51: Budget required for electricity cost incurred in cold chain maintenance | T51: =IF('C for c'!AA15=0,0,'C for c'!AA15) -> 0 | X51: =IFERROR(T51*12,"") -> 0
C53: TOTAL BUDGET REQUIRED FOR IVD DURING THE PLANNING YEAR | T53: =IF('C for c'!AA17=0,0,'C for c'!AA17) -> 0 | X53: =IFERROR(SUM(X38:Z51),"") -> 0
B57: 3. Estimate of vaccines and logistics requirement during the planning year
D59: Vaccine | J59: Requirement of vaccines (in doses)
J60: Annual (as per beneficiaries) | N60: Annual (including wastage rate) | R60: Annual (including 25% buffer stock) | W60: Monthly requirement
B63: 3.1 | D63: =IF('C for c'!B28=0,"",'C for c'!B28) -> BCG | J63: =IFERROR(('C for c'!N28),"") -> 0 | N63: =IFERROR('C for c'!T28,"") -> 0 | R63: =IFERROR('C for c'!U28,"") -> 0 | W63: =IFERROR('C for c'!V28,"") -> 0
B64: 3.2 | D64: =IF('C for c'!B29=0,"",'C for c'!B29) -> OPV | J64: =IFERROR(('C for c'!N29),"") -> 0 | N64: =IFERROR('C for c'!T29,"") -> 0 | R64: =IFERROR('C for c'!U29,"") -> 0 | W64: =IFERROR('C for c'!V29,"") -> 0
...

Sheet SumFcl
B3: BEFORE PRINTING HEALTH FACILITY SUMMARY ENSURE THAT NAME OF THE FACILITY IS FILTERED OUT IN HEALTH FACILITY AND COLD CHAIN MAINTENANCE PLANS
B4: IVD REC Plan Summary Sheet - Health Facility
B9: Name of Region: | F9: =IF('C for f'!C2=0,"",'C for f'!C2) | J9: Name of Council: | O9: =IF('C for c'!C3=0,"",'C for c'!C3) | S9: Planning Year: | W9: =IF('C for c'!C4=0,"",'C for c'!C4)
B11: Annual beneficiaries: | G11: Pregnant Women: | K11: =IF('C for f'!G2=0,"",'C for f'!G2) | N11: Surviving Infants: | R11: =IF('C for f'!G3=0,"",'C for f'!G3) | T11: 12-24 month children: | Y11: =IF('C for f'!G4=0,"",'C for f'!G4)
B13: Total villages: | F13: =IF('C for f'!D6=0,"",'C for f'!D6) | H13: Service delivery by: | L13: Health facility: | P13: =IF('C for f'!K4=0,"",'C for f'!K4) | Q13: Outreach: | T13: =IF('C for f'!K2=0,"",'C for f'!K2) | U13: Mobile clinic: | Y13: =IF('C for f'!K3=0,"",'C for f'!K3)
B17: 1. Operational plan for outreach immunization service delivery :
T18: Monthly | X18: Annual
B19: 1.1 Number of man-days/overnight stays for organizing outreach sessions/mobile clinics
B20: a | C20: Man-days planned for health facility staff organizing outreach & mobile clinics | T20: =IF('C for f'!H9=0,"",'C for f'!H9) | X20: =IFERROR(T20*12,"")
B21: b | C21: Man-days planned for community members at outreach sessions & mobile clinics | T21: =IF('C for f'!P9=0,"",'C for f'!P9) | X21: =IFERROR(T21*12,"")
B22: c | C22: Total overnight stays planned for health facility staff at outreach sessions | T22: =IF('C for f'!F11=0,"",'C for f'!F11) | X22: =IFERROR(T22*12,"")
B24: 1.2 Number of man-days/overnight stays for transportation of vaccines from district HQ
B25: a | C25: Total distance to be covered for transporting vaccines from district (in Km)
B26: b | C26: Man-days planned for officer from district level
B27: c | C27: Man-days planned for driver of vaccine van
B28: d | C28: Over night stays planned for officer from district level
B29: e | C29: Over night stays planned for driver of vaccine van
B31: 1.2 Cold chain maintenance
B32: a | C32: Total number of LP gas cylinders required to be refilled | T32: =IF('C for f'!G13=0,"",'C for f'!G13) | X32: =IFERROR(T32*12,"")
B33: b | C33: Number of new LP gas cylinders to be purchased from CHMT level
B34: b | C34: Health facility using electricity for cold chain maintenance
B38: 2. Estimate of budgetary requirements for the planning year (in TZS):
T39: Monthly | X39: Annual
B41: a | C41: Extra duty allowance to health facility staff at outreach sessions/mobile clincs | T41: =IF('C for f'!AA2=0,0,'C for f'!AA2) -> 0 | X41: =IFERROR(T41*12,"") -> 0
B42: b | C42: Extra duty allowance to community members at outreach sessions/mobile clinics | T42: =IF('C for f'!AA3=0,0,'C for f'!AA3) -> 0 | X42: =IFERROR(T42*12,"") -> 0
B43: c | C43: Overnight allowance (per diem) to facility staff at outreach sessions | T43: =IF('C for f'!AA4=0,0,'C for f'!AA4) -> 0 | X43: =IFERROR(T43*12,"") -> 0
B44: d | C44: Fare required for transporting vaccines to outreach sites | T44: =IF('C for f'!AA5=0,0,'C for f'!AA5) -> 0 | X44: =IFERROR(T44*12,"") -> 0
B46: e | C46: Budget for fuel to transport vaccines from district HQ to health facilities
B47: f | C47: Extra duty allowance to officer responsible for vaccine transport from district HQ
B48: g | C48: Extra duty allowance to driver of vaccine van
B49: h | C49: Overnight allowance to officer responsible for vaccine transport from district HQ
B50: i | C50: Overnight allowance to driver of vaccine van
B52: e | C52: Cost for refilling of LP gas cylinders | T52: =IF('C for f'!AA13=0,0,'C for f'!AA13) -> 0 | X52: =IFERROR(T52*12,"") -> 0
B53: k | C53: Cost for purchasing new LP gas cylinders at CHMT level
B54: f | C54: Budget required for electricity cost incurred in cold chain maintenance | T54: =IF('C for f'!AA15=0,0,'C for f'!AA15) -> 0 | X54: =IFERROR(T54*12,"") -> 0
C56: TOTAL BUDGET REQUIRED FOR IVD DURING THE PLANNING YEAR | T56: =IFERROR((T41+T42+T43+T44+T52+T54),"") -> 0 | X56: =IFERROR((T56*12),"") -> 0
B60: 3. Estimate of vaccines and logistics requirement during the planning year
D62: Vaccine | J62: Requirement of vaccines (in doses)
J63: Annual (as per beneficiaries) | N63: Annual (including wastage rate) | R63: Annual (including 25% buffer stock) | W63: Monthly requirement
B66: 3.1 | D66: =IF('C for c'!B28=0,"",'C for c'!B28) -> BCG | J66: =IFERROR(('C for f'!N28),"") -> 0 | N66: =IFERROR('C for f'!T28,"") -> 0 | R66: =IFERROR('C for f'!U28,"") -> 0 | W66: =IFERROR('C for f'!V28,"") -> 0
...

Sheet HFPlTm
F1: PRINT READY FORMAT FOR HEALTH FACILITY LEVEL PLANNING FOR IMMUNIZATION SERVICE DELIVERY
B3: REC PLANNING TEMPLATE FOR HEALTH FACILITY
B4: (To be manually filled and submitted to CHMT for compilation; Use extra sheets if there are more than five villages under health facility catchment area)
C6: Name of Region: | L6: Name of Council: | R6: Name of Health Facility:
C8: Number of LP gas cylinders refilled every month for cold chain : | T8: Planning Year:
C10: Whether electricity used to maintain cold chain: | J10: Yes / No | M10: Approximate cost of electricity consumed for maintaining cold chain every month (in TZS) :
G12: VILLAGE : ____ | K12: VILLAGE : ____ | O12: VILLAGE : ____ | S12: VILLAGE : ____ | W12: VILLAGE : ____
