Workbook

Sheet Guidelines
A1: MALAWI 2024 LLIN MASS CAMPAIGN
A3: Please read instructions before you start using this template
A4: This template contains eleven (11) worksheets; Guidlines, Unit cost, Staff List, District Microplan-To be filled, Quantification, Log cost, Training HHR, Implementation of HHR, Training distribution teams, LLIN distribution, data management and comments. Data should be entered on worksheets colored "GREEN" and marked "YES" under "TO BE COMPLETED BY DISTRICT" Column below
A5: WORKSHEET/TAB | B5: DESCRIPTION | I5: TO BE COMPLETED BY DISTRICT
A6: Guidelines | B6: This worksheet provides the instructions for completing this budget and microplanning template | I6: NO
A7: Unit cost | B7: This worksheets is to be completed by the districts based on information collected from health facility and community level on mass Campain. Complete white shaded areas only | I7: YES
A8: Stafflist | B8: This worksheet is to be completed by the districts based on information collected from health facility and community on mass campaign. List all campaign personel including volunteers.
A9: District Microplan-To be filled | B9: This worksheets is to be completed by the districts based on information collected from health facility and community on mass Campain. Complete white shaded areas only (if necessary). Insert a row at the end of each distribution point (Dp) to mark the end of data entry for each dp. | I9: YES
A10: Quantification | I10: NO
A11: Log costs | I11: NO
A12: Training HHR team | I12: NO
A13: Implementation of HHR | I13: NO
A14: Training distribution teams | I14: NO
A15: Summary | B15: The summary worksheet provides overview of the total budget by cost component | I15: NO
A16: Comments | B16: This sheet should be used for additional comments needed for review of microplan. Complete white shaded areas only | I16: YES
A19: For additional assistance contact | B19: Name | D19: Mobile number | E19: e-mail address
B20: Dr . Leonard Dandalo | C20: Technical Sub C | D20: 885534442 | E20: leonard_dandalo@abtassoc.com
B21: Norman Lakalaka | C21: Logistics Sub C | D21: 999402296 | E21: lakalakan@yahoo.com
B22: Lazarous Mangazi | C22: Finance Sub C | E22: lazarous.mangazi@mohpiu.com
B23: Austin Gumbo | C23: M & E and Digitalization Sub C | D23: 888319504 | E23: aagumbo@yahoo.co.uk
B24: Trinitas Mvalo | C24: SBCC Sub C | D24: 999121400 | E24: trinitasm@gmail.com
B25: Akuzike Tauzi | C25: NMCP | D25: 991694375 | E25: akuziketauzi@yahoo.com
A27: ASSUMPTION
B28: Number of Distribution Sites | C28: The average number of distribution sites is to be derived by dividing the total population by 4,000 (Each Distribution Site to manage an average of 4,000 persons)
C29: The avearge number of distribution points should be derived by multiplying the number of distribution sites by 4 (Each Distribution Site will be made up of average of 4 DPs).
B30: Volunteers | C30: 1 HSA will work with 1 volunteer

Sheet Unit Cost
B1: UNIT COST
B2: Item | C2: cost
B3: Refreshment for District level
B4: Airtime
B5: Lunch at district level
B6: Lunch at HHR & distribution team trainings
B7: Transport refund for District supervisors
B8: Transport refund for HF supervisors
B9: Transport refund for HF supervisors (During the HHR)
B10: Unit cost fuel
B11: Transportation reimbursement for HHA and distribution teams
B12: Hall hire at district level
B13: Hall hire for training of HHA and distribution teams
B14: DSA for national level staff
... B52: Hiring a drama group

Sheet Stafflist
A1: Surname | B1: First Name | C1: Middle Name | D1: Mobile network | E1: Phone Number | F1: Position | G1: District | H1: Health Facility | I1: Role 1

Sheet Transport plan
A1: Health facility | B1: Name of distribution site (DS) | C1: Total ITNs to the Distribution Site | D1: Bale/Distribution Site | E1: LOOSE NETS/ Distribution Site | F1: Tonnage | G1: Maximum distance (km) between the cluster warehouse and the distribution site | H1: Condition of the road from cluster warehouse to distribution site | I1: The Type and number of transport to use. | J1: Route | K1: Route/ Distribution
D2: =ROUNDDOWN((C2/50),0) -> 0 | E2: =ROUND((C2-(D2*$P$11)),0) -> 0
D3: =ROUNDDOWN((C3/50),0) -> 0 | E3: =ROUND((C3-(D3*$P$11)),0) -> 0
D4: =ROUNDDOWN((C4/50),0) -> 0 | E4: =ROUND((C4-(D4*$P$11)),0) -> 0
D5: =ROUNDDOWN((C5/50),0) -> 0 | E5: =ROUND((C5-(D5*$P$11)),0) -> 0
D6: =ROUNDDOWN((C6/50),0) -> 0 | E6: =ROUND((C6-(D6*$P$11)),0) -> 0
D7: =ROUNDDOWN((C7/50),0) -> 0 | E7: =ROUND((C7-(D7*$P$11)),0) -> 0
D8: =ROUNDDOWN((C8/50),0) -> 0 | E8: =ROUND((C8-(D8*$P$11)),0) -> 0
D9: =ROUNDDOWN((C9/50),0) -> 0 | E9: =ROUND((C9-(D9*$P$11)),0) -> 0
D10: =ROUNDDOWN((C10/50),0) -> 0 | E10: =ROUND((C10-(D10*$P$11)),0) -> 0
D11: =ROUNDDOWN((C11/50),0) -> 0 | E11: =ROUND((C11-(D11*$P$11)),0) -> 0
D12: =ROUNDDOWN((C12/50),0) -> 0 | E12: =ROUND((C12-(D12*$P$11)),0) -> 0
D13: =ROUNDDOWN((C13/50),0) -> 0 | E13: =ROUND((C13-(D13*$P$11)),0) -> 0
A32: =COUNTA(A24:A31) -> 0 | B32: =COUNTA(B24:B31) -> 0
A43: =COUNTA(A33:A42) -> 0 | B43: =COUNTA(B33:B42) -> 0
A56: =COUNTA(A44:A55) -> 0 | B56: =COUNTA(B44:B55) -> 0
A66: =COUNTA(A57) -> 0 | B66: =COUNTA(B57:B65) -> 0
A72: =COUNTA(A67:A71) -> 0 | B72: =COUNTA(B67:B71) -> 0
A84: =COUNTA(A73:A83) -> 0 | B84: =COUNTA(73:83) -> 0
A95: =COUNTA(A85) -> 0 | B95: =COUNTA(B84:B94) -> 1
A111: =COUNTA(A96) -> 0 | B111: =COUNTA(B96:B110) -> 0
A117: =COUNTA(A112) -> 0 | B117: =COUNTA(B96:B110) -> 0
A129: =COUNTA(A118:A128) -> 0 | B129: =COUNTA(B117:B128) -> 1
A140: =COUNTA(A130:A139) -> 0 | B140: =COUNTA(B130:B139) -> 0
A147: =COUNTA(A141:A146) -> 0 | B147: =COUNTA(B141:B146) -> 0
A155: =COUNTA(A148:A154) -> 0 | B155: =COUNTA(B148:B154) -> 0
A173: =COUNTA(A156:A171) -> 0 | B173: =COUNTA(B156:B172) -> 0
A180: =COUNTA(A174:A179) -> 0 | B180: =COUNTA(B174:B179) -> 0
A181: =SUM(A14+A23+A32+A43+A56+A66+A72+A84+A95+A111+A117+A129+A140+A147+A155+A173+A180) -> 0 | B181: =SUM(B14+B23+B32+B43+B56+B66+B72+B84+B95+B111+B117+B129+B140+B147+B155+B173+B180) -> 2

Sheet MP (To Be Filled) Rural
E3: REGION | G3: HEALTH DISTRICT
B4: ='MP (To Be Filled) Rural'!F3S -> #NAME? | E4: Number of Digital support supervisors | F4: =J4 -> 0 | I4: Number of district supervisors | J4: =ROUND((F9/K4),0) -> 0 | K4: 5
E5: Total population : | F5: =J1371 -> 0 | I5: No. distribution points: | J5: =F1371 -> 0
E6: Number of households: | F6: =K1371 -> 0 | I6: No. HSAs: | J6: =J5 -> 0 | N6: Sum up the total number of nets in Column "K" FOR EACH DP | Q6: Sum up the total number of nets in Column "M" FOR EACH DS
E7: Number of LLIN: (BALES) | F7: =O1371 -> 0 | I7: No.Health Facility supervisors: | J7: =X1371 -> 17
E8: Number of LLIN: (PIECES) | F8: =P1371 -> 0 | I8: No. distribution team members: | J8: =J5*4 -> 0
E9: Number of health facilities: | F9: =B1371 -> 0 | I9: No of Distribution Site Supervisors: | J9: =E1371 -> 2
E10: Number of villages: | F10: =I1371 -> 1 | I10: No of HHR team members | J10: =J5*2 -> 0
K11: 4.4 | L11: 1.8 | M11: 50 | O11: 50 | P11: 50 | X11: 6 | Y11: 4
A12: Serial Number | B12: Health facility | C12: Name of Facility in Charge | D12: Phone Number of Facility in Charge | E12: Name of distribution site (DS) | F12: Name of HSA (distribution point) (DP) | G12: Phone Number of HSA in Charge of DP | H12: CATCHMENT AREA | I12: Villages in catchment area of DP (List Serially by each row) | J12: 2024 Population ( by head count) | K12: Number of households (average HH size of 4.4) | L12: Total Number of LLIN/Village | M12: Number of bales/Village | N12: Total ITNs to the Distribution Point | O12: Bale/Distribution Point | P12: LOOSE NETS/Distribution Point | Q12: Total ITNs to the Distribution Site | R12: Bale/Distribution Site | S12: LOOSE NETS/Distribution Site | T12: Maximum distance (km) between the cluster warehouse and the distribution site | U12: Condition of the road from cluster warehouse to distribution site | V12: The Type and number of transport to use. | W12: Route | X12: Number of HF supervisors for HHR (1 sup:6 HHR teams) | Y12: Number of Distribution Team Members/HF
A13: 1 | K13: =J13/$K$11 -> 0 | L13: =J13/$L$11 -> 0 | M13: =ROUND((L13/$M$11),0) -> 0 | N13: =L13 -> 0 | O13: =ROUNDDOWN((N13/$O$11),0) -> 0 | P13: =ROUND((N13-(O13*$P$11)),0) -> 0 | R13: =ROUNDDOWN((Q13/$O$11),0) -> 0 | S13: =ROUND((Q13-(R13*$P$11)),0) -> 0 | X13: =F83/$X$11 -> 0
K14: =J14/$K$11 -> 0 | L14: =J14/$L$11 -> 0 | M14: =ROUND((L14/$M$11),0) -> 0 | N14: =L14 -> 0 | O14: =ROUNDDOWN((N14/$O$11),0) -> 0 | P14: =ROUND((N14-(O14*$P$11)),0) -> 0 | R14: =ROUNDDOWN((Q14/$O$11),0) -> 0 | S14: =ROUND((Q14-(R14*$P$11)),0) -> 0
K15: =J15/$K$11 -> 0 | L15: =J15/$L$11 -> 0 | M15: =ROUND((L15/$M$11),0) -> 0 | N15: =L15 -> 0 | O15: =ROUNDDOWN((N15/$O$11),0) -> 0 | P15: =ROUND((N15-(O15*$P$11)),0) -> 0 | R15: =ROUNDDOWN((Q15/$O$11),0) -> 0 | S15: =ROUND((Q15-(R15*$P$11)),0) -> 0
K16: =J16/$K$11 -> 0 | L16: =J16/$L$11 -> 0 | M16: =ROUND((L16/$M$11),0) -> 0 | N16: =L16 -> 0 | O16: =ROUNDDOWN((N16/$O$11),0) -> 0 | P16: =ROUND((N16-(O16*$P$11)),0) -> 0 | Q16: =SUM(N13:N16) -> 0 | R16: =ROUNDDOWN((Q16/$O$11),0) -> 0 | S16: =ROUND((Q16-(R16*$P$11)),0) -> 0
K18: =J18/$K$11 -> 0 | L18: =J18/$L$11 -> 0 | M18: =ROUND((L18/$M$11),0) -> 0 | N18: =L18 -> 0 | O18: =ROUNDDOWN((N18/$O$11),0) -> 0 | P18: =ROUND((N18-(O18*$P$11)),0) -> 0 | R18: =ROUNDDOWN((Q18/$O$11),0) -> 0 | S18: =ROUND((Q18-(R18*$P$11)),0) -> 0
K19: =J19/$K$11 -> 0 | L19: =J19/$L$11 -> 0 | M19: =ROUND((L19/$M$11),0) -> 0 | N19: =L19 -> 0 | O19: =ROUNDDOWN((N19/$O$11),0) -> 0 | P19: =ROUND((N19-(O19*$P$11)),0) -> 0 | R19: =ROUNDDOWN((Q19/$O$11),0) -> 0 | S19: =ROUND((Q19-(R19*$P$11)),0) -> 0
K20: =J20/$K$11 -> 0 | L20: =J20/$L$11 -> 0 | M20: =ROUND((L20/$M$11),0) -> 0 | O20: =ROUNDDOWN((N20/$O$11),0) -> 0 | P20: =ROUND((N20-(O20*$P$11)),0) -> 0 | R20: =ROUNDDOWN((Q20/$O$11),0) -> 0 | S20: =ROUND((Q20-(R20*$P$11)),0) -> 0
K21: =J21/$K$11 -> 0 | L21: =J21/$L$11 -> 0 | M21: =ROUND((L21/$M$11),0) -> 0 | N21: =L20+L21 -> 0 | O21: =ROUNDDOWN((N21/$O$11),0) -> 0 | P21: =ROUND((N21-(O21*$P$11)),0) -> 0 | Q21: =SUM(N18:N21) -> 0 | R21: =ROUNDDOWN((Q21/$O$11),0) -> 0 | S21: =ROUND((Q21-(R21*$P$11)),0) -> 0
K23: =J23/$K$11 -> 0 | L23: =J23/$L$11 -> 0 | M23: =ROUND((L23/$M$11),0) -> 0 | N23: =L23 -> 0 | O23: =ROUNDDOWN((N23/$O$11),0) -> 0 | P23: =ROUND((N23-(O23*$P$11)),0) -> 0 | R23: =ROUNDDOWN((Q23/$O$11),0) -> 0 | S23: =ROUND((Q23-(R23*$P$11)),0) -> 0
K24: =J24/$K$11 -> 0 | L24: =J24/$L$11 -> 0 | M24: =ROUND((L24/$M$11),0) -> 0 | N24: =L24 -> 0 | O24: =ROUNDDOWN((N24/$O$11),0) -> 0 | P24: =ROUND((N24-(O24*$P$11)),0) -> 0 | R24: =ROUNDDOWN((Q24/$O$11),0) -> 0 | S24: =ROUND((Q24-(R24*$P$11)),0) -> 0
K25: =J25/$K$11 -> 0 | L25: =J25/$L$11 -> 0 | M25: =ROUND((L25/$M$11),0) -> 0 | O25: =ROUNDDOWN((N25/$O$11),0) -> 0 | P25: =ROUND((N25-(O25*$P$11)),0) -> 0 | R25: =ROUNDDOWN((Q25/$O$11),0) -> 0 | S25: =ROUND((Q25-(R25*$P$11)),0) -> 0
K26: =J26/$K$11 -> 0 | L26: =J26/$L$11 -> 0 | M26: =ROUND((L26/$M$11),0) -> 0 | O26: =ROUNDDOWN((N26/$O$11),0) -> 0 | P26: =ROUND((N26-(O26*$P$11)),0) -> 0 | R26: =ROUNDDOWN((Q26/$O$11),0) -> 0 | S26: =ROUND((Q26-(R26*$P$11)),0) -> 0
K27: =J27/$K$11 -> 0 | L27: =J27/$L$11 -> 0 | M27: =ROUND((L27/$M$11),0) -> 0 | N27: =L25+L26+L27 -> 0 | O27: =ROUNDDOWN((N27/$O$11),0) -> 0 | P27: =ROUND((N27-(O27*$P$11)),0) -> 0 | Q27: =SUM(N23:N27) -> 0 | R27: =ROUNDDOWN((Q27/$O$11),0) -> 0 | S27: =ROUND((Q27-(R27*$P$11)),0) -> 0
K29: =J29/$K$11 -> 0 | L29: =J29/$L$11 -> 0 | M29: =ROUND((L29/$M$11),0) -> 0 | N29: =L29 -> 0 | O29: =ROUNDDOWN((N29/$O$11),0) -> 0 | P29: =ROUND((N29-(O29*$P$11)),0) -> 0 | R29: =ROUNDDOWN((Q29/$O$11),0) -> 0 | S29: =ROUND((Q29-(R29*$P$11)),0) -> 0
K30: =J30/$K$11 -> 0 | L30: =J30/$L$11 -> 0 | M30: =ROUND((L30/$M$11),0) -> 0 | N30: =L30 -> 0 | O30: =ROUNDDOWN((N30/$O$11),0) -> 0 | P30: =ROUND((N30-(O30*$P$11)),0) -> 0 | R30: =ROUNDDOWN((Q30/$O$11),0) -> 0 | S30: =ROUND((Q30-(R30*$P$11)),0) -> 0
K31: =J31/$K$11 -> 0 | L31: =J31/$L$11 -> 0 | M31: =ROUND((L31/$M$11),0) -> 0 | N31: =L31 -> 0 | O31: =ROUNDDOWN((N31/$O$11),0) -> 0 | P31: =ROUND((N31-(O31*$P$11)),0) -> 0 | R31: =ROUNDDOWN((Q31/$O$11),0) -> 0 | S31: =ROUND((Q31-(R31*$P$11)),0) -> 0
K32: =J32/$K$11 -> 0 | L32: =J32/$L$11 -> 0 | M32: =ROUND((L32/$M$11),0) -> 0 | N32: =L32 -> 0 | O32: =ROUNDDOWN((N32/$O$11),0) -> 0 | P32: =ROUND((N32-(O32*$P$11)),0) -> 0 | Q32: =SUM(N29:N32) -> 0 | R32: =ROUNDDOWN((Q32/$O$11),0) -> 0 | S32: =ROUND((Q32-(R32*$P$11)),0) -> 0
K34: =J34/$K$11 -> 0 | L34: =J34/$L$11 -> 0 | M34: =ROUND((L34/$M$11),0) -> 0 | O34: =ROUNDDOWN((N34/$O$11),0) -> 0 | P34: =ROUND((N34-(O34*$P$11)),0) -> 0 | R34: =ROUNDDOWN((Q34/$O$11),0) -> 0 | S34: =ROUND((Q34-(R34*$P$11)),0) -> 0
K35: =J35/$K$11 -> 0 | L35: =J35/$L$11 -> 0 | M35: =ROUND((L35/$M$11),0) -> 0 | N35: =L34+L35 -> 0 | O35: =ROUNDDOWN((N35/$O$11),0) -> 0 | P35: =ROUND((N35-(O35*$P$11)),0) -> 0 | R35: =ROUNDDOWN((Q35/$O$11),0) -> 0 | S35: =ROUND((Q35-(R35*$P$11)),0) -> 0
K36: =J36/$K$11 -> 0 | L36: =J36/$L$11 -> 0 | M36: =ROUND((L36/$M$11),0) -> 0 | N36: =L36 -> 0 | O36: =ROUNDDOWN((N36/$O$11),0) -> 0 | P36: =ROUND((N36-(O36*$P$11)),0) -> 0 | R36: =ROUNDDOWN((Q36/$O$11),0) -> 0 | S36: =ROUND((Q36-(R36*$P$11)),0) -> 0
K37: =J37/$K$11 -> 0 | L37: =J37/$L$11 -> 0 | M37: =ROUND((L37/$M$11),0) -> 0 | O37: =ROUNDDOWN((N37/$O$11),0) -> 0 | P37: =ROUND((N37-(O37*$P$11)),0) -> 0 | R37: =ROUNDDOWN((Q37/$O$11),0) -> 0 | S37: =ROUND((Q37-(R37*$P$11)),0) -> 0
K38: =J38/$K$11 -> 0 | L38: =J38/$L$11 -> 0 | M38: =ROUND((L38/$M$11),0) -> 0 | N38: =L37+L38 -> 0 | O38: =ROUNDDOWN((N38/$O$11),0) -> 0 | P38: =ROUND((N38-(O38*$P$11)),0) -> 0 | Q38: =SUM(N35:N38) -> 0 | R38: =ROUNDDOWN((Q38/$O$11),0) -> 0 | S38: =ROUND((Q38-(R38*$P$11)),0) -> 0
K40: =J40/$K$11 -> 0 | L40: =J40/$L$11 -> 0 | M40: =ROUND((L40/$M$11),0) -> 0 | O40: =ROUNDDOWN((N40/$O$11),0) -> 0 | P40: =ROUND((N40-(O40*$P$11)),0) -> 0 | R40: =ROUNDDOWN((Q40/$O$11),0) -> 0 | S40: =ROUND((Q40-(R40*$P$11)),0) -> 0
K41: =J41/$K$11 -> 0 | L41: =J41/$L$11 -> 0 | M41: =ROUND((L41/$M$11),0) -> 0 | O41: =ROUNDDOWN((N41/$O$11),0) -> 0 | P41: =ROUND((N41-(O41*$P$11)),0) -> 0 | R41: =ROUNDDOWN((Q41/$O$11),0) -> 0 | S41: =ROUND((Q41-(R41*$P$11)),0) -> 0
K42: =J42/$K$11 -> 0 | L42: =J42/$L$11 -> 0 | M42: =ROUND((L42/$M$11),0) -> 0 | O42: =ROUNDDOWN((N42/$O$11),0) -> 0 | P42: =ROUND((N42-(O42*$P$11)),0) -> 0 | R42: =ROUNDDOWN((Q42/$O$11),0) -> 0 | S42: =ROUND((Q42-(R42*$P$11)),0) -> 0
K43: =J43/$K$11 -> 0 | L43: =J43/$L$11 -> 0 | M43: =ROUND((L43/$M$11),0) -> 0 | N43: =SUM(L40:L43) -> 0 | O43: =ROUNDDOWN((N43/$O$11),0) -> 0 | P43: =ROUND((N43-(O43*$P$11)),0) -> 0 | R43: =ROUNDDOWN((Q43/$O$11),0) -> 0 | S43: =ROUND((Q43-(R43*$P$11)),0) -> 0
K44: =J44/$K$11 -> 0 | L44: =J44/$L$11 -> 0 | M44: =ROUND((L44/$M$11),0) -> 0 | O44: =ROUNDDOWN((N44/$O$11),0) -> 0 | P44: =ROUND((N44-(O44*$P$11)),0) -> 0 | R44: =ROUNDDOWN((Q44/$O$11),0) -> 0 | S44: =ROUND((Q44-(R44*$P$11)),0) -> 0
K45: =J45/$K$11 -> 0 | L45: =J45/$L$11 -> 0 | M45: =ROUND((L45/$M$11),0) -> 0 | O45: =ROUNDDOWN((N45/$O$11),0) -> 0 | P45: =ROUND((N45-(O45*$P$11)),0) -> 0 | R45: =ROUNDDOWN((Q45/$O$11),0) -> 0 | S45: =ROUND((Q45-(R45*$P$11)),0) -> 0
K46: =J46/$K$11 -> 0 | L46: =J46/$L$11 -> 0 | M46: =ROUND((L46/$M$11),0) -> 0 | N46: =SUM(L44:L46) -> 0 | O46: =ROUNDDOWN((N46/$O$11),0) -> 0 | P46: =ROUND((N46-(O46*$P$11)),0) -> 0 | Q46: =SUM(N43:N46) -> 0 | R46: =ROUNDDOWN((Q46/$O$11),0) -> 0 | S46: =ROUND((Q46-(R46*$P$11)),0) -> 0
K48: =J48/$K$11 -> 0 | L48: =J48/$L$11 -> 0 | M48: =ROUND((L48/$M$11),0) -> 0 | O48: =ROUNDDOWN((N48/$O$11),0) -> 0 | P48: =ROUND((N48-(O48*$P$11)),0) -> 0 | R48: =ROUNDDOWN((Q48/$O$11),0) -> 0 | S48: =ROUND((Q48-(R48*$P$11)),0) -> 0
...

Sheet Quantification
B2: Quantification
B3: Region | C3: District | L3: Number of distribution team (community) supervisors | M3: Number of district supervisors | N3: Number of district data managers
B4: ='MP (To Be Filled) Rural'!F3 -> 0 | C4: ='MP (To Be Filled) Rural'!I3 -> 0 | D4: ='MP (To Be Filled) Rural'!F5 -> 0 | E4: ='MP (To Be Filled) Rural'!F6 -> 0 | F4: =('MP (To Be Filled) Rural'!F7*50)+'MP (To Be Filled) Rural'!F8 -> 0 | G4: ='MP (To Be Filled) Rural'!F7 -> 0 | H4: ='MP (To Be Filled) Rural'!J6 -> 0 | I4: ='MP (To Be Filled) Rural'!J7 -> 17 | J4: ='MP (To Be Filled) Rural'!J5 -> 0 | K4: ='MP (To Be Filled) Rural'!J8 -> 0 | L4: ='MP (To Be Filled) Rural'!J9 -> 2 | M4: ='MP (To Be Filled) Rural'!J4 -> 0 | N4: ='MP (To Be Filled) Rural'!F4 -> 0

Sheet Log Costs
B2: Logistics Costs
B3: Region | C3: District | D3: Total population | E3: Number of households | F3: Number of LLIN required | G3: Number of bales of 50 | H3: Cost of handling, loading & unloading | I3: Security (2 security personnel for 1 month) | J3: Budget total (Log)
B4: ='MP (To Be Filled) Rural'!F3 -> 0 | C4: ='MP (To Be Filled) Rural'!I3 -> 0 | D4: ='MP (To Be Filled) Rural'!F5 -> 0 | E4: ='MP (To Be Filled) Rural'!F6 -> 0 | F4: =('MP (To Be Filled) Rural'!F7*50)+'MP (To Be Filled) Rural'!F8 -> 0 | G4: ='MP (To Be Filled) Rural'!F7 -> 0 | H4: =G4*2*$H$2 -> 0 | I4: =2*1*$I$2 -> 0 | J4: =SUM(H4:I4) -> 0

Sheet Training HH registration team
B1: Training of HHR supervisors and personnel (Rural)
F2: 40 | G2: 2 | H2: 3 | I2: ='Unit Cost'!C9 -> 0 | J2: ='Unit Cost'!C6 -> 0 | K2: 3 | L2: 3 | M2: ='Unit Cost'!C11 -> 0 | N2: ='Unit Cost'!C13 -> 0 | O2: ='Unit Cost'!C6 -> 0 | P2: ='Unit Cost'!C8 -> 0 | Q2: ='Unit Cost'!C5 -> 0 | R2: ='Unit Cost'!C36 -> 0
B3: Region | C3: District | D3: Number of HH registration personnel | E3: Number of HHR HF supervisors | F3: Number of training sessions | G3: Number of facilitators (2 per session) | H3: Number of days of facilitation | I3: Transport refunds for facilitators | J3: Lunch allowance for facilitators | K3: Number of training days of HH registration personnel | L3: Number of training days of HHA HF supervisors | M3: Transport refund for HHR personnel | N3: Hall hire for training of HHR personnel and community supervisors | O3: Lunch for HHR training (volunteers + supervisors) | P3: Transport refund for HHR HF supervisors | Q3: Lunch for training of HF supervisors for three days | R3: Stationery items for the participants | S3: Budget total implementation of HH assessment
B4: ='MP (To Be Filled) Rural'!F3 -> 0 | C4: ='MP (To Be Filled) Rural'!I3 -> 0 | D4: ='MP (To Be Filled) Rural'!J10 -> 0 | E4: ='MP (To Be Filled) Rural'!J7 -> 17 | F4: =ROUNDUP((D4+E4)/$F$2,0) -> 1 | G4: =F4*$G$2 -> 2 | H4: =H2 -> 3 | I4: =G4*H4*$I$2 -> 0 | J4: =G4*H4*$J$2 -> 0 | K4: =K2 -> 3 | L4: =L2 -> 3 | M4: =D4*$M$2 -> 0 | N4: =F4*H4*$N$2 -> 0 | O4: =(D4+E4+G4)*K4*$O$2 -> 0 | P4: =E4*$P$2 -> 0 | Q4: =E4*L4*$Q$2 -> 0 | R4: =(D4+E4)*$R$2 -> 0 | S4: =I4+J4+M4+N4+O4+P4+Q4+R4 -> 0

Sheet Implementation of HH Registrati
B2: Implementation of household assessment (Rural) | G2: 7 | H2: ='Unit Cost'!C22 -> 0 | I2: 7 | J2: ='Unit Cost'!C8 -> 0 | K2: ='Unit Cost'!C18 -> 0 | L2: 8 | M2: 140 | N2: ='Unit Cost'!C19 -> 0
B3: Region | C3: District | D3: Number of HH registration personnel | E3: Number of community supervisors | F3: Number of district supervisors | G3: Number of days of HH registration | H3: Allowances for HHR personnel | I3: Number of days of supervision and data collection (HF supervisors) | J3: Transport for HF supervisors | K3: Allowances for HF supervisors | L3: Number of days of supervision and data collection (district supervisors) | M3: Transport for district supervisors (Fuel) | N3: Allowances for district supervisors | O3: Communication for HF and district supervisors | P3: Budget total implementation of HH assessment
B4: ='MP (To Be Filled) Rural'!F3 -> 0 | C4: ='MP (To Be Filled) Rural'!I3 -> 0 | D4: ='MP (To Be Filled) Rural'!J10 -> 0 | E4: ='MP (To Be Filled) Rural'!J7 -> 17 | F4: ='MP (To Be Filled) Rural'!J4 -> 0 | G4: =G2 -> 7 | H4: =D4*G4*$H$2 -> 0 | I4: =I2 -> 7 | J4: =E4*I4*$J$2 -> 0 | K4: =E4*I4*$K$2 -> 0 | L4: =L2 -> 8 | M4: =F4*'Unit Cost'!C10*'Implementation of HH Registrati'!M2 -> 0 | N4: =F4*L4*$N$2 -> 0 | O4: =(E4+F4)*'Unit Cost'!C4 -> 0 | P4: =H4+J4+K4+M4+N4+O4 -> 0

Sheet Training Distribution Teams
B1: Training of distribution teams including DP supervisors and members (Rural)
H2: 40 | I2: 2 | J2: 2 | K2: ='[1]Unit cost'!C17 -> 3000 | L2: 150 | M2: ='[1]Unit cost'!C8 -> 7000 | N2: ='[1]Unit cost'!C17 -> 3000 | O2: ='[1]Unit cost'!C8 -> 7000 | P2: ='[1]Unit cost'!C6 -> 3000
B3: Region | C3: District | D3: Number of distribution team members | E3: Number of distribution point supervisors | F3: Number of training days of DP supervisors | G3: Number of training days of distribution team members | H3: Number of training sessions | I3: Number of facilitators (2 per session) | J3: Number of days of facilitation | K3: Lunch for district facilitators | L3: Fuel for district facilitators | M3: Transport for DP supervisors | N3: Lunch for DP supervisors | O3: Transport for distribution team members | P3: Lunch for training of distribution team members | Q3: Budget total training of LLIN distribution teams & supervisors
B4: ='[1]MP (To be filled) Rural'!F3 -> LILONGWE | C4: ='[1]MP (To be filled) Rural'!H3 -> 0 | D4: ='[1]MP (To be filled) Rural'!I8 -> 0 | E4: ='[1]MP (To be filled) Rural'!I5 -> 0 | F4: 2 | G4: 1 | H4: =(D4+E4)/$H$2 -> 0 | I4: =H4*$I$2 -> 0 | J4: =J2 -> 2 | K4: =I4*J4*$K$2 -> 0 | L4: =(I4/2)*'[1]Unit cost'!C10*J4*H4 -> 0 | M4: =E4*F4*$M$2 -> 0 | N4: =E4*N2*F4 -> 0 | O4: =D4*$O$2 -> 0 | P4: =D4*G4*$P$2 -> 0 | Q4: =K4+M4+N4+O4+P4 -> 0

Sheet LLIN Distribution
B2: LLIN distribution personnel cost (Rural) | H2: 1 | I2: 1 | J2: ='Unit Cost'!C22 -> 0 | K2: ='Unit Cost'!C19 -> 0 | L2: ='Unit Cost'!C8 -> 0 | M2: ='Unit Cost'!C19 -> 0 | N2: ='Unit Cost'!C7 -> 0
B3: Region | C3: District | D3: Number of distribution team members | E3: Number of DP supervisors | F3: Number of HF supervisors | G3: Number of district supervisors | H3: Number of days for LLIN distribution (teams) | I3: Number of days for LLIN distribution (supervisors) including data collection) | J3: Allowances for household registration personnel | K3: Allowances for distribution community supervisors | L3: Transport for community supervisors | M3: Allowances for district supervisors | N3: Transport for district supervisors | O3: Budget total implementation of LLINs distribution
B4: ='MP (To Be Filled) Rural'!F3 -> 0 | C4: ='MP (To Be Filled) Rural'!I3 -> 0 | D4: ='MP (To Be Filled) Rural'!J8 -> 0 | E4: ='MP (To Be Filled) Rural'!J9 -> 2 | F4: ='MP (To Be Filled) Rural'!J7 -> 17 | G4: ='MP (To Be Filled) Rural'!J4 -> 0 | H4: =H2 -> 1 | I4: =I2 -> 1 | J4: =D4*H4*$J$2 -> 0 | K4: =E4*I4*$K$2 -> 0 | L4: =E4*I4*$L$2 -> 0 | M4: =G4*I4*$M$2 -> 0 | N4: =G4*I4*$N$2 -> 0 | O4: =J4+K4+L4+M4+N4 -> 0

Sheet Data Management
B1: Data management
H2: ='MP (To Be Filled) Rural'!F4 -> 0 | I2: 10 | J2: ='Unit Cost'!C4 -> 0 | K2: ='Unit Cost'!C5 -> 0
B3: Region | C3: Health district | D3: Total population | E3: Number of households | F3: Number of LLIN required | G3: Number of bales of 50 | H3: Number of data managers | I3: Number of days for data management - HHA and LLIN distribution (13 + 10 = 36 days) | J3: Airtime | K3: Lunch for data managers | L3: Total budget
B4: ='MP (To Be Filled) Rural'!F3 -> 0 | C4: ='MP (To Be Filled) Rural'!I3 -> 0 | D4: ='MP (To Be Filled) Rural'!F5 -> 0 | E4: ='MP (To Be Filled) Rural'!F6 -> 0 | F4: =('MP (To Be Filled) Rural'!F7*50)+'MP (To Be Filled) Rural'!F8 -> 0 | G4: ='MP (To Be Filled) Rural'!F7 -> 0 | H4: =H2 -> 0 | I4: =I2 -> 10 | J4: =J2*I2*H4 -> 0 | K4: =H2*I2*K2 -> 0 | L4: =J4+K4 -> 0

Sheet Summary Budget
B2: Region
B3: District
B6: Campaign budget 2024
B7: Item | C7: Budget total (MK)
B8: Training of HHR supervisors and members | C8: ='Training HH registration team'!S4 -> 0
B9: Implementation of HHR | C9: ='Implementation of HH Registrati'!P4 -> 0
B10: Logistic costs
B11: Training of distribution point supervisors & members
B12: LLIN distribution | C12: ='LLIN Distribution'!O4 -> 0
C13: ='Data Management'!L4 -> 0
B18: TOTAL | C18: =SUM(C8:C17) -> 0
B21: Number of LLIN (in the district) | C21: ='Data Management'!F4 -> 0
B22: Cost per net | C22: =C18/C21 -> #DIV/0!

Sheet Comments
A1: COMMENTS
