Workbook

Sheet Instructions
A1: HEALTH CAMPAIGN CALENDAR — COUNTRY DATA-COLLECTION TOOL (2026-2028)
A2: Template | version 0.4
A4: PURPOSE
B5: This workbook collects, in a single structured table, all planned, tentative or possible health campaigns for 2026-2028. It is designed so that a country team enters each campaign once and the consolidated calendar, partner view and integration scan can then be generated without re-keying.
B6: A single row is entered per campaign, per first-level administrative unit and per year, so plans covering several areas, several diseases and several years are handled without repetition.
A8: HOW TO USE IT
B9: 1. Complete the 'Country & Contact' sheet.
B10: 2. Standardised campaign attributes (target group, platform, product, duration) are pre-filled once per intervention on the 'Campaign Characterisation' sheet — review and adjust only where your country's practice differs. They do not need to be repeated for every row.
B11: 3. On the 'Campaign Calendar' sheet, enter ONE ROW per campaign per first-level administrative unit (region / state / province) per year. Use the drop-down lists; mark the months in which the campaign takes place with an 'X'.
B12: 4. A campaign that runs in several admin-1 units = several rows. A campaign that recurs in 2027 or 2028 = an additional row with the corresponding Year.
B13: 5. The 'Snapshot' sheet consolidates the entries into a calendar view automatically; select the year at the top of that sheet to switch between 2026, 2027 and 2028.
A15: KEY DEFINITIONS
B16: Health campaign — Time-bound, intermittent activities which are deployed to address specific epidemiologic challenges, expediently fill delivery gaps, or provide surge coverage for health interventions.
B17: Integration — The sharing of all or specific campaign components or functions by a specific program addressing a disease or health need with the broader health system and ongoing delivery of interventions through general health services.
A19: SHEETS IN THIS WORKBOOK
B20: Country & Contact — submitting country and focal persons.
B21: Campaign Charaterisation — standardised attributes per intervention (pre-filled, editable).
B22: Campaign Calendar — main data-entry table (one row per campaign × admin-1 × year).
B23: Snapshot — consolidated calendar view, generated automatically (select year).
B24: Reference Lists — controlled vocabularies feeding the drop-down menus.
B26: Prepared by J. Cano (DPC/ESPEN, WHO Regional Office for Africa).

Sheet Country & Contact
A1: COUNTRY & CONTACT INFORMATION
B2: Complete the yellow cells. One workbook per country.
B4: Country | C4: UGANDA
B5: WHO Region | C5: AFRO
B6: Reporting officer (name) | C6: Prof. Olaro Charles
B7: Title / role | C7: Director General Health Services
B8: Organization | C8: Ministry of Health
B9: Department / programme | C9: MOH
B10: Email | C10: olarocharles@gmail.com
B11: Contact number (WhatsApp) | C11: 256772516363
B12: Date completed | C12: 46175
B13: Calendar period covered | C13: 2026 - 2028
B14: Note: example values shown are illustrative — overwrite with the submitting country's details.
B15: Country Focal Persons / Contributing Officers
B16: Name | C16: Title / role | D16: Organization | E16: Department / programme | F16: Email | G16: Contact number (WhatsApp)
B17: Dr Stavia Turyahabwe | C17: Commissioner | D17: MOH | E17: Communicable Diseases Prevention and Control | F17: turyahabwestavia@gmail.com | G17: 256773783932
B18: Diana Atwine | C18: PS | D18: MOH | E18: MOH | F18: datwine1273@gmail.com | G18: 256775324462
B19: Charles Olaro | C19: DGHS | D19: MOH | E19: MOH | F19: olarocharles@gmail.com | G19: '256772516363
B20: Kisakye Annet | C20: EPI team lead | D20: WHO | E20: EPI | F20: kisakyean@who.int | G20: 256772504668
B21: Nyamugisa Esther | C21: Immunization& child health specialist | D21: UNICEF | E21: EPI & Child Health | F21: enyamugisa@unicef.org | G21: 256773470268
B22: Michael Baganizi | C22: Program Manager | D22: MOH | E22: EPI | F22: miknizi@gmail.com | G22: 256772438860
B23: Oyo Charles | C23: CHS | D23: MOH | E23: NCDs | F23: drocakiya@gmail.com | G23: 256772514845
B24: Mubangizi Alfred | C24: ACHS | D24: MOH | E24: NTDs | F24: mubangizialfred@gmail.com | G24: 256701686842
B25: Katurebe Cordelia | C25: Integration secretariat | D25: USG | E25: ACP | F25: katureebecordelia@gmail.com | G25: 256772372411
B26: Mugahi Richard | C26: CHS | D26: MOH | E26: Maternal & Child Health | F26: rmugahi99@gmail.com | G26: 256772563113
B27: Evelynn Kyomugisha | C27: Ag. CHS | D27: MOH | E27: Nursing & midwifery | F27: evky2011@gmail.com | G27: 256782669931
... B29: Robert Mutumba | C29: Program Manager | D29: MOH | E29: ACP | F29: robmutumba@gmail.com | G29: 256755953564
B30: Hafsa Lukwata | C30: ACHS | D30: MOH | E30: Mental Health | G30: 256781033393
B31: Irene Mwenyango | C31: ACHS | D31: MOH | E31: School & Adolescent Health | F31: mwenyangoi@yahoo.com | G31: 256772487327
B32: Paul Mbaka | C32: ACHS | D32: MOH | E32: Health Information | F32: paul.mbaka@gmail.com | G32: 256755050171
B33: Rita Atugonza | C33: Deputy PM | D33: MOH | E33: EPI | F33: atugonzarita@gmail.com, | G33: 256776180360
B34: Richard Kabanda | C34: CHS- | D34: MOH | E34: Health Promotion & Education | F34: krdent@yahoo.com | G34: 256773961965
B35: Henry Semakula | C35: Principal Eductaion Officer | D35: MOES | E35: School health FP | G35: 256772906073
B36: Paul Okware | C36: NMS | D36: NMS | F36: paul.okware@nms.go.ug | G36: 256757058948
B37: Catherine Maiteki | C37: Program Manager | D37: MOH | E37: NMEP | F37: cmaiteki@gmail.com | G37: 256752900219
B38: Jessica Healey | C38: Technical lead | D38: USG
B39: Eleanor Magola | D39: ACP | E39: MOH | G39: 256772692628
B40: Dr. Nabadda Suzan | C40: Head | D40: MOH | E40: UNHLS | F40: sndidde@gmail.com | G40: 256772435996
B41: Dr. George Upenytho | D41: MOH | E41: Community Health Department | F41: upenytho.george@gmail.com
B42: Dr. Akiteng Ann | D42: IDI | E42: NCDs
...

Sheet Campaign Characterisation
A1: CAMPAIGN CHARACTERISATION — standardised attributes per intervention (pre-filled WHO-aligned defaults; edit only where country practice differs)
A2: Captured once per intervention so the main Campaign Calendar sheet does not repeat it for every row.
A3: Intervention | B3: Typical target population | C3: Typical delivery platform | D3: Mode of delivery | E3: Standard pharmaceutical / commodity | F3: Typical duration (days) | G3: Typical team composition | H3: Supplies/Logistics | I3: Training | J3: Job Aids | K3: Census/registration | L3: Communication | M3: Supervision | N3: Data collection/ Monitoring | O3: Transportation | P3: Notes
A4: Measles-Rubella (MR)- every 3 years | B4: Children 9-59 months (catch-up to 15 y in some SIAs) | C4: Fixed + temporary fixed posts + house-to-house | D4: Injectable | E4: MR vaccine | F4: 5-10 | G4: Vaccinator, recorder, mobiliser, supervisor | H4: Vaccines & injection material, data tools, IEC material, CCE | I4: Yes | J4: Yes | K4: Household registration and mobilization to inform operational targets | L4: Mixed channels at all levels | M4: National, Regional, district , Subcounty, Parish | N4: Tally & summary sheets, GIS/ODK, dashboard, | O4: Supervision, vaccine & related supplies delivery at all levels
A5: Community Awareness Testing & Screening for TB, HIV and others(CAST+ ICHDs) | B5: Whole population | C5: Fixed + temporary fixed posts + house-to-house | D5: Multiple | E5: Multiple | F5: 60 | G5: Vaccinator, recorder, mobiliser, supervisor | H5: Vaccines & injection material, data tools, IEC material, CCE, Sample collection & testing kits, condoms,waste management | I5: No | J5: Need a national SOP for integrated health campaigns | K5: No | L5: Mixed channels at all levels | M5: National, Regional, district , Subcounty, Parish | N5: Tally & summary sheets, GIS/ODK, dashboard, research | O5: Supervision, vaccine delivery at all levels | P5: Need an integrated digital tool
A6: OPV / nOPV | B6: Children < 5 years | C6: House-to-house | D6: Oral | E6: bOPV / nOPV2 | F6: 4 | G6: Two-person teams, recorder, supervisor | H6: Vaccines & injection material, data tools, IEC material, CCE | I6: Yes | J6: Yes | K6: Household registration and mobilization to inform operational targets | L6: Mixed channels at all levels | M6: National, Regional, district , Subcounty, Parish | N6: Tally & summary sheets, GIS/ODK, e-register. dashboard, | O6: Supervision, vaccine delivery at all levels | P6: Used for SIAs and outbreak response (OBR).
A7: HPV | B7: Girls 10 years | C7: School-based + fixed posts | D7: Injectable | E7: HPV vaccine | F7: 60 | G7: Vaccinator, recorder, teacher focal point | H7: Vaccines & injection material, data tools, IEC material, CCE | I7: Yes | J7: Yes | K7: No | L7: Mixed channels at all levels | M7: National, Regional, district , Subcounty, Parish | N7: Tally & summary sheets, GIS/ODK, e-register, dashboard, | O7: Supervision, vaccine delivery at all levels
A8: ITN / LLIN-every 3 years | B8: Whole population (per household) | C8: House-to-house + fixed distribution points | D8: Net distribution | E8: LLIN | F8: 14 | G8: Distributor, recorder, crowd control, supervisor | H8: ITNs | I8: Yes | J8: Yes | K8: Household registration and mobilization to inform operational targets | L8: Mixed channels at all levels | M8: National, Regional, district , Subcounty, Parish | N8: Tally & summary sheets, GIS/ODK, dashboard, | O8: Supervision, supplies delivery at all levels
A9: SMC | B9: Children 3 months -10 years | C9: House-to-house | D9: Oral | E9: SP | F9: 4 (per monthly cycle) | G9: Community distributor, supervisor | H9: Tablets, MUAC , Vaccines | I9: Yes | J9: Supervision, vaccine delivery at all levels | K9: No, use previous estimates | L9: Facilitation of CHWs to conduct Household | M9: National, Regional, district , Subcounty, Parish | N9: Tally & summary sheets, GIS/ODK, e-register dashboard, | O9: Supervision, supplies delivery at all levels | P9: Typically 4-5 monthly cycles in the high-transmission season.
A10: Schistosomiasis (SCH) | B10: School-age(5-14 years) children (15 years +) | C10: School-based + community | D10: Oral | E10: Praziquantel (PZQ) | F10: 3-5 | G10: Teacher / community distributor, recorder, supervisor | H10: Tablets, MUAC , Vaccines,,waste management | I10: No | J10: Need a national SOP for integrated health campaigns-school& adolescent health standards | K10: No | L10: Facilitation of teachers to mobilise and participate; IEC | N10: Tally & summary sheets, GIS/ODK, dashboard | O10: Supervision, supplies delivery at all levels
A11: Deworming | B11: 1 year to 14 years | C11: School-based + community | D11: Oral | E11: Albendazole / Mebendazole | F11: 60 | G11: Teacher / community distributor, recorder, supervisor | H11: Tablets, MUAC , Vaccines,,waste management | I11: No | K11: No | M11: National, Regional, district , Subcounty, Parish | O11: Supervision, supplies delivery at all levels | P11: Often co-delivered with SCH.
A12: Lymphatic Filariasis (LF) | B12: Total population ≥ 5 years in endemic IUs | C12: Community-directed (CDD) | D12: Oral | E12: IVM + ALB (or IDA where eligible) | F12: 5-7 | G12: Community distributor, recorder, supervisor | H12: Tablets, MUAC , Vaccines,,waste management | I12: No | J12: Need a national SOP for integrated health campaigns-school& adolescent health standards | K12: No | L12: Facilitation of teachers to mobilize and participate and IEC | M12: National, Regional, district , Subcounty, Parish | N12: Tally & summary sheets, GIS/ODK, dashboard | O12: Supervision, supplies delivery | P12: Localised
A13: Onchocerciasis | B13: Total population ≥ 5 years in endemic communities | C13: Community-directed (CDTI) | D13: Oral | E13: Ivermectin | F13: 5-7 | G13: Community distributor, recorder, supervisor | H13: Tablets, MUAC , Vaccines,,waste management | I13: No | J13: Need a national SOP for integrated health | K13: No | L13: Mixed channels at all levels | M13: National, Regional, district , Subcounty, Parish | N13: Tally & summary sheets, GIS/ODK, e-register. DHIS 2 dashboard, | O13: Supervision, supplies delivery | P13: Localised
A14: Trachoma | B14: 0- 6 months | C14: Community-directed + fixed | D14: topical | E14: Azithromycin (± tetracycline eye ointment) | F14: 5 | G14: Community distributor, recorder, supervisor | H14: Tablets, MUAC , Vaccines,,waste management | I14: No | J14: Need a national SOP for integrated health | K14: No | L14: Mixed channels at all levels | M14: National, Regional, district , Subcounty, Parish | N14: Tally & summary sheets, GIS/ODK, e-register. DHIS 2 dashboard, | O14: Supervision, supplies delivery | P14: Localised
A15: Nutritional assessment | B15: Children 6-59 months | C15: Community-directed + fixed | D15: MUAC,weight | E15: Referral & care | F15: 60 | G15: Vaccinator, recorder, mobiliser, supervisor | H15: Tablets, MUAC , Vaccines,,waste management | I15: Yes | J15: Need a national SOP for integrated health household/community level | K15: No | L15: Facilitation of CHWs to conduct Household, IEC | M15: National, Regional, district , Subcounty, Parish | N15: Tally & summary sheets, GIS/ODK, e-register. DHIS 2 dashboard, | O15: Supervision, supplies delivery
A16: Fistula repairs(surgical camps) | B16: WCBA | C16: Fixed + temporary posts | D16: Screening | E16: Surgery | F16: 7 | G16: Surgical teams | H16: Drugs & sundries, MUAC , Vaccines,,waste management | I16: No | J16: Need a national SOP for integrated health surgcal camps | K16: No | L16: Mixed channels at all levels | M16: site supervision | N16: Digital reporting | O16: Service delivery | P16: Localised
A17: Indoor Residual Spraying | B17: High burden districts | C17: Community-directed (CDD) | D17: Spraying | E17: NDA approved chemical | F17: 14 | G17: Sprayer, recorder, mobiliser | H17: Spray, vaccines, MUAC,Tablets | I17: Yes | J17: Need a national SOP for integrated health | K17: No | L17: Facilitation of CHWs to conduct Household, IEC | M17: National, Regional, district , Subcounty, Parish | N17: Digital reporting | O17: Supervision, supplies delivery | P17: Localised
A18: Vitamin A (VAS) | B18: Children 6-59 months | C18: Fixed + temporary posts; integrated with MNCH / campaigns | D18: Oral | E18: Vitamin A capsules | F18: 60 | G18: Distributor, recorder, mobiliser | H18: Tablets, MUAC , Vaccines,,waste management | I18: No | J18: Need a national SOP for integrated health | K18: No | L18: Facilitation of CHWs to conduct Household, IEC | M18: National, Regional, district , Subcounty, Parish | N18: Tally & summary sheets, GIS/ODK, e-register. DHIS 2 dashboard, | O18: Supervision, supplies delivery | P18: Frequently integrated into other campaigns or MNCH weeks.

Sheet Campaign Calendar
A1: CAMPAIGN CALENDAR — main data-entry sheet (one row per campaign × admin-1 unit × year)
A2: CAMPAIGN IDENTIFICATION | E2: IMPLEMENTATION CALENDAR — mark each active month with 'X' | Q2: GEOGRAPHIC COVERAGE | S2: CAMPAIGN CHARACTERISTICS & COORDINATION
A3: Campaign ID | B3: Programme area | C3: Intervention | D3: Year | E3: Jan | F3: Feb | G3: Mar | H3: Apr | I3: May | J3: Jun | K3: Jul | L3: Aug | M3: Sep | N3: Oct | O3: Nov | P3: Dec | Q3: Admin-1 unit (region / state / province) | R3: No. of Admin-2 units targeted (district / county / municipality) | S3: Status | T3: Target population | U3: Delivery platform | V3: Commodity / funding status | W3: Implementing partner(s) | X3: Funder / donor | Y3: Duration (days) | Z3: Integration / co-delivery intent | AA3: Comments
A4: UGA-01 | B4: Malaria | C4: ITN / LLIN | D4: 2026 | F4: X | G4: X | H4: X | I4: X | J4: X | K4: X | L4: X | M4: X | Q4: National | R4: 146 | S4: Confirmed | T4: 45000000 | U4: House-to-house | V4: Secured | W4: MoH - Malaria CP | X4: Global Fund, USG | Y4: 7 | AA4: Mass net distribution; one-time campaign
A5: UGA-02 | B5: NTD | C5: Schistosomiasis (SCH) | D5: 2026 | G5: X | H5: X | M5: X | N5: X | Q5: Selected districts | R5: 95 | S5: Confirmed | T5: 740000 | U5: Mixed | V5: Secured | W5: MoH NTD | X5: Drug donation (e.g. MDP / ITI) | Y5: 5 | Z5: Same schools as STH (EX-03) — joint delivery
A6: UGA-03 | B6: NTD | C6: STH | D6: 2026 | G6: X | H6: X | M6: X | N6: X | Q6: National | R6: 146 | S6: Confirmed | T6: 920000 | U6: Mixed | V6: Secured | W6: MoH NTD | X6: Drug donation (e.g. MDP / ITI) | Y6: 5 | Z6: Same schools as SCH (EX-02) — joint delivery | AA6: Co-administered with PZQ
A7: UGA-04 | B7: Malaria | C7: SMC | D7: 2026 | H7: X | I7: X | M7: X | N7: X | Q7: Selected districts | R7: 9 | S7: Confirmed | T7: 1180000 | U7: House-to-house | V7: Secured | W7: MoH - Malaria CP, Malaria Consortium, UNICEF | X7: Global Fund | Y7: 4 | Z7: VAS (EX-05) overlaps in May and November — joint mobilisation possible | AA7: Five monthly cycles
A8: UGA-05 | B8: Nutrition | C8: Vitamin A (VAS) | D8: 2026 | G8: X | H8: X | M8: X | N8: X | Q8: National | R8: 146 | S8: Confirmed | T8: 1180000 | U8: Mixed | V8: Secured | W8: MoH, UNICEF | X8: Government | Y8: 5 | Z8: Aligns with SMC (EX-04) in same region | AA8: Twice-yearly distribution
A9: UGA-06 | B9: NTD | C9: Onchocerciasis | D9: 2026 | G9: X | H9: X | M9: X | N9: X | Q9: Selected districts | R9: 50 | S9: Confirmed | T9: 750000 | U9: Mixed | V9: Secured | W9: MoH NTD | X9: Drug donation (e.g. MDP / ITI) | Y9: 7 | Z9: Co-deliver with LF (EX-07) — shared CDD network | AA9: CDTI; ivermectin donated
A10: UGA-07 | B10: NTD | C10: Lymphatic Filariasis (LF) | D10: 2026 | Q10: Selected districts | S10: Confirmed | T10: 1950000 | U10: Mixed | V10: Pipeline / expected | W10: MoH NTD | X10: Drug donation (e.g. MDP / ITI) | Y10: 7 | Z10: Co-deliver with Onchocerciasis (EX-06) — shared CDD network | AA10: IDA where eligible [NOTE: no implementation month marked - timing to confirm]
A11: UGA-08 | B11: Immunization | C11: Measles-Rubella (MR) | D11: 2026 | N11: X | Q11: National | R11: 146 | S11: Confirmed | T11: 520000 | U11: Mixed | V11: Secured | W11: MoH -UNEPI, WHO, UNICEF | X11: Gavi | Y11: 7 | AA11: Catch-up campaign
A12: UGA-09 | B12: Immunization | C12: CAST+ICHDs | D12: 2026 | G12: X | H12: X | M12: X | N12: X | Q12: National | R12: 146 | S12: Confirmed | T12: 2400000 | U12: Fixed post | V12: Secured | W12: MoH | X12: Gavi | Y12: 10 | AA12: Preventive mass vaccination
A13: UGA-10 | B13: Immunization | C13: HPV | D13: 2026 | G13: X | H13: X | M13: X | N13: X | Q13: National | R13: 146 | S13: Tentative | T13: 470000 | U13: Mixed | V13: Pipeline / expected | W13: MoH | X13: Gavi | Y13: 5 | AA13: School-based; girls 9-14
A14: UGA-11 | B14: Polio | C14: OPV / nOPV | D14: 2026 | Q14: Selected districts | R14: 0 | S14: Tentative | T14: 880000 | U14: Mixed | V14: Secured | W14: MoH | X14: GPEI | Y14: 4 | AA14: Outbreak response (OBR)
A15: UGA-12 | B15: NTD | C15: Trachoma | D15: 2026 | G15: X | H15: X | M15: X | N15: X | Q15: Selected districts | R15: 0 | S15: Confirmed | T15: 2750000 | U15: Mixed | V15: Pipeline / expected | W15: MoH NTD | X15: Drug donation (e.g. MDP / ITI) | Y15: 5 | AA15: Azithromycin MDA
A16: UGA-13 | B16: Malaria | C16: IRS | D16: 2026 | M16: X | Q16: Selected districts | R16: 66 | S16: Confirmed | T16: 760000 | U16: House-to-house | V16: Pipeline / expected | W16: MoH - Malaria CP | X16: USG, GF | Y16: 5 | AA16: IRS Campaign
A17: e | Q17: Districts/Cities | R17: 22 | S17: Tentative | T17: 8100000 | AA17: Phased follow-up distribution [INCOMPLETE ROW: intervention and year not specified - please complete or delete]
A44: Rows EX-01 to EX-14 are illustrative examples from a fictional country (Murkonia) showing how the structure is used — delete them before sending the tool to a country. Drop-down lists allow free text where an option is not listed (e.g. 'Other' interventions).

Sheet Snapshot
A1: CALENDAR SNAPSHOT — consolidated view by intervention and month (updates automatically from the Campaign Calendar sheet)
A2: Calendar year: | B2: 2026 | C2: Each cell lists the admin-1 units where that intervention is planned in the selected year. Change the year to switch between 2026-2028. Empty cell = no campaign recorded.
A3: Intervention | B3: Jan | C3: Feb | D3: Mar | E3: Apr | F3: May | G3: Jun | H3: Jul | I3: Aug | J3: Sep | K3: Oct | L3: Nov | M3: Dec
A4: Measles-Rubella (MR) | B4: ='Snapshot calc'!B$203 | C4: ='Snapshot calc'!C$203 | D4: ='Snapshot calc'!D$203 | E4: ='Snapshot calc'!E$203 | F4: ='Snapshot calc'!F$203 | G4: ='Snapshot calc'!G$203 | H4: ='Snapshot calc'!H$203 | I4: ='Snapshot calc'!I$203 | ... M4: ='Snapshot calc'!M$203
A5: Yellow Fever (YF) | B5: ='Snapshot calc'!N$203 | C5: ='Snapshot calc'!O$203 | D5: ='Snapshot calc'!P$203 | E5: ='Snapshot calc'!Q$203 | F5: ='Snapshot calc'!R$203 | G5: ='Snapshot calc'!S$203 | H5: ='Snapshot calc'!T$203 | I5: ='Snapshot calc'!U$203 | ... M5: ='Snapshot calc'!Y$203
A6: OPV / nOPV | B6: ='Snapshot calc'!Z$203 | C6: ='Snapshot calc'!AA$203 | D6: ='Snapshot calc'!AB$203 | E6: ='Snapshot calc'!AC$203 | F6: ='Snapshot calc'!AD$203 | G6: ='Snapshot calc'!AE$203 | H6: ='Snapshot calc'!AF$203 | I6: ='Snapshot calc'!AG$203 | ... M6: ='Snapshot calc'!AK$203
A7: OCV | B7: ='Snapshot calc'!AL$203 | C7: ='Snapshot calc'!AM$203 | D7: ='Snapshot calc'!AN$203 | E7: ='Snapshot calc'!AO$203 | F7: ='Snapshot calc'!AP$203 | G7: ='Snapshot calc'!AQ$203 | H7: ='Snapshot calc'!AR$203 | I7: ='Snapshot calc'!AS$203 | ... M7: ='Snapshot calc'!AW$203
A8: HPV | B8: ='Snapshot calc'!AX$203 | C8: ='Snapshot calc'!AY$203 | D8: ='Snapshot calc'!AZ$203 | E8: ='Snapshot calc'!BA$203 | F8: ='Snapshot calc'!BB$203 | G8: ='Snapshot calc'!BC$203 | H8: ='Snapshot calc'!BD$203 | I8: ='Snapshot calc'!BE$203 | ... M8: ='Snapshot calc'!BI$203
A9: TCV | B9: ='Snapshot calc'!BJ$203 | C9: ='Snapshot calc'!BK$203 | D9: ='Snapshot calc'!BL$203 | E9: ='Snapshot calc'!BM$203 | F9: ='Snapshot calc'!BN$203 | G9: ='Snapshot calc'!BO$203 | H9: ='Snapshot calc'!BP$203 | I9: ='Snapshot calc'!BQ$203 | ... M9: ='Snapshot calc'!BU$203
A10: ITN / LLIN | B10: ='Snapshot calc'!BV$203 | C10: ='Snapshot calc'!BW$203 | D10: ='Snapshot calc'!BX$203 | E10: ='Snapshot calc'!BY$203 | F10: ='Snapshot calc'!BZ$203 | G10: ='Snapshot calc'!CA$203 | H10: ='Snapshot calc'!CB$203 | I10: ='Snapshot calc'!CC$203 | ... M10: ='Snapshot calc'!CG$203
A11: IRS | B11: ='Snapshot calc'!CH$203 | C11: ='Snapshot calc'!CI$203 | D11: ='Snapshot calc'!CJ$203 | E11: ='Snapshot calc'!CK$203 | F11: ='Snapshot calc'!CL$203 | G11: ='Snapshot calc'!CM$203 | H11: ='Snapshot calc'!CN$203 | I11: ='Snapshot calc'!CO$203 | ... M11: ='Snapshot calc'!CS$203
A12: SMC | B12: ='Snapshot calc'!CT$203 | C12: ='Snapshot calc'!CU$203 | D12: ='Snapshot calc'!CV$203 | E12: ='Snapshot calc'!CW$203 | F12: ='Snapshot calc'!CX$203 | G12: ='Snapshot calc'!CY$203 | H12: ='Snapshot calc'!CZ$203 | I12: ='Snapshot calc'!DA$203 | ... M12: ='Snapshot calc'!DE$203
A13: Schistosomiasis (SCH) | B13: ='Snapshot calc'!DF$203 | C13: ='Snapshot calc'!DG$203 | D13: ='Snapshot calc'!DH$203 | E13: ='Snapshot calc'!DI$203 | F13: ='Snapshot calc'!DJ$203 | G13: ='Snapshot calc'!DK$203 | H13: ='Snapshot calc'!DL$203 | I13: ='Snapshot calc'!DM$203 | ... M13: ='Snapshot calc'!DQ$203
A14: STH | B14: ='Snapshot calc'!DR$203 | C14: ='Snapshot calc'!DS$203 | D14: ='Snapshot calc'!DT$203 | E14: ='Snapshot calc'!DU$203 | F14: ='Snapshot calc'!DV$203 | G14: ='Snapshot calc'!DW$203 | H14: ='Snapshot calc'!DX$203 | I14: ='Snapshot calc'!DY$203 | ... M14: ='Snapshot calc'!EC$203
A15: Lymphatic Filariasis (LF) | B15: ='Snapshot calc'!ED$203 | C15: ='Snapshot calc'!EE$203 | D15: ='Snapshot calc'!EF$203 | E15: ='Snapshot calc'!EG$203 | F15: ='Snapshot calc'!EH$203 | G15: ='Snapshot calc'!EI$203 | H15: ='Snapshot calc'!EJ$203 | I15: ='Snapshot calc'!EK$203 | ... M15: ='Snapshot calc'!EO$203
A16: Onchocerciasis | B16: ='Snapshot calc'!EP$203 | C16: ='Snapshot calc'!EQ$203 | D16: ='Snapshot calc'!ER$203 | E16: ='Snapshot calc'!ES$203 | F16: ='Snapshot calc'!ET$203 | G16: ='Snapshot calc'!EU$203 | H16: ='Snapshot calc'!EV$203 | I16: ='Snapshot calc'!EW$203 | ... M16: ='Snapshot calc'!FA$203
A17: Trachoma | B17: ='Snapshot calc'!FB$203 | C17: ='Snapshot calc'!FC$203 | D17: ='Snapshot calc'!FD$203 | E17: ='Snapshot calc'!FE$203 | F17: ='Snapshot calc'!FF$203 | G17: ='Snapshot calc'!FG$203 | H17: ='Snapshot calc'!FH$203 | I17: ='Snapshot calc'!FI$203 | ... M17: ='Snapshot calc'!FM$203
A18: Vitamin A (VAS) | B18: ='Snapshot calc'!FN$203 | C18: ='Snapshot calc'!FO$203 | D18: ='Snapshot calc'!FP$203 | E18: ='Snapshot calc'!FQ$203 | F18: ='Snapshot calc'!FR$203 | G18: ='Snapshot calc'!FS$203 | H18: ='Snapshot calc'!FT$203 | I18: ='Snapshot calc'!FU$203 | ... M18: ='Snapshot calc'!FY$203
A19: Nutrition (MUAC) | B19: ='Snapshot calc'!FZ$203 | C19: ='Snapshot calc'!GA$203 | D19: ='Snapshot calc'!GB$203 | E19: ='Snapshot calc'!GC$203 | F19: ='Snapshot calc'!GD$203 | G19: ='Snapshot calc'!GE$203 | H19: ='Snapshot calc'!GF$203 | I19: ='Snapshot calc'!GG$203 | ... M19: ='Snapshot calc'!GK$203
A20: CAST+ICHDs | B20: ='Snapshot calc'!GL$203 | C20: ='Snapshot calc'!GM$203 | D20: ='Snapshot calc'!GN$203 | E20: ='Snapshot calc'!GO$203 | F20: ='Snapshot calc'!GP$203 | G20: ='Snapshot calc'!GQ$203 | H20: ='Snapshot calc'!GR$203 | I20: ='Snapshot calc'!GS$203 | ... M20: ='Snapshot calc'!GW$203
A21: Fistula repair | B21: ='Snapshot calc'!GX$203 | C21: ='Snapshot calc'!GY$203 | D21: ='Snapshot calc'!GZ$203 | E21: ='Snapshot calc'!HA$203 | F21: ='Snapshot calc'!HB$203 | G21: ='Snapshot calc'!HC$203 | H21: ='Snapshot calc'!HD$203 | I21: ='Snapshot calc'!HE$203 | ... M21: ='Snapshot calc'!HI$203
A23: Reading the snapshot: where the same admin-1 unit appears under two or more interventions in the same month, that month-and-location is a candidate for coordinated or integrated delivery (shared microplanning, social mobilisation, transport or co-administration).

Sheet Reference Lists
A1: REFERENCE LISTS — controlled vocabularies feeding the drop-down menus
A2: Programme area | B2: Intervention | C2: Status | D2: Delivery platform | E2: Commodity / funding status | F2: Funder / donor | G2: Year | H2: Month mark
A3: Immunization | B3: Measles-Rubella (MR) | C3: Confirmed | D3: Fixed post | E3: Secured | F3: Government | G3: 2026 | H3: X
A4: Malaria | B4: Yellow Fever (YF) | C4: Tentative | D4: Temporary fixed post | E4: Partially secured | F4: Gavi | G4: 2027
A5: NTD | B5: OPV / nOPV | C5: Under discussion | D5: House-to-house | E5: Pipeline / expected | F5: Global Fund | G5: 2028
A6: Nutrition | B6: OCV | C6: At risk | D6: School-based | E6: Funding gap | F6: GPEI
A7: Polio | B7: HPV | D7: Community-directed (CDD) | E7: Not yet known | F7: USAID
A8: Other | B8: TCV | D8: Health facility | F8: FCDO
B9: ITN / LLIN | D9: Mixed | F9: Gates Foundation
B10: IRS | F10: World Bank
B11: SMC | F11: Drug donation (e.g. MDP / ITI)
B12: Schistosomiasis (SCH) | F12: Other
B13: STH
B14: Lymphatic Filariasis (LF)
B15: Onchocerciasis
B16: Trachoma
B17: Vitamin A (VAS)
B18: Nutrition (MUAC)
B19: CAST+ICHDs
B20: Fistula repair

Sheet Snapshot calc
A1: AUTO-GENERATED - do not edit. Running concatenation that feeds the Snapshot sheet. Uses only IF / AND / & so it works in every version of Excel. Safe to leave hidden.
B2: =Snapshot!$A$4&" | "&Snapshot!B$3 | C2: =Snapshot!$A$4&" | "&Snapshot!C$3 | D2: =Snapshot!$A$4&" | "&Snapshot!D$3 | E2: =Snapshot!$A$4&" | "&Snapshot!E$3 | F2: =Snapshot!$A$4&" | "&Snapshot!F$3 | G2: =Snapshot!$A$4&" | "&Snapshot!G$3 | H2: =Snapshot!$A$4&" | "&Snapshot!H$3 | I2: =Snapshot!$A$4&" | "&Snapshot!I$3 | ... M2: =Snapshot!$A$4&" | "&Snapshot!M$3 | N2: =Snapshot!$A$5&" | "&Snapshot!B$3 | O2: =Snapshot!$A$5&" | "&Snapshot!C$3 | P2: =Snapshot!$A$5&" | "&Snapshot!D$3 | Q2: =Snapshot!$A$5&" | "&Snapshot!E$3 | R2: =Snapshot!$A$5&" | "&Snapshot!F$3 | S2: =Snapshot!$A$5&" | "&Snapshot!G$3 | T2: =Snapshot!$A$5&" | "&Snapshot!H$3 | U2: =Snapshot!$A$5&" | "&Snapshot!I$3 | ... Y2: =Snapshot!$A$5&" | "&Snapshot!M$3 | Z2: =Snapshot!$A$6&" | "&Snapshot!B$3 | AA2: =Snapshot!$A$6&" | "&Snapshot!C$3 | AB2: =Snapshot!$A$6&" | "&Snapshot!D$3 | AC2: =Snapshot!$A$6&" | "&Snapshot!E$3 | AD2: =Snapshot!$A$6&" | "&Snapshot!F$3 | AE2: =Snapshot!$A$6&" | "&Snapshot!G$3 | AF2: =Snapshot!$A$6&" | "&Snapshot!H$3 | AG2: =Snapshot!$A$6&" | "&Snapshot!I$3 | ... AK2: =Snapshot!$A$6&" | "&Snapshot!M$3 | AL2: =Snapshot!$A$7&" | "&Snapshot!B$3 | AM2: =Snapshot!$A$7&" | "&Snapshot!C$3 | AN2: =Snapshot!$A$7&" | "&Snapshot!D$3 | AO2: =Snapshot!$A$7&" | "&Snapshot!E$3 | AP2: =Snapshot!$A$7&" | "&Snapshot!F$3 | AQ2: =Snapshot!$A$7&" | "&Snapshot!G$3 | AR2: =Snapshot!$A$7&" | "&Snapshot!H$3 | AS2: =Snapshot!$A$7&" | "&Snapshot!I$3 | ... AW2: =Snapshot!$A$7&" | "&Snapshot!M$3 | AX2: =Snapshot!$A$8&" | "&Snapshot!B$3 | AY2: =Snapshot!$A$8&" | "&Snapshot!C$3 | AZ2: =Snapshot!$A$8&" | "&Snapshot!D$3 | BA2: =Snapshot!$A$8&" | "&Snapshot!E$3 | BB2: =Snapshot!$A$8&" | "&Snapshot!F$3 | BC2: =Snapshot!$A$8&" | "&Snapshot!G$3 | BD2: =Snapshot!$A$8&" | "&Snapshot!H$3 | BE2: =Snapshot!$A$8&" | "&Snapshot!I$3 | ... BI2: =Snapshot!$A$8&" | "&Snapshot!M$3 | BJ2: =Snapshot!$A$9&" | "&Snapshot!B$3 | BK2: =Snapshot!$A$9&" | "&Snapshot!C$3 | BL2: =Snapshot!$A$9&" | "&Snapshot!D$3 | BM2: =Snapshot!$A$9&" | "&Snapshot!E$3 | BN2: =Snapshot!$A$9&" | "&Snapshot!F$3 | BO2: =Snapshot!$A$9&" | "&Snapshot!G$3 | BP2: =Snapshot!$A$9&" | "&Snapshot!H$3 | BQ2: =Snapshot!$A$9&" | "&Snapshot!I$3 | ... BU2: =Snapshot!$A$9&" | "&Snapshot!M$3 | BV2: =Snapshot!$A$10&" | "&Snapshot!B$3 | BW2: =Snapshot!$A$10&" | "&Snapshot!C$3 | BX2: =Snapshot!$A$10&" | "&Snapshot!D$3 | BY2: =Snapshot!$A$10&" | "&Snapshot!E$3 | BZ2: =Snapshot!$A$10&" | "&Snapshot!F$3 | CA2: =Snapshot!$A$10&" | "&Snapshot!G$3 | CB2: =Snapshot!$A$10&" | "&Snapshot!H$3 | CC2: =Snapshot!$A$10&" | "&Snapshot!I$3 | ... CG2: =Snapshot!$A$10&" | "&Snapshot!M$3 | CH2: =Snapshot!$A$11&" | "&Snapshot!B$3 | CI2: =Snapshot!$A$11&" | "&Snapshot!C$3 | CJ2: =Snapshot!$A$11&" | "&Snapshot!D$3 | CK2: =Snapshot!$A$11&" | "&Snapshot!E$3 | CL2: =Snapshot!$A$11&" | "&Snapshot!F$3 | CM2: =Snapshot!$A$11&" | "&Snapshot!G$3 | CN2: =Snapshot!$A$11&" | "&Snapshot!H$3 | CO2: =Snapshot!$A$11&" | "&Snapshot!I$3 | ... CS2: =Snapshot!$A$11&" | "&Snapshot!M$3 | CT2: =Snapshot!$A$12&" | "&Snapshot!B$3 | CU2: =Snapshot!$A$12&" | "&Snapshot!C$3 | CV2: =Snapshot!$A$12&" | "&Snapshot!D$3 | CW2: =Snapshot!$A$12&" | "&Snapshot!E$3 | CX2: =Snapshot!$A$12&" | "&Snapshot!F$3 | CY2: =Snapshot!$A$12&" | "&Snapshot!G$3 | CZ2: =Snapshot!$A$12&" | "&Snapshot!H$3 | DA2: =Snapshot!$A$12&" | "&Snapshot!I$3 | ... DE2: =Snapshot!$A$12&" | "&Snapshot!M$3 | DF2: =Snapshot!$A$13&" | "&Snapshot!B$3 | DG2: =Snapshot!$A$13&" | "&Snapshot!C$3 | DH2: =Snapshot!$A$13&" | "&Snapshot!D$3 | DI2: =Snapshot!$A$13&" | "&Snapshot!E$3 | DJ2: =Snapshot!$A$13&" | "&Snapshot!F$3 | DK2: =Snapshot!$A$13&" | "&Snapshot!G$3 | DL2: =Snapshot!$A$13&" | "&Snapshot!H$3 | DM2: =Snapshot!$A$13&" | "&Snapshot!I$3 | ... DQ2: =Snapshot!$A$13&" | "&Snapshot!M$3 | DR2: =Snapshot!$A$14&" | "&Snapshot!B$3 | DS2: =Snapshot!$A$14&" | "&Snapshot!C$3 | DT2: =Snapshot!$A$14&" | "&Snapshot!D$3 | DU2: =Snapshot!$A$14&" | "&Snapshot!E$3 | DV2: =Snapshot!$A$14&" | "&Snapshot!F$3 | DW2: =Snapshot!$A$14&" | "&Snapshot!G$3 | DX2: =Snapshot!$A$14&" | "&Snapshot!H$3 | DY2: =Snapshot!$A$14&" | "&Snapshot!I$3 | ... EC2: =Snapshot!$A$14&" | "&Snapshot!M$3 | ED2: =Snapshot!$A$15&" | "&Snapshot!B$3 | EE2: =Snapshot!$A$15&" | "&Snapshot!C$3 | EF2: =Snapshot!$A$15&" | "&Snapshot!D$3 | EG2: =Snapshot!$A$15&" | "&Snapshot!E$3 | EH2: =Snapshot!$A$15&" | "&Snapshot!F$3 | EI2: =Snapshot!$A$15&" | "&Snapshot!G$3 | EJ2: =Snapshot!$A$15&" | "&Snapshot!H$3 | EK2: =Snapshot!$A$15&" | "&Snapshot!I$3 | ... EO2: =Snapshot!$A$15&" | "&Snapshot!M$3 | EP2: =Snapshot!$A$16&" | "&Snapshot!B$3 | EQ2: =Snapshot!$A$16&" | "&Snapshot!C$3 | ER2: =Snapshot!$A$16&" | "&Snapshot!D$3 | ES2: =Snapshot!$A$16&" | "&Snapshot!E$3 | ET2: =Snapshot!$A$16&" | "&Snapshot!F$3 | EU2: =Snapshot!$A$16&" | "&Snapshot!G$3 | EV2: =Snapshot!$A$16&" | "&Snapshot!H$3 | EW2: =Snapshot!$A$16&" | "&Snapshot!I$3 | ... FA2: =Snapshot!$A$16&" | "&Snapshot!M$3 | FB2: =Snapshot!$A$17&" | "&Snapshot!B$3 | FC2: =Snapshot!$A$17&" | "&Snapshot!C$3 | FD2: =Snapshot!$A$17&" | "&Snapshot!D$3 | FE2: =Snapshot!$A$17&" | "&Snapshot!E$3 | FF2: =Snapshot!$A$17&" | "&Snapshot!F$3 | FG2: =Snapshot!$A$17&" | "&Snapshot!G$3 | FH2: =Snapshot!$A$17&" | "&Snapshot!H$3 | FI2: =Snapshot!$A$17&" | "&Snapshot!I$3 | ... FM2: =Snapshot!$A$17&" | "&Snapshot!M$3 | FN2: =Snapshot!$A$18&" | "&Snapshot!B$3 | FO2: =Snapshot!$A$18&" | "&Snapshot!C$3 | FP2: =Snapshot!$A$18&" | "&Snapshot!D$3 | FQ2: =Snapshot!$A$18&" | "&Snapshot!E$3 | FR2: =Snapshot!$A$18&" | "&Snapshot!F$3 | FS2: =Snapshot!$A$18&" | "&Snapshot!G$3 | FT2: =Snapshot!$A$18&" | "&Snapshot!H$3 | FU2: =Snapshot!$A$18&" | "&Snapshot!I$3 | ... FY2: =Snapshot!$A$18&" | "&Snapshot!M$3 | FZ2: =Snapshot!$A$19&" | "&Snapshot!B$3 | GA2: =Snapshot!$A$19&" | "&Snapshot!C$3 | GB2: =Snapshot!$A$19&" | "&Snapshot!D$3 | GC2: =Snapshot!$A$19&" | "&Snapshot!E$3 | GD2: =Snapshot!$A$19&" | "&Snapshot!F$3 | GE2: =Snapshot!$A$19&" | "&Snapshot!G$3 | GF2: =Snapshot!$A$19&" | "&Snapshot!H$3 | GG2: =Snapshot!$A$19&" | "&Snapshot!I$3 | ... GK2: =Snapshot!$A$19&" | "&Snapshot!M$3 | GL2: =Snapshot!$A$20&" | "&Snapshot!B$3 | GM2: =Snapshot!$A$20&" | "&Snapshot!C$3 | GN2: =Snapshot!$A$20&" | "&Snapshot!D$3 | GO2: =Snapshot!$A$20&" | "&Snapshot!E$3 | GP2: =Snapshot!$A$20&" | "&Snapshot!F$3 | GQ2: =Snapshot!$A$20&" | "&Snapshot!G$3 | GR2: =Snapshot!$A$20&" | "&Snapshot!H$3 | GS2: =Snapshot!$A$20&" | "&Snapshot!I$3 | ... GW2: =Snapshot!$A$20&" | "&Snapshot!M$3 | GX2: =Snapshot!$A$21&" | "&Snapshot!B$3 | GY2: =Snapshot!$A$21&" | "&Snapshot!C$3 | GZ2: =Snapshot!$A$21&" | "&Snapshot!D$3 | HA2: =Snapshot!$A$21&" | "&Snapshot!E$3 | HB2: =Snapshot!$A$21&" | "&Snapshot!F$3 | HC2: =Snapshot!$A$21&" | "&Snapshot!G$3 | HD2: =Snapshot!$A$21&" | "&Snapshot!H$3 | HE2: =Snapshot!$A$21&" | "&Snapshot!I$3 | ... HI2: =Snapshot!$A$21&" | "&Snapshot!M$3
B3: ="" | C3: ="" | D3: ="" | E3: ="" | F3: ="" | G3: ="" | H3: ="" | I3: ="" | ... HI3: =""
